<?xml version='1.0' encoding='utf-8'?>
<robot name="bot">
    <link name="fr3_link0">
        <visual>
            <origin xyz="0 0 0" rpy="0 -0 0" />
            <geometry>
                <mesh filename="meshes/link0.dae" />
            </geometry>
        </visual>
        <collision>
            <origin xyz="-0.0407596 0.000357889 0.0583352" rpy="-0.0257223 0.986458 -0.0138274" />
            <geometry>
                <cylinder radius="0.119562" length="0.076010" />
            </geometry>
        </collision>
        <collision>
            <origin xyz="-0.0724587 -0.000181328 0.0373768" rpy="0 -0 0" />
            <geometry>
                <sphere radius="0.119562" />
            </geometry>
        </collision>
        <collision>
            <origin xyz="-0.0090606 0.000897106 0.0792936" rpy="0 -0 0" />
            <geometry>
                <sphere radius="0.119562" />
            </geometry>
        </collision>
        <inertial>
            <origin xyz="-0.0172 0.0004 0.0745" rpy="0 -0 0" />
            <mass value="2.396600" />
            <inertia ixx="9.000000e-03" ixy="0.000000e+00" ixz="2.000000e-03" iyy="1.150000e-02" iyz="0.000000e+00" izz="8.500000e-03" />
        </inertial>
    </link>
    <link name="fr3_link1">
        <visual>
            <origin xyz="0 0 0" rpy="0 -0 0" />
            <geometry>
                <mesh filename="meshes/link1.dae" />
            </geometry>
        </visual>
        <collision>
            <origin xyz="-6.34898e-06 -0.0377228 -0.0696574" rpy="-2.7435 0.00118553 -0.00587713" />
            <geometry>
                <cylinder radius="0.086502" length="0.149074" />
            </geometry>
        </collision>
        <collision>
            <origin xyz="-9.47147e-05 -0.066618 -0.000949382" rpy="0 -0 0" />
            <geometry>
                <sphere radius="0.086502" />
            </geometry>
        </collision>
        <collision>
            <origin xyz="8.20167e-05 -0.00882767 -0.138365" rpy="0 -0 0" />
            <geometry>
                <sphere radius="0.086502" />
            </geometry>
        </collision>
        <inertial>
            <origin xyz="4.128e-07 -0.0181251 -0.0386036" rpy="0 -0 0" />
            <mass value="2.927465" />
            <inertia ixx="2.392732e-02" ixy="1.331790e-05" ixz="-1.140477e-04" iyy="2.248216e-02" iyz="-1.995032e-03" izz="6.350098e-03" />
        </inertial>
    </link>
    <joint name="fr3_joint1" type="revolute">
        <parent link="fr3_link0" />
        <child link="fr3_link1" />
        <origin xyz="0 0 0.333" rpy="0 -0 0" />
        <axis xyz="0 0 1" />
        <limit lower="-2.743700" upper="2.743700" effort="87.000000" velocity="2.620000" />
        <dynamics damping="0.003000" friction="0.200000" />
    </joint>
    <link name="fr3_link2">
        <visual>
            <origin xyz="0 0 0" rpy="0 -0 0" />
            <geometry>
                <mesh filename="meshes/link2.dae" />
            </geometry>
        </visual>
        <collision>
            <origin xyz="-4.35092e-05 -0.0705256 0.0374995" rpy="1.96485 0.00164003 0.00245809" />
            <geometry>
                <cylinder radius="0.085986" length="0.148954" />
            </geometry>
        </collision>
        <collision>
            <origin xyz="-0.000165654 -0.00175642 0.0660939" rpy="0 -0 0" />
            <geometry>
                <sphere radius="0.085986" />
            </geometry>
        </collision>
        <collision>
            <origin xyz="7.86358e-05 -0.139295 0.00890499" rpy="0 -0 0" />
            <geometry>
                <sphere radius="0.085986" />
            </geometry>
        </collision>
        <inertial>
            <origin xyz="0.00318289 -0.0743222 0.00881461" rpy="0 -0 0" />
            <mass value="2.935537" />
            <inertia ixx="4.193895e-02" ixy="2.025733e-04" ixz="4.077784e-03" iyy="2.514515e-02" iyz="-4.225216e-03" izz="6.170214e-02" />
        </inertial>
    </link>
    <joint name="fr3_joint2" type="revolute">
        <parent link="fr3_link1" />
        <child link="fr3_link2" />
        <origin xyz="0 0 0" rpy="-1.5708 0 0" />
        <axis xyz="0 0 1" />
        <limit lower="-1.783700" upper="1.783700" effort="87.000000" velocity="2.620000" />
        <dynamics damping="0.003000" friction="0.200000" />
    </joint>
    <link name="fr3_link3">
        <visual>
            <origin xyz="0 0 0" rpy="0 -0 0" />
            <geometry>
                <mesh filename="meshes/link3.dae" />
            </geometry>
        </visual>
        <collision>
            <origin xyz="0.0469273 0.0285163 -0.0428328" rpy="-0.576988 0.672981 -0.206878" />
            <geometry>
                <cylinder radius="0.082286" length="0.107681" />
            </geometry>
        </collision>
        <collision>
            <origin xyz="0.0133675 0.00554986 -0.0781184" rpy="0 -0 0" />
            <geometry>
                <sphere radius="0.082286" />
            </geometry>
        </collision>
        <collision>
            <origin xyz="0.0804871 0.0514827 -0.00754716" rpy="0 -0 0" />
            <geometry>
                <sphere radius="0.082286" />
            </geometry>
        </collision>
        <inertial>
            <origin xyz="0.0407016 -0.00482006 -0.0289731" rpy="0 -0 0" />
            <mass value="2.244901" />
            <inertia ixx="2.410143e-02" ixy="2.404695e-03" ixz="-2.856269e-03" iyy="1.974053e-02" iyz="-2.104213e-03" izz="1.904449e-02" />
        </inertial>
    </link>
    <joint name="fr3_joint3" type="revolute">
        <parent link="fr3_link2" />
        <child link="fr3_link3" />
        <origin xyz="0 -0.316 0" rpy="1.5708 -0 0" />
        <axis xyz="0 0 1" />
        <limit lower="-2.900700" upper="2.900700" effort="87.000000" velocity="2.620000" />
        <dynamics damping="0.003000" friction="0.200000" />
    </joint>
    <link name="fr3_link4">
        <visual>
            <origin xyz="0 0 0" rpy="0 -0 0" />
            <geometry>
                <mesh filename="meshes/link4.dae" />
            </geometry>
        </visual>
        <collision>
            <origin xyz="-0.0342527 0.0433581 0.0296528" rpy="0.987054 0.673286 0.372155" />
            <geometry>
                <cylinder radius="0.081605" length="0.112189" />
            </geometry>
        </collision>
        <collision>
            <origin xyz="-0.069231 0.0799498 0.00548293" rpy="0 -0 0" />
            <geometry>
                <sphere radius="0.081605" />
            </geometry>
        </collision>
        <collision>
            <origin xyz="0.000725629 0.00676649 0.0538227" rpy="0 -0 0" />
            <geometry>
                <sphere radius="0.081605" />
            </geometry>
        </collision>
        <inertial>
            <origin xyz="-0.0459101 0.0630493 -0.00851879" rpy="0 -0 0" />
            <mass value="2.615596" />
            <inertia ixx="3.452998e-02" ixy="1.322552e-02" ixz="1.015143e-02" iyy="2.888162e-02" iyz="-9.762834e-04" izz="4.125471e-02" />
        </inertial>
    </link>
    <joint name="fr3_joint4" type="revolute">
        <parent link="fr3_link3" />
        <child link="fr3_link4" />
        <origin xyz="0.0825 0 0" rpy="1.5708 -0 0" />
        <axis xyz="0 0 1" />
        <limit lower="-3.042100" upper="-0.151800" effort="87.000000" velocity="2.620000" />
        <dynamics damping="0.003000" friction="0.200000" />
    </joint>
    <link name="fr3_link5">
        <visual>
            <origin xyz="0 0 0" rpy="0 -0 0" />
            <geometry>
                <mesh filename="meshes/link5.dae" />
            </geometry>
        </visual>
        <collision>
            <origin xyz="-0.000174971 0.0222333 -0.223245" rpy="-0.60738 0.00456768 -0.00143144" />
            <geometry>
                <cylinder radius="0.068770" length="0.039832" />
            </geometry>
        </collision>
        <collision>
            <origin xyz="-0.000265942 0.0108669 -0.239599" rpy="0 -0 0" />
            <geometry>
                <sphere radius="0.068770" />
            </geometry>
        </collision>
        <collision>
            <origin xyz="-8.40001e-05 0.0335998 -0.206891" rpy="0 -0 0" />
            <geometry>
                <sphere radius="0.068770" />
            </geometry>
        </collision>
        <collision>
            <origin xyz="0.000131336 0.0666334 -0.154291" rpy="-0.333765 -0.00195652 0.000329574" />
            <geometry>
                <cylinder radius="0.052032" length="0.024224" />
            </geometry>
        </collision>
        <collision>
            <origin xyz="0.000155034 0.0626655 -0.165734" rpy="0 -0 0" />
            <geometry>
                <sphere radius="0.052032" />
            </geometry>
        </collision>
        <collision>
            <origin xyz="0.000107639 0.0706013 -0.142847" rpy="0 -0 0" />
            <geometry>
                <sphere radius="0.052032" />
            </geometry>
        </collision>
        <collision>
            <origin xyz="0.000172543 0.0892083 -0.0350342" rpy="0.047254 0.00397214 9.38673e-05" />
            <geometry>
                <cylinder radius="0.086403" length="0.072837" />
            </geometry>
        </collision>
        <collision>
            <origin xyz="2.78843e-05 0.0909286 -0.0714117" rpy="0 -0 0" />
            <geometry>
                <sphere radius="0.086403" />
            </geometry>
        </collision>
        <collision>
            <origin xyz="0.000317201 0.0874881 0.00134319" rpy="0 -0 0" />
            <geometry>
                <sphere radius="0.086403" />
            </geometry>
        </collision>
        <inertial>
            <origin xyz="-0.00160396 0.0292536 -0.0972966" rpy="0 -0 0" />
            <mass value="2.327121" />
            <inertia ixx="5.161028e-02" ixy="-5.715173e-03" ixz="-3.567317e-03" iyy="4.787730e-02" iyz="1.067399e-02" izz="1.642363e-02" />
        </inertial>
    </link>
    <joint name="fr3_joint5" type="revolute">
        <parent link="fr3_link4" />
        <child link="fr3_link5" />
        <origin xyz="-0.0825 0.384 0" rpy="-1.5708 0 0" />
        <axis xyz="0 0 1" />
        <limit lower="-2.806500" upper="2.806500" effort="12.000000" velocity="5.260000" />
        <dynamics damping="0.003000" friction="0.200000" />
    </joint>
    <link name="fr3_link6">
        <visual>
            <origin xyz="0 0 0" rpy="0 -0 0" />
            <geometry>
                <mesh filename="meshes/link6.dae" />
            </geometry>
        </visual>
        <collision>
            <origin xyz="0.039703 0.0121281 0.0101816" rpy="-1.88567 1.23605 -1.54984" />
            <geometry>
                <cylinder radius="0.090288" length="0.065965" />
            </geometry>
        </collision>
        <collision>
            <origin xyz="0.00855143 0.00182526 0.0135374" rpy="0 -0 0" />
            <geometry>
                <sphere radius="0.090288" />
            </geometry>
        </collision>
        <collision>
            <origin xyz="0.0708547 0.0224309 0.00682583" rpy="0 -0 0" />
            <geometry>
                <sphere radius="0.090288" />
            </geometry>
        </collision>
        <collision>
            <origin xyz="0.0831349 0.024038 -0.00231962" rpy="-2.24348 1.2139 -1.92824" />
            <geometry>
                <cylinder radius="0.089993" length="0.000078" />
            </geometry>
        </collision>
        <collision>
            <origin xyz="0.0830983 0.0240273 -0.0023111" rpy="0 -0 0" />
            <geometry>
                <sphere radius="0.089993" />
            </geometry>
        </collision>
        <collision>
            <origin xyz="0.0831716 0.0240486 -0.00232813" rpy="0 -0 0" />
            <geometry>
                <sphere radius="0.089993" />
            </geometry>
        </collision>
        <inertial>
            <origin xyz="0.0597131 -0.0410295 -0.0101693" rpy="0 -0 0" />
            <mass value="1.817038" />
            <inertia ixx="5.412334e-03" ixy="6.193456e-03" ixz="1.421929e-03" iyy="1.405833e-02" iyz="-1.314075e-03" izz="1.608082e-02" />
        </inertial>
    </link>
    <joint name="fr3_joint6" type="revolute">
        <parent link="fr3_link5" />
        <child link="fr3_link6" />
        <origin xyz="0 0 0" rpy="1.5708 -0 0" />
        <axis xyz="0 0 1" />
        <limit lower="0.544500" upper="4.516900" effort="12.000000" velocity="4.180000" />
        <dynamics damping="0.003000" friction="0.200000" />
    </joint>
    <link name="fr3_link7">
        <visual>
            <origin xyz="0 0 0" rpy="0 -0 0" />
            <geometry>
                <mesh filename="meshes/link7.dae" />
            </geometry>
        </visual>
        <collision>
            <origin xyz="0.00569659 0.00568079 0.079031" rpy="-1.46384 0.78112 -0.708538" />
            <geometry>
                <cylinder radius="0.051232" length="0.039707" />
            </geometry>
        </collision>
        <collision>
            <origin xyz="-0.00828162 -0.00833698 0.077526" rpy="0 -0 0" />
            <geometry>
                <sphere radius="0.051232" />
            </geometry>
        </collision>
        <collision>
            <origin xyz="0.0196748 0.0196985 0.0805359" rpy="0 -0 0" />
            <geometry>
                <sphere radius="0.051232" />
            </geometry>
        </collision>
        <collision>
            <origin xyz="0.0512783 0.0513375 0.0852714" rpy="-1.41449 0.778863 -0.67474" />
            <geometry>
                <cylinder radius="0.041823" length="0.009467" />
            </geometry>
        </collision>
        <collision>
            <origin xyz="0.0479532 0.0480097 0.0847469" rpy="0 -0 0" />
            <geometry>
                <sphere radius="0.041823" />
            </geometry>
        </collision>
        <collision>
            <origin xyz="0.0546034 0.0546653 0.0857958" rpy="0 -0 0" />
            <geometry>
                <sphere radius="0.041823" />
            </geometry>
        </collision>
        <inertial>
            <origin xyz="0.00452258 0.00862619 -0.0161633" rpy="0 -0 0" />
            <mass value="0.627143" />
            <inertia ixx="2.109239e-04" ixy="-2.433299e-05" ixz="4.564480e-05" iyy="1.771857e-04" iyz="8.744070e-05" izz="5.993191e-05" />
        </inertial>
    </link>
    <joint name="fr3_joint7" type="revolute">
        <parent link="fr3_link6" />
        <child link="fr3_link7" />
        <origin xyz="0.088 0 0" rpy="1.5708 -0 0" />
        <axis xyz="0 0 1" />
        <limit lower="-3.015900" upper="3.015900" effort="12.000000" velocity="5.260000" />
        <dynamics damping="0.003000" friction="0.200000" />
    </joint>
    <link name="fr3_link8" />
    <joint name="fr3_joint8" type="fixed">
        <parent link="fr3_link7" />
        <child link="fr3_link8" />
        <origin xyz="0 0 0.107" rpy="0 -0 0" />
    </joint>
    <link name="world" />
    <joint name="fr3_joint_world" type="fixed">
        <parent link="world" />
        <child link="fr3_link0" />
        <origin xyz="0 0 0" rpy="0 -0 0" />
    </joint>
    <link name="hand_hand">
        <visual>
            <origin xyz="0 0 0" rpy="0 -0 0" />
            <geometry>
                <mesh filename="meshes/hand.dae" />
            </geometry>
        </visual>
        <collision>
            <origin xyz="2.82035e-06 -0.00523646 0.0238722" rpy="1.61255 -0.000187087 -0.000195066" />
            <geometry>
                <cylinder radius="0.048430" length="0.149041" />
            </geometry>
        </collision>
        <collision>
            <origin xyz="1.67621e-05 0.0692189 0.0269825" rpy="0 -0 0" />
            <geometry>
                <sphere radius="0.048430" />
            </geometry>
        </collision>
        <collision>
            <origin xyz="-1.11214e-05 -0.0796918 0.0207619" rpy="0 -0 0" />
            <geometry>
                <sphere radius="0.048430" />
            </geometry>
        </collision>
        <inertial>
            <origin xyz="-3.76e-05 0.0119128 0.020726" rpy="0 -0 0" />
            <mass value="0.654400" />
            <inertia ixx="1.860000e-03" ixy="0.000000e+00" ixz="0.000000e+00" iyy="3.000000e-04" iyz="-2.000000e-05" izz="1.740000e-03" />
        </inertial>
    </link>
    <link name="hand_leftfinger">
        <visual>
            <origin xyz="-0.0165 0.0165 0.127733" rpy="-1.5708 0.202458 -1.5708" />
            <geometry>
                <mesh filename="meshes/flex_griper_connect.stl" />
            </geometry>
        </visual>
        <collision>
            <origin xyz="-7.80177e-07 0.0142341 0.053424" rpy="-3.03427 -3.95284e-05 0.000735892" />
            <geometry>
                <cylinder radius="0.025740" length="0.007463" />
            </geometry>
        </collision>
        <collision>
            <origin xyz="-6.32675e-07 0.0138344 0.0571341" rpy="0 -0 0" />
            <geometry>
                <sphere radius="0.025740" />
            </geometry>
        </collision>
        <collision>
            <origin xyz="-9.2768e-07 0.0146338 0.0497139" rpy="0 -0 0" />
            <geometry>
                <sphere radius="0.025740" />
            </geometry>
        </collision>
        <collision>
            <origin xyz="7.04994e-07 0.00971926 0.0879297" rpy="-2.96055 -4.96385e-05 0.000546851" />
            <geometry>
                <cylinder radius="0.018054" length="0.049817" />
            </geometry>
        </collision>
        <collision>
            <origin xyz="1.94141e-06 0.00523426 0.112431" rpy="0 -0 0" />
            <geometry>
                <sphere radius="0.018054" />
            </geometry>
        </collision>
        <collision>
            <origin xyz="-5.31426e-07 0.0142043 0.0634283" rpy="0 -0 0" />
            <geometry>
                <sphere radius="0.018054" />
            </geometry>
        </collision>
        <collision>
            <origin xyz="-1.81538e-06 0.0170394 0.0273859" rpy="-3.03427 -3.95284e-05 0.000735892" />
            <geometry>
                <cylinder radius="0.026280" length="0.014368" />
            </geometry>
        </collision>
        <collision>
            <origin xyz="-1.5314e-06 0.0162699 0.0345288" rpy="0 -0 0" />
            <geometry>
                <sphere radius="0.026280" />
            </geometry>
        </collision>
        <collision>
            <origin xyz="-2.09936e-06 0.017809 0.0202431" rpy="0 -0 0" />
            <geometry>
                <sphere radius="0.026280" />
            </geometry>
        </collision>
        <inertial>
            <origin xyz="0 0.0145644 0.0227941" rpy="0 -0 0" />
            <mass value="0.100000" />
            <inertia ixx="3.012209e-05" ixy="0.000000e+00" ixz="0.000000e+00" iyy="2.958738e-05" iyz="0.000000e+00" izz="6.951252e-06" />
        </inertial>
    </link>
    <joint name="hand_finger_joint1" type="prismatic">
        <parent link="hand_hand" />
        <child link="hand_leftfinger" />
        <origin xyz="0 0 0.0584" rpy="0 -0 0" />
        <axis xyz="0 1 0" />
        <limit lower="0.000000" upper="0.040000" effort="100.000000" velocity="0.200000" />
        <dynamics damping="0.300000" friction="0.000000" />
    </joint>
    <link name="hand_rightfinger">
        <visual>
            <origin xyz="-0.0165 0.0165 0.127733" rpy="-1.5708 0.202458 -1.5708" />
            <geometry>
                <mesh filename="meshes/flex_griper_connect.stl" />
            </geometry>
        </visual>
        <collision>
            <origin xyz="-7.80177e-07 0.0142341 0.053424" rpy="-3.03427 -3.95284e-05 0.000735892" />
            <geometry>
                <cylinder radius="0.025740" length="0.007463" />
            </geometry>
        </collision>
        <collision>
            <origin xyz="-6.32675e-07 0.0138344 0.0571341" rpy="0 -0 0" />
            <geometry>
                <sphere radius="0.025740" />
            </geometry>
        </collision>
        <collision>
            <origin xyz="-9.2768e-07 0.0146338 0.0497139" rpy="0 -0 0" />
            <geometry>
                <sphere radius="0.025740" />
            </geometry>
        </collision>
        <collision>
            <origin xyz="7.04994e-07 0.00971926 0.0879297" rpy="-2.96055 -4.96385e-05 0.000546851" />
            <geometry>
                <cylinder radius="0.018054" length="0.049817" />
            </geometry>
        </collision>
        <collision>
            <origin xyz="1.94141e-06 0.00523426 0.112431" rpy="0 -0 0" />
            <geometry>
                <sphere radius="0.018054" />
            </geometry>
        </collision>
        <collision>
            <origin xyz="-5.31426e-07 0.0142043 0.0634283" rpy="0 -0 0" />
            <geometry>
                <sphere radius="0.018054" />
            </geometry>
        </collision>
        <collision>
            <origin xyz="-1.81538e-06 0.0170394 0.0273859" rpy="-3.03427 -3.95284e-05 0.000735892" />
            <geometry>
                <cylinder radius="0.026280" length="0.014368" />
            </geometry>
        </collision>
        <collision>
            <origin xyz="-1.5314e-06 0.0162699 0.0345288" rpy="0 -0 0" />
            <geometry>
                <sphere radius="0.026280" />
            </geometry>
        </collision>
        <collision>
            <origin xyz="-2.09936e-06 0.017809 0.0202431" rpy="0 -0 0" />
            <geometry>
                <sphere radius="0.026280" />
            </geometry>
        </collision>
        <inertial>
            <origin xyz="0 0.0145644 0.0227941" rpy="0 -0 3.14159" />
            <mass value="0.100000" />
            <inertia ixx="3.012209e-05" ixy="0.000000e+00" ixz="0.000000e+00" iyy="2.958738e-05" iyz="0.000000e+00" izz="6.951252e-06" />
        </inertial>
    </link>
    <joint name="hand_finger_joint2" type="prismatic">
        <parent link="hand_hand" />
        <child link="hand_rightfinger" />
        <origin xyz="0 0 0.0584" rpy="0 -0 3.14159" />
        <axis xyz="0 1 0" />
        <limit lower="0.000000" upper="0.040000" effort="100.000000" velocity="0.200000" />
        <dynamics damping="0.300000" friction="0.000000" />
    </joint>
    <link name="hand_hand_tcp" />
    <joint name="hand_hand_tcp_joint" type="fixed">
        <parent link="hand_hand" />
        <child link="hand_hand_tcp" />
        <origin xyz="0 0 0.1034" rpy="0 -0 0" />
    </joint>
    <joint name="hand_joint_fr3_link8" type="fixed">
        <parent link="fr3_link8" />
        <child link="hand_hand" />
        <origin xyz="0 0 0" rpy="0 0 -0.785398" />
    </joint>
</robot>