<?xml version='1.0' encoding='utf-8'?>
<robot name="bot">
    <link name="fr3_link0">
        <visual>
            <origin xyz="0 0 0" rpy="0 -0 0" />
            <geometry>
                <mesh filename="meshes/link0.dae" />
            </geometry>
        </visual>
        <collision>
            <origin xyz="-0.00502796 3.03191e-05 0.0638593" rpy="0 -0 0" />
            <geometry>
                <sphere radius="0.097890" />
            </geometry>
        </collision>
        <collision>
            <origin xyz="-0.0988262 0.0225491 0.0326812" rpy="0 -0 0" />
            <geometry>
                <sphere radius="0.065233" />
            </geometry>
        </collision>
        <collision>
            <origin xyz="-0.102782 -0.020493 0.0299124" rpy="0 -0 0" />
            <geometry>
                <sphere radius="0.062523" />
            </geometry>
        </collision>
        <collision>
            <origin xyz="-0.0259722 0.00414787 0.0655118" rpy="0 -0 0" />
            <geometry>
                <sphere radius="0.091497" />
            </geometry>
        </collision>
        <collision>
            <origin xyz="-0.0151273 -0.0543495 0.0132872" rpy="0 -0 0" />
            <geometry>
                <sphere radius="0.045094" />
            </geometry>
        </collision>
        <collision>
            <origin xyz="-0.0638213 0.0769316 0.00455215" rpy="0 -0 0" />
            <geometry>
                <sphere radius="0.019236" />
            </geometry>
        </collision>
        <collision>
            <origin xyz="-0.0141844 0.0515305 0.0161664" rpy="0 -0 0" />
            <geometry>
                <sphere radius="0.047938" />
            </geometry>
        </collision>
        <collision>
            <origin xyz="-0.0658055 -0.0684812 0.00462755" rpy="0 -0 0" />
            <geometry>
                <sphere radius="0.026175" />
            </geometry>
        </collision>
        <inertial>
            <origin xyz="-0.0172 0.0004 0.0745" rpy="0 -0 0" />
            <mass value="2.396600" />
            <inertia ixx="9.000000e-03" ixy="0.000000e+00" ixz="2.000000e-03" iyy="1.150000e-02" iyz="0.000000e+00" izz="8.500000e-03" />
        </inertial>
    </link>
    <link name="fr3_link1">
        <visual>
            <origin xyz="0 0 0" rpy="0 -0 0" />
            <geometry>
                <mesh filename="meshes/link1.dae" />
            </geometry>
        </visual>
        <collision>
            <origin xyz="-1.96421e-05 -0.0554798 -0.000350991" rpy="0 -0 0" />
            <geometry>
                <sphere radius="0.076886" />
            </geometry>
        </collision>
        <collision>
            <origin xyz="0.000135988 -3.15343e-05 -0.139378" rpy="0 -0 0" />
            <geometry>
                <sphere radius="0.075285" />
            </geometry>
        </collision>
        <collision>
            <origin xyz="-0.0158102 -0.0393214 -0.0689131" rpy="0 -0 0" />
            <geometry>
                <sphere radius="0.045917" />
            </geometry>
        </collision>
        <collision>
            <origin xyz="0.0187935 -0.035706 -0.0764657" rpy="0 -0 0" />
            <geometry>
                <sphere radius="0.041923" />
            </geometry>
        </collision>
        <collision>
            <origin xyz="-0.0385739 -0.0228966 -0.0871971" rpy="0 -0 0" />
            <geometry>
                <sphere radius="0.016680" />
            </geometry>
        </collision>
        <collision>
            <origin xyz="0.0233492 -0.0408262 -0.0509195" rpy="0 -0 0" />
            <geometry>
                <sphere radius="0.031338" />
            </geometry>
        </collision>
        <inertial>
            <origin xyz="4.128e-07 -0.0181251 -0.0386036" rpy="0 -0 0" />
            <mass value="2.927465" />
            <inertia ixx="2.392732e-02" ixy="1.331790e-05" ixz="-1.140477e-04" iyy="2.248216e-02" iyz="-1.995032e-03" izz="6.350098e-03" />
        </inertial>
    </link>
    <joint name="fr3_joint1" type="revolute">
        <parent link="fr3_link0" />
        <child link="fr3_link1" />
        <origin xyz="0 0 0.333" rpy="0 -0 0" />
        <axis xyz="0 0 1" />
        <limit lower="-2.743700" upper="2.743700" effort="87.000000" velocity="2.620000" />
        <dynamics damping="0.003000" friction="0.200000" />
    </joint>
    <link name="fr3_link2">
        <visual>
            <origin xyz="0 0 0" rpy="0 -0 0" />
            <geometry>
                <mesh filename="meshes/link2.dae" />
            </geometry>
        </visual>
        <collision>
            <origin xyz="-2.66949e-05 -0.140427 -0.000222234" rpy="0 -0 0" />
            <geometry>
                <sphere radius="0.075363" />
            </geometry>
        </collision>
        <collision>
            <origin xyz="0.000690686 -0.00314771 0.0548543" rpy="0 -0 0" />
            <geometry>
                <sphere radius="0.076172" />
            </geometry>
        </collision>
        <collision>
            <origin xyz="-0.0195716 0.0261234 0.022061" rpy="0 -0 0" />
            <geometry>
                <sphere radius="0.032312" />
            </geometry>
        </collision>
        <collision>
            <origin xyz="-0.0159581 -0.076903 0.0369456" rpy="0 -0 0" />
            <geometry>
                <sphere radius="0.044956" />
            </geometry>
        </collision>
        <collision>
            <origin xyz="-0.0312543 0.00382377 0.023838" rpy="0 -0 0" />
            <geometry>
                <sphere radius="0.034652" />
            </geometry>
        </collision>
        <collision>
            <origin xyz="0.00845347 0.0161487 0.0363647" rpy="0 -0 0" />
            <geometry>
                <sphere radius="0.053180" />
            </geometry>
        </collision>
        <collision>
            <origin xyz="0.0192488 -0.0742832 0.0366172" rpy="0 -0 0" />
            <geometry>
                <sphere radius="0.043727" />
            </geometry>
        </collision>
        <inertial>
            <origin xyz="0.00318289 -0.0743222 0.00881461" rpy="0 -0 0" />
            <mass value="2.935537" />
            <inertia ixx="4.193895e-02" ixy="2.025733e-04" ixz="4.077784e-03" iyy="2.514515e-02" iyz="-4.225216e-03" izz="6.170214e-02" />
        </inertial>
    </link>
    <joint name="fr3_joint2" type="revolute">
        <parent link="fr3_link1" />
        <child link="fr3_link2" />
        <origin xyz="0 0 0" rpy="-1.5708 0 0" />
        <axis xyz="0 0 1" />
        <limit lower="-1.783700" upper="1.783700" effort="87.000000" velocity="2.620000" />
        <dynamics damping="0.003000" friction="0.200000" />
    </joint>
    <link name="fr3_link3">
        <visual>
            <origin xyz="0 0 0" rpy="0 -0 0" />
            <geometry>
                <mesh filename="meshes/link3.dae" />
            </geometry>
        </visual>
        <collision>
            <origin xyz="0.0816365 0.0511491 0.00146336" rpy="0 -0 0" />
            <geometry>
                <sphere radius="0.073830" />
            </geometry>
        </collision>
        <collision>
            <origin xyz="-0.000844373 0.000833979 -0.0712848" rpy="0 -0 0" />
            <geometry>
                <sphere radius="0.072965" />
            </geometry>
        </collision>
        <collision>
            <origin xyz="0.00452192 0.000974114 -0.0733276" rpy="0 -0 0" />
            <geometry>
                <sphere radius="0.070525" />
            </geometry>
        </collision>
        <collision>
            <origin xyz="-0.00700946 -0.0203464 -0.0891946" rpy="0 -0 0" />
            <geometry>
                <sphere radius="0.050813" />
            </geometry>
        </collision>
        <collision>
            <origin xyz="0.103535 0.0328642 0.000752593" rpy="0 -0 0" />
            <geometry>
                <sphere radius="0.051473" />
            </geometry>
        </collision>
        <collision>
            <origin xyz="0.0370639 0.0228015 -0.0207311" rpy="0 -0 0" />
            <geometry>
                <sphere radius="0.038257" />
            </geometry>
        </collision>
        <collision>
            <origin xyz="0.0832711 0.0383283 0.0168965" rpy="0 -0 0" />
            <geometry>
                <sphere radius="0.058471" />
            </geometry>
        </collision>
        <collision>
            <origin xyz="0.0650065 0.0219432 -0.0345431" rpy="0 -0 0" />
            <geometry>
                <sphere radius="0.029829" />
            </geometry>
        </collision>
        <inertial>
            <origin xyz="0.0407016 -0.00482006 -0.0289731" rpy="0 -0 0" />
            <mass value="2.244901" />
            <inertia ixx="2.410143e-02" ixy="2.404695e-03" ixz="-2.856269e-03" iyy="1.974053e-02" iyz="-2.104213e-03" izz="1.904449e-02" />
        </inertial>
    </link>
    <joint name="fr3_joint3" type="revolute">
        <parent link="fr3_link2" />
        <child link="fr3_link3" />
        <origin xyz="0 -0.316 0" rpy="1.5708 -0 0" />
        <axis xyz="0 0 1" />
        <limit lower="-2.900700" upper="2.900700" effort="87.000000" velocity="2.620000" />
        <dynamics damping="0.003000" friction="0.200000" />
    </joint>
    <link name="fr3_link4">
        <visual>
            <origin xyz="0 0 0" rpy="0 -0 0" />
            <geometry>
                <mesh filename="meshes/link4.dae" />
            </geometry>
        </visual>
        <collision>
            <origin xyz="-0.00290368 0.00281151 0.0491178" rpy="0 -0 0" />
            <geometry>
                <sphere radius="0.071623" />
            </geometry>
        </collision>
        <collision>
            <origin xyz="-0.082573 0.0724 0.000127859" rpy="0 -0 0" />
            <geometry>
                <sphere radius="0.074061" />
            </geometry>
        </collision>
        <collision>
            <origin xyz="-0.0162433 -0.0230709 0.0262942" rpy="0 -0 0" />
            <geometry>
                <sphere radius="0.041514" />
            </geometry>
        </collision>
        <collision>
            <origin xyz="0.0215916 0.0143764 0.0284475" rpy="0 -0 0" />
            <geometry>
                <sphere radius="0.040815" />
            </geometry>
        </collision>
        <collision>
            <origin xyz="0.0125497 -0.026489 0.0253028" rpy="0 -0 0" />
            <geometry>
                <sphere radius="0.038823" />
            </geometry>
        </collision>
        <collision>
            <origin xyz="0.0322434 -0.00676463 0.021862" rpy="0 -0 0" />
            <geometry>
                <sphere radius="0.034599" />
            </geometry>
        </collision>
        <collision>
            <origin xyz="-0.0411474 0.0121691 0.0212764" rpy="0 -0 0" />
            <geometry>
                <sphere radius="0.029371" />
            </geometry>
        </collision>
        <inertial>
            <origin xyz="-0.0459101 0.0630493 -0.00851879" rpy="0 -0 0" />
            <mass value="2.615596" />
            <inertia ixx="3.452998e-02" ixy="1.322552e-02" ixz="1.015143e-02" iyy="2.888162e-02" iyz="-9.762834e-04" izz="4.125471e-02" />
        </inertial>
    </link>
    <joint name="fr3_joint4" type="revolute">
        <parent link="fr3_link3" />
        <child link="fr3_link4" />
        <origin xyz="0.0825 0 0" rpy="1.5708 -0 0" />
        <axis xyz="0 0 1" />
        <limit lower="-3.042100" upper="-0.151800" effort="87.000000" velocity="2.620000" />
        <dynamics damping="0.003000" friction="0.200000" />
    </joint>
    <link name="fr3_link5">
        <visual>
            <origin xyz="0 0 0" rpy="0 -0 0" />
            <geometry>
                <mesh filename="meshes/link5.dae" />
            </geometry>
        </visual>
        <collision>
            <origin xyz="0.000185339 -0.000420607 -0.215993" rpy="0 -0 0" />
            <geometry>
                <sphere radius="0.068792" />
            </geometry>
        </collision>
        <collision>
            <origin xyz="-2.74908e-05 0.0633469 0.00115377" rpy="0 -0 0" />
            <geometry>
                <sphere radius="0.066684" />
            </geometry>
        </collision>
        <collision>
            <origin xyz="-0.000669498 0.0525702 -0.183321" rpy="0 -0 0" />
            <geometry>
                <sphere radius="0.045243" />
            </geometry>
        </collision>
        <collision>
            <origin xyz="-0.000376146 0.0833461 -0.00607282" rpy="0 -0 0" />
            <geometry>
                <sphere radius="0.060318" />
            </geometry>
        </collision>
        <collision>
            <origin xyz="-0.000571864 0.0841397 -0.116695" rpy="0 -0 0" />
            <geometry>
                <sphere radius="0.036017" />
            </geometry>
        </collision>
        <collision>
            <origin xyz="0.000260321 0.0217735 -0.219437" rpy="0 -0 0" />
            <geometry>
                <sphere radius="0.052633" />
            </geometry>
        </collision>
        <collision>
            <origin xyz="0.000572158 0.0738319 -0.151628" rpy="0 -0 0" />
            <geometry>
                <sphere radius="0.037193" />
            </geometry>
        </collision>
        <collision>
            <origin xyz="0.00102099 0.0917936 -0.0728866" rpy="0 -0 0" />
            <geometry>
                <sphere radius="0.040813" />
            </geometry>
        </collision>
        <inertial>
            <origin xyz="-0.00160396 0.0292536 -0.0972966" rpy="0 -0 0" />
            <mass value="2.327121" />
            <inertia ixx="5.161028e-02" ixy="-5.715173e-03" ixz="-3.567317e-03" iyy="4.787730e-02" iyz="1.067399e-02" izz="1.642363e-02" />
        </inertial>
    </link>
    <joint name="fr3_joint5" type="revolute">
        <parent link="fr3_link4" />
        <child link="fr3_link5" />
        <origin xyz="-0.0825 0.384 0" rpy="-1.5708 0 0" />
        <axis xyz="0 0 1" />
        <limit lower="-2.806500" upper="2.806500" effort="12.000000" velocity="5.260000" />
        <dynamics damping="0.003000" friction="0.200000" />
    </joint>
    <link name="fr3_link6">
        <visual>
            <origin xyz="0 0 0" rpy="0 -0 0" />
            <geometry>
                <mesh filename="meshes/link6.dae" />
            </geometry>
        </visual>
        <collision>
            <origin xyz="-0.00399556 0.0174593 0.0149736" rpy="0 -0 0" />
            <geometry>
                <sphere radius="0.044378" />
            </geometry>
        </collision>
        <collision>
            <origin xyz="0.0886532 -0.00981432 -6.16892e-05" rpy="0 -0 0" />
            <geometry>
                <sphere radius="0.059939" />
            </geometry>
        </collision>
        <collision>
            <origin xyz="0.081693 0.0384406 0.00189205" rpy="0 -0 0" />
            <geometry>
                <sphere radius="0.050775" />
            </geometry>
        </collision>
        <collision>
            <origin xyz="0.0293554 0.00046824 0.0242573" rpy="0 -0 0" />
            <geometry>
                <sphere radius="0.043046" />
            </geometry>
        </collision>
        <collision>
            <origin xyz="-0.0173852 -0.000240689 0.01537" rpy="0 -0 0" />
            <geometry>
                <sphere radius="0.046734" />
            </geometry>
        </collision>
        <collision>
            <origin xyz="0.0609892 -0.0261793 0.00345603" rpy="0 -0 0" />
            <geometry>
                <sphere radius="0.038000" />
            </geometry>
        </collision>
        <collision>
            <origin xyz="-0.00030341 -0.0192336 0.0135651" rpy="0 -0 0" />
            <geometry>
                <sphere radius="0.045064" />
            </geometry>
        </collision>
        <collision>
            <origin xyz="0.0362316 0.0407423 0.00736301" rpy="0 -0 0" />
            <geometry>
                <sphere radius="0.032942" />
            </geometry>
        </collision>
        <inertial>
            <origin xyz="0.0597131 -0.0410295 -0.0101693" rpy="0 -0 0" />
            <mass value="1.817038" />
            <inertia ixx="5.412334e-03" ixy="6.193456e-03" ixz="1.421929e-03" iyy="1.405833e-02" iyz="-1.314075e-03" izz="1.608082e-02" />
        </inertial>
    </link>
    <joint name="fr3_joint6" type="revolute">
        <parent link="fr3_link5" />
        <child link="fr3_link6" />
        <origin xyz="0 0 0" rpy="1.5708 -0 0" />
        <axis xyz="0 0 1" />
        <limit lower="0.544500" upper="4.516900" effort="12.000000" velocity="4.180000" />
        <dynamics damping="0.003000" friction="0.200000" />
    </joint>
    <link name="fr3_link7">
        <visual>
            <origin xyz="0 0 0" rpy="0 -0 0" />
            <geometry>
                <mesh filename="meshes/link7.dae" />
            </geometry>
        </visual>
        <collision>
            <origin xyz="0.0382428 0.0622922 0.086866" rpy="0 -0 0" />
            <geometry>
                <sphere radius="0.019873" />
            </geometry>
        </collision>
        <collision>
            <origin xyz="0.0041752 -0.0170902 0.0710056" rpy="0 -0 0" />
            <geometry>
                <sphere radius="0.041720" />
            </geometry>
        </collision>
        <collision>
            <origin xyz="0.023731 0.00598199 0.0748544" rpy="0 -0 0" />
            <geometry>
                <sphere radius="0.038414" />
            </geometry>
        </collision>
        <collision>
            <origin xyz="-0.0176612 -0.00622239 0.0714394" rpy="0 -0 0" />
            <geometry>
                <sphere radius="0.041356" />
            </geometry>
        </collision>
        <collision>
            <origin xyz="0.0488181 0.0223909 0.0841225" rpy="0 -0 0" />
            <geometry>
                <sphere radius="0.020777" />
            </geometry>
        </collision>
        <collision>
            <origin xyz="0.0204923 0.0464431 0.0822114" rpy="0 -0 0" />
            <geometry>
                <sphere radius="0.024859" />
            </geometry>
        </collision>
        <collision>
            <origin xyz="0.0564729 0.041841 0.0865083" rpy="0 -0 0" />
            <geometry>
                <sphere radius="0.025720" />
            </geometry>
        </collision>
        <collision>
            <origin xyz="-0.00620334 0.0194356 0.0730581" rpy="0 -0 0" />
            <geometry>
                <sphere radius="0.039916" />
            </geometry>
        </collision>
        <inertial>
            <origin xyz="0.00452258 0.00862619 -0.0161633" rpy="0 -0 0" />
            <mass value="0.627143" />
            <inertia ixx="2.109239e-04" ixy="-2.433299e-05" ixz="4.564480e-05" iyy="1.771857e-04" iyz="8.744070e-05" izz="5.993191e-05" />
        </inertial>
    </link>
    <joint name="fr3_joint7" type="revolute">
        <parent link="fr3_link6" />
        <child link="fr3_link7" />
        <origin xyz="0.088 0 0" rpy="1.5708 -0 0" />
        <axis xyz="0 0 1" />
        <limit lower="-3.015900" upper="3.015900" effort="12.000000" velocity="5.260000" />
        <dynamics damping="0.003000" friction="0.200000" />
    </joint>
    <link name="fr3_link8" />
    <joint name="fr3_joint8" type="fixed">
        <parent link="fr3_link7" />
        <child link="fr3_link8" />
        <origin xyz="0 0 0.107" rpy="0 -0 0" />
    </joint>
    <link name="world" />
    <joint name="fr3_joint_world" type="fixed">
        <parent link="world" />
        <child link="fr3_link0" />
        <origin xyz="0 0 0" rpy="0 -0 0" />
    </joint>
    <link name="hand_hand">
        <visual>
            <origin xyz="0 0 0" rpy="0 -0 0" />
            <geometry>
                <mesh filename="meshes/hand.dae" />
            </geometry>
        </visual>
        <collision>
            <origin xyz="0.0153837 -0.0667018 0.0173947" rpy="0 -0 0" />
            <geometry>
                <sphere radius="0.049274" />
            </geometry>
        </collision>
        <collision>
            <origin xyz="-0.0154583 0.0687094 0.0172281" rpy="0 -0 0" />
            <geometry>
                <sphere radius="0.049097" />
            </geometry>
        </collision>
        <collision>
            <origin xyz="-0.0179202 -0.031396 0.0390229" rpy="0 -0 0" />
            <geometry>
                <sphere radius="0.047866" />
            </geometry>
        </collision>
        <collision>
            <origin xyz="0.00627867 0.0197593 7.8774e-07" rpy="0 -0 0" />
            <geometry>
                <sphere radius="0.043650" />
            </geometry>
        </collision>
        <collision>
            <origin xyz="0.0028145 0.0224741 0.0583997" rpy="0 -0 0" />
            <geometry>
                <sphere radius="0.034280" />
            </geometry>
        </collision>
        <collision>
            <origin xyz="0.00296839 0.0807183 0.065925" rpy="0 -0 0" />
            <geometry>
                <sphere radius="0.037690" />
            </geometry>
        </collision>
        <collision>
            <origin xyz="-0.00605203 -0.0908043 0.0657482" rpy="0 -0 0" />
            <geometry>
                <sphere radius="0.029047" />
            </geometry>
        </collision>
        <inertial>
            <origin xyz="-3.76e-05 0.0119128 0.020726" rpy="0 -0 0" />
            <mass value="0.654400" />
            <inertia ixx="1.860000e-03" ixy="0.000000e+00" ixz="0.000000e+00" iyy="3.000000e-04" iyz="-2.000000e-05" izz="1.740000e-03" />
        </inertial>
    </link>
    <link name="hand_leftfinger">
        <visual>
            <origin xyz="-0.0165 0.0165 0.127733" rpy="-1.5708 0.202458 -1.5708" />
            <geometry>
                <mesh filename="meshes/flex_griper_connect.stl" />
            </geometry>
        </visual>
        <collision>
            <origin xyz="2.85677e-07 0.0120494 0.0746126" rpy="0 -0 0" />
            <geometry>
                <sphere radius="0.016112" />
            </geometry>
        </collision>
        <collision>
            <origin xyz="0.000520517 0.00419438 0.113085" rpy="0 -0 0" />
            <geometry>
                <sphere radius="0.013462" />
            </geometry>
        </collision>
        <collision>
            <origin xyz="0.00110377 0.0182587 0.0448001" rpy="0 -0 0" />
            <geometry>
                <sphere radius="0.026667" />
            </geometry>
        </collision>
        <collision>
            <origin xyz="-0.0118234 0.0300333 0.0256996" rpy="0 -0 0" />
            <geometry>
                <sphere radius="0.009485" />
            </geometry>
        </collision>
        <collision>
            <origin xyz="-0.000551583 0.00814576 0.093836" rpy="0 -0 0" />
            <geometry>
                <sphere radius="0.014089" />
            </geometry>
        </collision>
        <collision>
            <origin xyz="0.000141599 0.0216961 0.00640947" rpy="0 -0 0" />
            <geometry>
                <sphere radius="0.016831" />
            </geometry>
        </collision>
        <collision>
            <origin xyz="-0.0107718 0.0134431 0.0220573" rpy="0 -0 0" />
            <geometry>
                <sphere radius="0.010171" />
            </geometry>
        </collision>
        <collision>
            <origin xyz="0.00638043 0.0231311 0.0208771" rpy="0 -0 0" />
            <geometry>
                <sphere radius="0.018591" />
            </geometry>
        </collision>
        <inertial>
            <origin xyz="0 0.0145644 0.0227941" rpy="0 -0 0" />
            <mass value="0.100000" />
            <inertia ixx="3.012209e-05" ixy="0.000000e+00" ixz="0.000000e+00" iyy="2.958738e-05" iyz="0.000000e+00" izz="6.951252e-06" />
        </inertial>
    </link>
    <joint name="hand_finger_joint1" type="prismatic">
        <parent link="hand_hand" />
        <child link="hand_leftfinger" />
        <origin xyz="0 0 0.0584" rpy="0 -0 0" />
        <axis xyz="0 1 0" />
        <limit lower="0.000000" upper="0.040000" effort="100.000000" velocity="0.200000" />
        <dynamics damping="0.300000" friction="0.000000" />
    </joint>
    <link name="hand_rightfinger">
        <visual>
            <origin xyz="-0.0165 0.0165 0.127733" rpy="-1.5708 0.202458 -1.5708" />
            <geometry>
                <mesh filename="meshes/flex_griper_connect.stl" />
            </geometry>
        </visual>
        <collision>
            <origin xyz="0.00102668 0.0181498 0.0450979" rpy="0 -0 0" />
            <geometry>
                <sphere radius="0.026935" />
            </geometry>
        </collision>
        <collision>
            <origin xyz="0.000533909 0.00424238 0.112853" rpy="0 -0 0" />
            <geometry>
                <sphere radius="0.013646" />
            </geometry>
        </collision>
        <collision>
            <origin xyz="0.00758027 0.0231087 0.0217299" rpy="0 -0 0" />
            <geometry>
                <sphere radius="0.017617" />
            </geometry>
        </collision>
        <collision>
            <origin xyz="-1.60947e-07 0.0123306 0.075024" rpy="0 -0 0" />
            <geometry>
                <sphere radius="0.015809" />
            </geometry>
        </collision>
        <collision>
            <origin xyz="-0.000436958 0.00828466 0.093154" rpy="0 -0 0" />
            <geometry>
                <sphere radius="0.014128" />
            </geometry>
        </collision>
        <collision>
            <origin xyz="3.67358e-05 0.0215578 0.00544787" rpy="0 -0 0" />
            <geometry>
                <sphere radius="0.016380" />
            </geometry>
        </collision>
        <collision>
            <origin xyz="-0.00647271 0.0242406 0.0211314" rpy="0 -0 0" />
            <geometry>
                <sphere radius="0.018167" />
            </geometry>
        </collision>
        <inertial>
            <origin xyz="0 0.0145644 0.0227941" rpy="0 -0 3.14159" />
            <mass value="0.100000" />
            <inertia ixx="3.012209e-05" ixy="0.000000e+00" ixz="0.000000e+00" iyy="2.958738e-05" iyz="0.000000e+00" izz="6.951252e-06" />
        </inertial>
    </link>
    <joint name="hand_finger_joint2" type="prismatic">
        <parent link="hand_hand" />
        <child link="hand_rightfinger" />
        <origin xyz="0 0 0.0584" rpy="0 -0 3.14159" />
        <axis xyz="0 1 0" />
        <limit lower="0.000000" upper="0.040000" effort="100.000000" velocity="0.200000" />
        <dynamics damping="0.300000" friction="0.000000" />
    </joint>
    <link name="hand_hand_tcp" />
    <joint name="hand_hand_tcp_joint" type="fixed">
        <parent link="hand_hand" />
        <child link="hand_hand_tcp" />
        <origin xyz="0 0 0.1034" rpy="0 -0 0" />
    </joint>
    <joint name="hand_joint_fr3_link8" type="fixed">
        <parent link="fr3_link8" />
        <child link="hand_hand" />
        <origin xyz="0 0 0" rpy="0 0 -0.785398" />
    </joint>
</robot>