<?xml version='1.0' encoding='utf-8'?>
<robot name="bot">
    <link name="fr3_link0">
        <visual>
            <origin xyz="0 0 0" rpy="0 -0 0" />
            <geometry>
                <mesh filename="meshes/link0.dae" />
            </geometry>
        </visual>
        <collision>
            <origin xyz="-0.00880641 9.92503e-06 0.0663966" rpy="0 -0 0" />
            <geometry>
                <sphere radius="0.102419" />
            </geometry>
        </collision>
        <collision>
            <origin xyz="-0.0999895 0.0235581 0.0315205" rpy="0 -0 0" />
            <geometry>
                <sphere radius="0.063341" />
            </geometry>
        </collision>
        <collision>
            <origin xyz="-0.102577 -0.0204548 0.0300868" rpy="0 -0 0" />
            <geometry>
                <sphere radius="0.062736" />
            </geometry>
        </collision>
        <collision>
            <origin xyz="-0.014563 -0.0537388 0.0139479" rpy="0 -0 0" />
            <geometry>
                <sphere radius="0.045522" />
            </geometry>
        </collision>
        <collision>
            <origin xyz="-0.0618853 0.0756516 0.00458507" rpy="0 -0 0" />
            <geometry>
                <sphere radius="0.022296" />
            </geometry>
        </collision>
        <collision>
            <origin xyz="-0.0124674 0.0544104 0.0137383" rpy="0 -0 0" />
            <geometry>
                <sphere radius="0.044023" />
            </geometry>
        </collision>
        <collision>
            <origin xyz="-0.0663042 -0.0729589 0.0045886" rpy="0 -0 0" />
            <geometry>
                <sphere radius="0.024740" />
            </geometry>
        </collision>
        <inertial>
            <origin xyz="-0.0172 0.0004 0.0745" rpy="0 -0 0" />
            <mass value="2.396600" />
            <inertia ixx="9.000000e-03" ixy="0.000000e+00" ixz="2.000000e-03" iyy="1.150000e-02" iyz="0.000000e+00" izz="8.500000e-03" />
        </inertial>
    </link>
    <link name="fr3_link1">
        <visual>
            <origin xyz="0 0 0" rpy="0 -0 0" />
            <geometry>
                <mesh filename="meshes/link1.dae" />
            </geometry>
        </visual>
        <collision>
            <origin xyz="-1.59067e-05 -0.0555051 -0.000558925" rpy="0 -0 0" />
            <geometry>
                <sphere radius="0.077043" />
            </geometry>
        </collision>
        <collision>
            <origin xyz="0.01714 -0.0269693 -0.0960756" rpy="0 -0 0" />
            <geometry>
                <sphere radius="0.041934" />
            </geometry>
        </collision>
        <collision>
            <origin xyz="-0.0421366 -0.0213203 -0.0891554" rpy="0 -0 0" />
            <geometry>
                <sphere radius="0.012660" />
            </geometry>
        </collision>
        <collision>
            <origin xyz="0.00015864 -2.76258e-05 -0.13938" rpy="0 -0 0" />
            <geometry>
                <sphere radius="0.075281" />
            </geometry>
        </collision>
        <collision>
            <origin xyz="-0.0175274 -0.0371806 -0.0737994" rpy="0 -0 0" />
            <geometry>
                <sphere radius="0.042164" />
            </geometry>
        </collision>
        <collision>
            <origin xyz="0.0155675 -0.0413249 -0.0621145" rpy="0 -0 0" />
            <geometry>
                <sphere radius="0.043576" />
            </geometry>
        </collision>
        <inertial>
            <origin xyz="4.128e-07 -0.0181251 -0.0386036" rpy="0 -0 0" />
            <mass value="2.927465" />
            <inertia ixx="2.392732e-02" ixy="1.331790e-05" ixz="-1.140477e-04" iyy="2.248216e-02" iyz="-1.995032e-03" izz="6.350098e-03" />
        </inertial>
    </link>
    <joint name="fr3_joint1" type="revolute">
        <parent link="fr3_link0" />
        <child link="fr3_link1" />
        <origin xyz="0 0 0.333" rpy="0 -0 0" />
        <axis xyz="0 0 1" />
        <limit lower="-2.743700" upper="2.743700" effort="87.000000" velocity="2.620000" />
        <dynamics damping="0.003000" friction="0.200000" />
    </joint>
    <link name="fr3_link2">
        <visual>
            <origin xyz="0 0 0" rpy="0 -0 0" />
            <geometry>
                <mesh filename="meshes/link2.dae" />
            </geometry>
        </visual>
        <collision>
            <origin xyz="3.36613e-07 -0.00118299 0.055496" rpy="0 -0 0" />
            <geometry>
                <sphere radius="0.076789" />
            </geometry>
        </collision>
        <collision>
            <origin xyz="-1.26969e-05 -0.140391 -9.11539e-05" rpy="0 -0 0" />
            <geometry>
                <sphere radius="0.075360" />
            </geometry>
        </collision>
        <collision>
            <origin xyz="-0.0154742 -0.10262 0.0243878" rpy="0 -0 0" />
            <geometry>
                <sphere radius="0.044385" />
            </geometry>
        </collision>
        <collision>
            <origin xyz="-0.0189003 -0.0686569 0.0385869" rpy="0 -0 0" />
            <geometry>
                <sphere radius="0.039931" />
            </geometry>
        </collision>
        <collision>
            <origin xyz="0.0121858 -0.0641145 0.0421875" rpy="0 -0 0" />
            <geometry>
                <sphere radius="0.043567" />
            </geometry>
        </collision>
        <collision>
            <origin xyz="0.0311514 -0.0824111 0.0284961" rpy="0 -0 0" />
            <geometry>
                <sphere radius="0.026841" />
            </geometry>
        </collision>
        <inertial>
            <origin xyz="0.00318289 -0.0743222 0.00881461" rpy="0 -0 0" />
            <mass value="2.935537" />
            <inertia ixx="4.193895e-02" ixy="2.025733e-04" ixz="4.077784e-03" iyy="2.514515e-02" iyz="-4.225216e-03" izz="6.170214e-02" />
        </inertial>
    </link>
    <joint name="fr3_joint2" type="revolute">
        <parent link="fr3_link1" />
        <child link="fr3_link2" />
        <origin xyz="0 0 0" rpy="-1.5708 0 0" />
        <axis xyz="0 0 1" />
        <limit lower="-1.783700" upper="1.783700" effort="87.000000" velocity="2.620000" />
        <dynamics damping="0.003000" friction="0.200000" />
    </joint>
    <link name="fr3_link3">
        <visual>
            <origin xyz="0 0 0" rpy="0 -0 0" />
            <geometry>
                <mesh filename="meshes/link3.dae" />
            </geometry>
        </visual>
        <collision>
            <origin xyz="0.0782503 0.049202 -0.000785864" rpy="0 -0 0" />
            <geometry>
                <sphere radius="0.071222" />
            </geometry>
        </collision>
        <collision>
            <origin xyz="-0.00017882 9.12983e-05 -0.0704795" rpy="0 -0 0" />
            <geometry>
                <sphere radius="0.073944" />
            </geometry>
        </collision>
        <collision>
            <origin xyz="0.0831225 0.037421 0.0179656" rpy="0 -0 0" />
            <geometry>
                <sphere radius="0.057650" />
            </geometry>
        </collision>
        <collision>
            <origin xyz="0.0427483 0.0295603 -0.0253737" rpy="0 -0 0" />
            <geometry>
                <sphere radius="0.043055" />
            </geometry>
        </collision>
        <collision>
            <origin xyz="0.0610775 0.013875 -0.0458189" rpy="0 -0 0" />
            <geometry>
                <sphere radius="0.018411" />
            </geometry>
        </collision>
        <collision>
            <origin xyz="0.0166472 0.0317022 -0.10245" rpy="0 -0 0" />
            <geometry>
                <sphere radius="0.027189" />
            </geometry>
        </collision>
        <collision>
            <origin xyz="0.11219 0.0244311 0.00754044" rpy="0 -0 0" />
            <geometry>
                <sphere radius="0.038337" />
            </geometry>
        </collision>
        <collision>
            <origin xyz="0.107364 0.0209514 -0.0211163" rpy="0 -0 0" />
            <geometry>
                <sphere radius="0.033132" />
            </geometry>
        </collision>
        <inertial>
            <origin xyz="0.0407016 -0.00482006 -0.0289731" rpy="0 -0 0" />
            <mass value="2.244901" />
            <inertia ixx="2.410143e-02" ixy="2.404695e-03" ixz="-2.856269e-03" iyy="1.974053e-02" iyz="-2.104213e-03" izz="1.904449e-02" />
        </inertial>
    </link>
    <joint name="fr3_joint3" type="revolute">
        <parent link="fr3_link2" />
        <child link="fr3_link3" />
        <origin xyz="0 -0.316 0" rpy="1.5708 -0 0" />
        <axis xyz="0 0 1" />
        <limit lower="-2.900700" upper="2.900700" effort="87.000000" velocity="2.620000" />
        <dynamics damping="0.003000" friction="0.200000" />
    </joint>
    <link name="fr3_link4">
        <visual>
            <origin xyz="0 0 0" rpy="0 -0 0" />
            <geometry>
                <mesh filename="meshes/link4.dae" />
            </geometry>
        </visual>
        <collision>
            <origin xyz="-0.0034488 -0.00353127 0.0471695" rpy="0 -0 0" />
            <geometry>
                <sphere radius="0.068317" />
            </geometry>
        </collision>
        <collision>
            <origin xyz="-0.02916 0.0235666 0.0328487" rpy="0 -0 0" />
            <geometry>
                <sphere radius="0.053048" />
            </geometry>
        </collision>
        <collision>
            <origin xyz="-0.0822895 0.0724792 0.000292415" rpy="0 -0 0" />
            <geometry>
                <sphere radius="0.073777" />
            </geometry>
        </collision>
        <collision>
            <origin xyz="0.0122005 0.0310361 0.0215009" rpy="0 -0 0" />
            <geometry>
                <sphere radius="0.032887" />
            </geometry>
        </collision>
        <collision>
            <origin xyz="0.0230922 0.00307991 0.0308469" rpy="0 -0 0" />
            <geometry>
                <sphere radius="0.048269" />
            </geometry>
        </collision>
        <collision>
            <origin xyz="-0.105633 0.0928826 -0.00390767" rpy="0 -0 0" />
            <geometry>
                <sphere radius="0.047613" />
            </geometry>
        </collision>
        <collision>
            <origin xyz="-0.0851033 0.114481 -0.0461483" rpy="0 -0 0" />
            <geometry>
                <sphere radius="0.014219" />
            </geometry>
        </collision>
        <collision>
            <origin xyz="0.0142084 -0.0254674 0.0254204" rpy="0 -0 0" />
            <geometry>
                <sphere radius="0.040192" />
            </geometry>
        </collision>
        <inertial>
            <origin xyz="-0.0459101 0.0630493 -0.00851879" rpy="0 -0 0" />
            <mass value="2.615596" />
            <inertia ixx="3.452998e-02" ixy="1.322552e-02" ixz="1.015143e-02" iyy="2.888162e-02" iyz="-9.762834e-04" izz="4.125471e-02" />
        </inertial>
    </link>
    <joint name="fr3_joint4" type="revolute">
        <parent link="fr3_link3" />
        <child link="fr3_link4" />
        <origin xyz="0.0825 0 0" rpy="1.5708 -0 0" />
        <axis xyz="0 0 1" />
        <limit lower="-3.042100" upper="-0.151800" effort="87.000000" velocity="2.620000" />
        <dynamics damping="0.003000" friction="0.200000" />
    </joint>
    <link name="fr3_link5">
        <visual>
            <origin xyz="0 0 0" rpy="0 -0 0" />
            <geometry>
                <mesh filename="meshes/link5.dae" />
            </geometry>
        </visual>
        <collision>
            <origin xyz="0.00369457 0.013323 -0.212912" rpy="0 -0 0" />
            <geometry>
                <sphere radius="0.068347" />
            </geometry>
        </collision>
        <collision>
            <origin xyz="5.91683e-05 -0.00114685 -0.216211" rpy="0 -0 0" />
            <geometry>
                <sphere radius="0.068362" />
            </geometry>
        </collision>
        <collision>
            <origin xyz="-4.15819e-05 0.0633309 0.00113852" rpy="0 -0 0" />
            <geometry>
                <sphere radius="0.066672" />
            </geometry>
        </collision>
        <collision>
            <origin xyz="-0.000498138 0.0567908 -0.180941" rpy="0 -0 0" />
            <geometry>
                <sphere radius="0.042869" />
            </geometry>
        </collision>
        <collision>
            <origin xyz="-0.000380091 0.0833417 -0.00606817" rpy="0 -0 0" />
            <geometry>
                <sphere radius="0.060564" />
            </geometry>
        </collision>
        <collision>
            <origin xyz="-0.00214613 0.0842255 -0.116591" rpy="0 -0 0" />
            <geometry>
                <sphere radius="0.038453" />
            </geometry>
        </collision>
        <collision>
            <origin xyz="0.00227615 0.0715365 -0.156278" rpy="0 -0 0" />
            <geometry>
                <sphere radius="0.038470" />
            </geometry>
        </collision>
        <collision>
            <origin xyz="0.00157024 0.0920764 -0.0711967" rpy="0 -0 0" />
            <geometry>
                <sphere radius="0.039685" />
            </geometry>
        </collision>
        <inertial>
            <origin xyz="-0.00160396 0.0292536 -0.0972966" rpy="0 -0 0" />
            <mass value="2.327121" />
            <inertia ixx="5.161028e-02" ixy="-5.715173e-03" ixz="-3.567317e-03" iyy="4.787730e-02" iyz="1.067399e-02" izz="1.642363e-02" />
        </inertial>
    </link>
    <joint name="fr3_joint5" type="revolute">
        <parent link="fr3_link4" />
        <child link="fr3_link5" />
        <origin xyz="-0.0825 0.384 0" rpy="-1.5708 0 0" />
        <axis xyz="0 0 1" />
        <limit lower="-2.806500" upper="2.806500" effort="12.000000" velocity="5.260000" />
        <dynamics damping="0.003000" friction="0.200000" />
    </joint>
    <link name="fr3_link6">
        <visual>
            <origin xyz="0 0 0" rpy="0 -0 0" />
            <geometry>
                <mesh filename="meshes/link6.dae" />
            </geometry>
        </visual>
        <collision>
            <origin xyz="-0.0117796 0.0083828 0.0181964" rpy="0 -0 0" />
            <geometry>
                <sphere radius="0.050531" />
            </geometry>
        </collision>
        <collision>
            <origin xyz="0.088151 -0.0101961 0.000179087" rpy="0 -0 0" />
            <geometry>
                <sphere radius="0.059593" />
            </geometry>
        </collision>
        <collision>
            <origin xyz="0.0858356 0.0341492 0.000544377" rpy="0 -0 0" />
            <geometry>
                <sphere radius="0.054706" />
            </geometry>
        </collision>
        <collision>
            <origin xyz="0.0240131 0.022085 0.0134703" rpy="0 -0 0" />
            <geometry>
                <sphere radius="0.045858" />
            </geometry>
        </collision>
        <collision>
            <origin xyz="0.0275064 -0.0215011 0.00340509" rpy="0 -0 0" />
            <geometry>
                <sphere radius="0.028540" />
            </geometry>
        </collision>
        <collision>
            <origin xyz="-0.00633513 -0.0138134 0.0173821" rpy="0 -0 0" />
            <geometry>
                <sphere radius="0.049621" />
            </geometry>
        </collision>
        <collision>
            <origin xyz="0.0289308 -0.00234986 0.0239722" rpy="0 -0 0" />
            <geometry>
                <sphere radius="0.043953" />
            </geometry>
        </collision>
        <collision>
            <origin xyz="0.0669151 0.0506059 0.00415511" rpy="0 -0 0" />
            <geometry>
                <sphere radius="0.039288" />
            </geometry>
        </collision>
        <inertial>
            <origin xyz="0.0597131 -0.0410295 -0.0101693" rpy="0 -0 0" />
            <mass value="1.817038" />
            <inertia ixx="5.412334e-03" ixy="6.193456e-03" ixz="1.421929e-03" iyy="1.405833e-02" iyz="-1.314075e-03" izz="1.608082e-02" />
        </inertial>
    </link>
    <joint name="fr3_joint6" type="revolute">
        <parent link="fr3_link5" />
        <child link="fr3_link6" />
        <origin xyz="0 0 0" rpy="1.5708 -0 0" />
        <axis xyz="0 0 1" />
        <limit lower="0.544500" upper="4.516900" effort="12.000000" velocity="4.180000" />
        <dynamics damping="0.003000" friction="0.200000" />
    </joint>
    <link name="fr3_link7">
        <visual>
            <origin xyz="0 0 0" rpy="0 -0 0" />
            <geometry>
                <mesh filename="meshes/link7.dae" />
            </geometry>
        </visual>
        <collision>
            <origin xyz="0.0435766 0.0593991 0.0870202" rpy="0 -0 0" />
            <geometry>
                <sphere radius="0.023712" />
            </geometry>
        </collision>
        <collision>
            <origin xyz="-0.00508554 -0.0172881 0.0709841" rpy="0 -0 0" />
            <geometry>
                <sphere radius="0.042524" />
            </geometry>
        </collision>
        <collision>
            <origin xyz="0.0179882 -0.00233207 0.0717978" rpy="0 -0 0" />
            <geometry>
                <sphere radius="0.042720" />
            </geometry>
        </collision>
        <collision>
            <origin xyz="-0.0171323 0.00466831 0.0712605" rpy="0 -0 0" />
            <geometry>
                <sphere radius="0.040940" />
            </geometry>
        </collision>
        <collision>
            <origin xyz="0.0482152 0.0236327 0.0832779" rpy="0 -0 0" />
            <geometry>
                <sphere radius="0.025019" />
            </geometry>
        </collision>
        <collision>
            <origin xyz="0.00104792 0.0247646 0.0744111" rpy="0 -0 0" />
            <geometry>
                <sphere radius="0.035718" />
            </geometry>
        </collision>
        <collision>
            <origin xyz="0.062978 0.0395543 0.0866232" rpy="0 -0 0" />
            <geometry>
                <sphere radius="0.019152" />
            </geometry>
        </collision>
        <collision>
            <origin xyz="0.0235315 0.0482404 0.0833324" rpy="0 -0 0" />
            <geometry>
                <sphere radius="0.024752" />
            </geometry>
        </collision>
        <inertial>
            <origin xyz="0.00452258 0.00862619 -0.0161633" rpy="0 -0 0" />
            <mass value="0.627143" />
            <inertia ixx="2.109239e-04" ixy="-2.433299e-05" ixz="4.564480e-05" iyy="1.771857e-04" iyz="8.744070e-05" izz="5.993191e-05" />
        </inertial>
    </link>
    <joint name="fr3_joint7" type="revolute">
        <parent link="fr3_link6" />
        <child link="fr3_link7" />
        <origin xyz="0.088 0 0" rpy="1.5708 -0 0" />
        <axis xyz="0 0 1" />
        <limit lower="-3.015900" upper="3.015900" effort="12.000000" velocity="5.260000" />
        <dynamics damping="0.003000" friction="0.200000" />
    </joint>
    <link name="fr3_link8" />
    <joint name="fr3_joint8" type="fixed">
        <parent link="fr3_link7" />
        <child link="fr3_link8" />
        <origin xyz="0 0 0.107" rpy="0 -0 0" />
    </joint>
    <link name="world" />
    <joint name="fr3_joint_world" type="fixed">
        <parent link="world" />
        <child link="fr3_link0" />
        <origin xyz="0 0 0" rpy="0 -0 0" />
    </joint>
    <link name="hand_hand">
        <visual>
            <origin xyz="0 0 0" rpy="0 -0 0" />
            <geometry>
                <mesh filename="meshes/hand.dae" />
            </geometry>
        </visual>
        <collision>
            <origin xyz="-0.00487615 0.0814733 -0.00656114" rpy="0 -0 0" />
            <geometry>
                <sphere radius="0.045462" />
            </geometry>
        </collision>
        <collision>
            <origin xyz="0.00349673 0.0653076 0.0590131" rpy="0 -0 0" />
            <geometry>
                <sphere radius="0.046645" />
            </geometry>
        </collision>
        <collision>
            <origin xyz="0.0161347 -0.0673277 0.0132001" rpy="0 -0 0" />
            <geometry>
                <sphere radius="0.046008" />
            </geometry>
        </collision>
        <collision>
            <origin xyz="0.00413578 0.0167389 -0.000626459" rpy="0 -0 0" />
            <geometry>
                <sphere radius="0.043203" />
            </geometry>
        </collision>
        <collision>
            <origin xyz="-0.0083528 -0.0932238 0.0650685" rpy="0 -0 0" />
            <geometry>
                <sphere radius="0.037613" />
            </geometry>
        </collision>
        <collision>
            <origin xyz="-0.0175288 -0.0355204 0.0299339" rpy="0 -0 0" />
            <geometry>
                <sphere radius="0.040583" />
            </geometry>
        </collision>
        <collision>
            <origin xyz="0.000213512 0.0157813 0.0583996" rpy="0 -0 0" />
            <geometry>
                <sphere radius="0.035113" />
            </geometry>
        </collision>
        <collision>
            <origin xyz="0.0180354 -0.0368761 0.0457648" rpy="0 -0 0" />
            <geometry>
                <sphere radius="0.033738" />
            </geometry>
        </collision>
        <inertial>
            <origin xyz="-3.76e-05 0.0119128 0.020726" rpy="0 -0 0" />
            <mass value="0.654400" />
            <inertia ixx="1.860000e-03" ixy="0.000000e+00" ixz="0.000000e+00" iyy="3.000000e-04" iyz="-2.000000e-05" izz="1.740000e-03" />
        </inertial>
    </link>
    <link name="hand_leftfinger">
        <visual>
            <origin xyz="-0.0165 0.0165 0.127733" rpy="-1.5708 0.202458 -1.5708" />
            <geometry>
                <mesh filename="meshes/flex_griper_connect.stl" />
            </geometry>
        </visual>
        <collision>
            <origin xyz="6.43671e-07 0.0122467 0.0719192" rpy="0 -0 0" />
            <geometry>
                <sphere radius="0.016006" />
            </geometry>
        </collision>
        <collision>
            <origin xyz="0.000518821 0.00419104 0.1131" rpy="0 -0 0" />
            <geometry>
                <sphere radius="0.013449" />
            </geometry>
        </collision>
        <collision>
            <origin xyz="-0.00293819 0.0185338 0.0444037" rpy="0 -0 0" />
            <geometry>
                <sphere radius="0.026882" />
            </geometry>
        </collision>
        <collision>
            <origin xyz="-0.0028697 0.0231121 0.0203656" rpy="0 -0 0" />
            <geometry>
                <sphere radius="0.019674" />
            </geometry>
        </collision>
        <collision>
            <origin xyz="-0.000644938 0.00850013 0.0921064" rpy="0 -0 0" />
            <geometry>
                <sphere radius="0.015415" />
            </geometry>
        </collision>
        <collision>
            <origin xyz="6.01357e-05 0.0214774 0.00467561" rpy="0 -0 0" />
            <geometry>
                <sphere radius="0.016138" />
            </geometry>
        </collision>
        <collision>
            <origin xyz="0.0132172 0.022322 0.0260753" rpy="0 -0 0" />
            <geometry>
                <sphere radius="0.015712" />
            </geometry>
        </collision>
        <inertial>
            <origin xyz="0 0.0145644 0.0227941" rpy="0 -0 0" />
            <mass value="0.100000" />
            <inertia ixx="3.012209e-05" ixy="0.000000e+00" ixz="0.000000e+00" iyy="2.958738e-05" iyz="0.000000e+00" izz="6.951252e-06" />
        </inertial>
    </link>
    <joint name="hand_finger_joint1" type="prismatic">
        <parent link="hand_hand" />
        <child link="hand_leftfinger" />
        <origin xyz="0 0 0.0584" rpy="0 -0 0" />
        <axis xyz="0 1 0" />
        <limit lower="0.000000" upper="0.040000" effort="100.000000" velocity="0.200000" />
        <dynamics damping="0.300000" friction="0.000000" />
    </joint>
    <link name="hand_rightfinger">
        <visual>
            <origin xyz="-0.0165 0.0165 0.127733" rpy="-1.5708 0.202458 -1.5708" />
            <geometry>
                <mesh filename="meshes/flex_griper_connect.stl" />
            </geometry>
        </visual>
        <collision>
            <origin xyz="-0.00289771 0.0200209 0.0436404" rpy="0 -0 0" />
            <geometry>
                <sphere radius="0.021385" />
            </geometry>
        </collision>
        <collision>
            <origin xyz="0.000647985 0.00458452 0.111188" rpy="0 -0 0" />
            <geometry>
                <sphere radius="0.015011" />
            </geometry>
        </collision>
        <collision>
            <origin xyz="-0.00806791 0.0326163 0.0258211" rpy="0 -0 0" />
            <geometry>
                <sphere radius="0.011975" />
            </geometry>
        </collision>
        <collision>
            <origin xyz="-6.7376e-09 0.0154586 0.0642686" rpy="0 -0 0" />
            <geometry>
                <sphere radius="0.017947" />
            </geometry>
        </collision>
        <collision>
            <origin xyz="0.00763121 0.0191866 0.0394628" rpy="0 -0 0" />
            <geometry>
                <sphere radius="0.023853" />
            </geometry>
        </collision>
        <collision>
            <origin xyz="0.000482522 0.0217245 0.00953724" rpy="0 -0 0" />
            <geometry>
                <sphere radius="0.018322" />
            </geometry>
        </collision>
        <collision>
            <origin xyz="-0.00997847 0.0129292 0.0368256" rpy="0 -0 0" />
            <geometry>
                <sphere radius="0.019098" />
            </geometry>
        </collision>
        <collision>
            <origin xyz="-0.000611316 0.00965973 0.0864565" rpy="0 -0 0" />
            <geometry>
                <sphere radius="0.017016" />
            </geometry>
        </collision>
        <inertial>
            <origin xyz="0 0.0145644 0.0227941" rpy="0 -0 3.14159" />
            <mass value="0.100000" />
            <inertia ixx="3.012209e-05" ixy="0.000000e+00" ixz="0.000000e+00" iyy="2.958738e-05" iyz="0.000000e+00" izz="6.951252e-06" />
        </inertial>
    </link>
    <joint name="hand_finger_joint2" type="prismatic">
        <parent link="hand_hand" />
        <child link="hand_rightfinger" />
        <origin xyz="0 0 0.0584" rpy="0 -0 3.14159" />
        <axis xyz="0 1 0" />
        <limit lower="0.000000" upper="0.040000" effort="100.000000" velocity="0.200000" />
        <dynamics damping="0.300000" friction="0.000000" />
    </joint>
    <link name="hand_hand_tcp" />
    <joint name="hand_hand_tcp_joint" type="fixed">
        <parent link="hand_hand" />
        <child link="hand_hand_tcp" />
        <origin xyz="0 0 0.1034" rpy="0 -0 0" />
    </joint>
    <joint name="hand_joint_fr3_link8" type="fixed">
        <parent link="fr3_link8" />
        <child link="hand_hand" />
        <origin xyz="0 0 0" rpy="0 0 -0.785398" />
    </joint>
</robot>