<?xml version='1.0' encoding='utf-8'?>
<robot name="bot">
    <link name="fr3_link0">
        <visual>
            <origin xyz="0 0 0" rpy="0 -0 0" />
            <geometry>
                <mesh filename="meshes/link0.dae" />
            </geometry>
        </visual>
        <collision>
            <origin xyz="-0.00880299 8.84346e-06 0.0664022" rpy="0 -0 0" />
            <geometry>
                <sphere radius="0.102418" />
            </geometry>
        </collision>
        <collision>
            <origin xyz="-0.093327 0.018244 0.0377148" rpy="0 -0 0" />
            <geometry>
                <sphere radius="0.073670" />
            </geometry>
        </collision>
        <collision>
            <origin xyz="-0.103792 -0.0233388 0.0285107" rpy="0 -0 0" />
            <geometry>
                <sphere radius="0.059555" />
            </geometry>
        </collision>
        <collision>
            <origin xyz="-0.0559253 0.0771439 0.00461432" rpy="0 -0 0" />
            <geometry>
                <sphere radius="0.017509" />
            </geometry>
        </collision>
        <collision>
            <origin xyz="-0.0145833 -0.0540733 0.0136244" rpy="0 -0 0" />
            <geometry>
                <sphere radius="0.045164" />
            </geometry>
        </collision>
        <collision>
            <origin xyz="-0.0124247 0.0577624 0.0108271" rpy="0 -0 0" />
            <geometry>
                <sphere radius="0.040483" />
            </geometry>
        </collision>
        <collision>
            <origin xyz="-0.0657948 -0.0714243 0.00460357" rpy="0 -0 0" />
            <geometry>
                <sphere radius="0.026166" />
            </geometry>
        </collision>
        <inertial>
            <origin xyz="-0.0172 0.0004 0.0745" rpy="0 -0 0" />
            <mass value="2.396600" />
            <inertia ixx="9.000000e-03" ixy="0.000000e+00" ixz="2.000000e-03" iyy="1.150000e-02" iyz="0.000000e+00" izz="8.500000e-03" />
        </inertial>
    </link>
    <link name="fr3_link1">
        <visual>
            <origin xyz="0 0 0" rpy="0 -0 0" />
            <geometry>
                <mesh filename="meshes/link1.dae" />
            </geometry>
        </visual>
        <collision>
            <origin xyz="-0.000169087 -0.0553081 -0.000194155" rpy="0 -0 0" />
            <geometry>
                <sphere radius="0.076646" />
            </geometry>
        </collision>
        <collision>
            <origin xyz="-0.0340103 -0.0250198 -0.0857285" rpy="0 -0 0" />
            <geometry>
                <sphere radius="0.022111" />
            </geometry>
        </collision>
        <collision>
            <origin xyz="0.000148843 -2.89516e-05 -0.139381" rpy="0 -0 0" />
            <geometry>
                <sphere radius="0.075281" />
            </geometry>
        </collision>
        <collision>
            <origin xyz="-0.0123548 -0.0430302 -0.0595768" rpy="0 -0 0" />
            <geometry>
                <sphere radius="0.048564" />
            </geometry>
        </collision>
        <collision>
            <origin xyz="0.0203251 -0.0366981 -0.0721796" rpy="0 -0 0" />
            <geometry>
                <sphere radius="0.044285" />
            </geometry>
        </collision>
        <inertial>
            <origin xyz="4.128e-07 -0.0181251 -0.0386036" rpy="0 -0 0" />
            <mass value="2.927465" />
            <inertia ixx="2.392732e-02" ixy="1.331790e-05" ixz="-1.140477e-04" iyy="2.248216e-02" iyz="-1.995032e-03" izz="6.350098e-03" />
        </inertial>
    </link>
    <joint name="fr3_joint1" type="revolute">
        <parent link="fr3_link0" />
        <child link="fr3_link1" />
        <origin xyz="0 0 0.333" rpy="0 -0 0" />
        <axis xyz="0 0 1" />
        <limit lower="-2.743700" upper="2.743700" effort="87.000000" velocity="2.620000" />
        <dynamics damping="0.003000" friction="0.200000" />
    </joint>
    <link name="fr3_link2">
        <visual>
            <origin xyz="0 0 0" rpy="0 -0 0" />
            <geometry>
                <mesh filename="meshes/link2.dae" />
            </geometry>
        </visual>
        <collision>
            <origin xyz="-4.08878e-06 -0.00117935 0.0555043" rpy="0 -0 0" />
            <geometry>
                <sphere radius="0.076790" />
            </geometry>
        </collision>
        <collision>
            <origin xyz="0.000427074 -0.139648 0.00299682" rpy="0 -0 0" />
            <geometry>
                <sphere radius="0.075369" />
            </geometry>
        </collision>
        <collision>
            <origin xyz="0.014521 -0.0758238 0.0377696" rpy="0 -0 0" />
            <geometry>
                <sphere radius="0.046565" />
            </geometry>
        </collision>
        <collision>
            <origin xyz="-0.0196472 -0.0754532 0.0361693" rpy="0 -0 0" />
            <geometry>
                <sphere radius="0.042006" />
            </geometry>
        </collision>
        <collision>
            <origin xyz="-0.0167194 -0.158636 -0.0118195" rpy="0 -0 0" />
            <geometry>
                <sphere radius="0.052344" />
            </geometry>
        </collision>
        <collision>
            <origin xyz="0.00868597 -0.161445 -0.0216194" rpy="0 -0 0" />
            <geometry>
                <sphere radius="0.048361" />
            </geometry>
        </collision>
        <inertial>
            <origin xyz="0.00318289 -0.0743222 0.00881461" rpy="0 -0 0" />
            <mass value="2.935537" />
            <inertia ixx="4.193895e-02" ixy="2.025733e-04" ixz="4.077784e-03" iyy="2.514515e-02" iyz="-4.225216e-03" izz="6.170214e-02" />
        </inertial>
    </link>
    <joint name="fr3_joint2" type="revolute">
        <parent link="fr3_link1" />
        <child link="fr3_link2" />
        <origin xyz="0 0 0" rpy="-1.5708 0 0" />
        <axis xyz="0 0 1" />
        <limit lower="-1.783700" upper="1.783700" effort="87.000000" velocity="2.620000" />
        <dynamics damping="0.003000" friction="0.200000" />
    </joint>
    <link name="fr3_link3">
        <visual>
            <origin xyz="0 0 0" rpy="0 -0 0" />
            <geometry>
                <mesh filename="meshes/link3.dae" />
            </geometry>
        </visual>
        <collision>
            <origin xyz="-8.43156e-05 0.00019002 -0.0704999" rpy="0 -0 0" />
            <geometry>
                <sphere radius="0.074006" />
            </geometry>
        </collision>
        <collision>
            <origin xyz="0.079194 0.0472725 -0.00296832" rpy="0 -0 0" />
            <geometry>
                <sphere radius="0.069410" />
            </geometry>
        </collision>
        <collision>
            <origin xyz="0.100753 0.0198298 0.0319051" rpy="0 -0 0" />
            <geometry>
                <sphere radius="0.031446" />
            </geometry>
        </collision>
        <collision>
            <origin xyz="0.113811 0.0230431 0.0067831" rpy="0 -0 0" />
            <geometry>
                <sphere radius="0.036168" />
            </geometry>
        </collision>
        <collision>
            <origin xyz="0.0738092 0.0294067 0.0252578" rpy="0 -0 0" />
            <geometry>
                <sphere radius="0.043701" />
            </geometry>
        </collision>
        <collision>
            <origin xyz="0.112778 0.0177135 -0.0199336" rpy="0 -0 0" />
            <geometry>
                <sphere radius="0.026748" />
            </geometry>
        </collision>
        <collision>
            <origin xyz="0.0497156 0.0225222 0.00932155" rpy="0 -0 0" />
            <geometry>
                <sphere radius="0.035467" />
            </geometry>
        </collision>
        <inertial>
            <origin xyz="0.0407016 -0.00482006 -0.0289731" rpy="0 -0 0" />
            <mass value="2.244901" />
            <inertia ixx="2.410143e-02" ixy="2.404695e-03" ixz="-2.856269e-03" iyy="1.974053e-02" iyz="-2.104213e-03" izz="1.904449e-02" />
        </inertial>
    </link>
    <joint name="fr3_joint3" type="revolute">
        <parent link="fr3_link2" />
        <child link="fr3_link3" />
        <origin xyz="0 -0.316 0" rpy="1.5708 -0 0" />
        <axis xyz="0 0 1" />
        <limit lower="-2.900700" upper="2.900700" effort="87.000000" velocity="2.620000" />
        <dynamics damping="0.003000" friction="0.200000" />
    </joint>
    <link name="fr3_link4">
        <visual>
            <origin xyz="0 0 0" rpy="0 -0 0" />
            <geometry>
                <mesh filename="meshes/link4.dae" />
            </geometry>
        </visual>
        <collision>
            <origin xyz="-3.93747e-05 -1.52197e-05 0.0514134" rpy="0 -0 0" />
            <geometry>
                <sphere radius="0.074180" />
            </geometry>
        </collision>
        <collision>
            <origin xyz="-0.082573 0.0723975 0.000126164" rpy="0 -0 0" />
            <geometry>
                <sphere radius="0.074063" />
            </geometry>
        </collision>
        <collision>
            <origin xyz="-0.00990606 0.0506038 0.00640499" rpy="0 -0 0" />
            <geometry>
                <sphere radius="0.007279" />
            </geometry>
        </collision>
        <collision>
            <origin xyz="-0.0361011 0.00611396 0.0239444" rpy="0 -0 0" />
            <geometry>
                <sphere radius="0.032416" />
            </geometry>
        </collision>
        <inertial>
            <origin xyz="-0.0459101 0.0630493 -0.00851879" rpy="0 -0 0" />
            <mass value="2.615596" />
            <inertia ixx="3.452998e-02" ixy="1.322552e-02" ixz="1.015143e-02" iyy="2.888162e-02" iyz="-9.762834e-04" izz="4.125471e-02" />
        </inertial>
    </link>
    <joint name="fr3_joint4" type="revolute">
        <parent link="fr3_link3" />
        <child link="fr3_link4" />
        <origin xyz="0.0825 0 0" rpy="1.5708 -0 0" />
        <axis xyz="0 0 1" />
        <limit lower="-3.042100" upper="-0.151800" effort="87.000000" velocity="2.620000" />
        <dynamics damping="0.003000" friction="0.200000" />
    </joint>
    <link name="fr3_link5">
        <visual>
            <origin xyz="0 0 0" rpy="0 -0 0" />
            <geometry>
                <mesh filename="meshes/link5.dae" />
            </geometry>
        </visual>
        <collision>
            <origin xyz="0.0101858 -0.00437899 -0.218414" rpy="0 -0 0" />
            <geometry>
                <sphere radius="0.062306" />
            </geometry>
        </collision>
        <collision>
            <origin xyz="-0.0101363 -0.0111603 -0.221316" rpy="0 -0 0" />
            <geometry>
                <sphere radius="0.059165" />
            </geometry>
        </collision>
        <collision>
            <origin xyz="-2.81821e-05 0.0633475 0.00115329" rpy="0 -0 0" />
            <geometry>
                <sphere radius="0.066684" />
            </geometry>
        </collision>
        <collision>
            <origin xyz="-0.00301504 0.0149476 -0.212589" rpy="0 -0 0" />
            <geometry>
                <sphere radius="0.067389" />
            </geometry>
        </collision>
        <collision>
            <origin xyz="0.000881317 0.0613402 -0.173306" rpy="0 -0 0" />
            <geometry>
                <sphere radius="0.043272" />
            </geometry>
        </collision>
        <collision>
            <origin xyz="-0.00179068 0.0852436 -0.00966756" rpy="0 -0 0" />
            <geometry>
                <sphere radius="0.062288" />
            </geometry>
        </collision>
        <collision>
            <origin xyz="-0.000343217 0.0813708 -0.1304" rpy="0 -0 0" />
            <geometry>
                <sphere radius="0.039338" />
            </geometry>
        </collision>
        <collision>
            <origin xyz="0.000881363 0.0901634 -0.0821078" rpy="0 -0 0" />
            <geometry>
                <sphere radius="0.039793" />
            </geometry>
        </collision>
        <inertial>
            <origin xyz="-0.00160396 0.0292536 -0.0972966" rpy="0 -0 0" />
            <mass value="2.327121" />
            <inertia ixx="5.161028e-02" ixy="-5.715173e-03" ixz="-3.567317e-03" iyy="4.787730e-02" iyz="1.067399e-02" izz="1.642363e-02" />
        </inertial>
    </link>
    <joint name="fr3_joint5" type="revolute">
        <parent link="fr3_link4" />
        <child link="fr3_link5" />
        <origin xyz="-0.0825 0.384 0" rpy="-1.5708 0 0" />
        <axis xyz="0 0 1" />
        <limit lower="-2.806500" upper="2.806500" effort="12.000000" velocity="5.260000" />
        <dynamics damping="0.003000" friction="0.200000" />
    </joint>
    <link name="fr3_link6">
        <visual>
            <origin xyz="0 0 0" rpy="0 -0 0" />
            <geometry>
                <mesh filename="meshes/link6.dae" />
            </geometry>
        </visual>
        <collision>
            <origin xyz="-0.00528404 0.013969 0.0176057" rpy="0 -0 0" />
            <geometry>
                <sphere radius="0.047252" />
            </geometry>
        </collision>
        <collision>
            <origin xyz="0.0881505 -0.010193 0.000177639" rpy="0 -0 0" />
            <geometry>
                <sphere radius="0.059595" />
            </geometry>
        </collision>
        <collision>
            <origin xyz="0.0853079 0.0351347 0.000723117" rpy="0 -0 0" />
            <geometry>
                <sphere radius="0.055036" />
            </geometry>
        </collision>
        <collision>
            <origin xyz="0.0203508 -0.00504144 0.0197954" rpy="0 -0 0" />
            <geometry>
                <sphere radius="0.053030" />
            </geometry>
        </collision>
        <collision>
            <origin xyz="-0.0194169 0.00221325 0.0132237" rpy="0 -0 0" />
            <geometry>
                <sphere radius="0.041978" />
            </geometry>
        </collision>
        <collision>
            <origin xyz="-0.00668429 -0.0168674 0.0146027" rpy="0 -0 0" />
            <geometry>
                <sphere radius="0.044872" />
            </geometry>
        </collision>
        <collision>
            <origin xyz="0.0364331 0.0380914 0.00929987" rpy="0 -0 0" />
            <geometry>
                <sphere radius="0.036975" />
            </geometry>
        </collision>
        <inertial>
            <origin xyz="0.0597131 -0.0410295 -0.0101693" rpy="0 -0 0" />
            <mass value="1.817038" />
            <inertia ixx="5.412334e-03" ixy="6.193456e-03" ixz="1.421929e-03" iyy="1.405833e-02" iyz="-1.314075e-03" izz="1.608082e-02" />
        </inertial>
    </link>
    <joint name="fr3_joint6" type="revolute">
        <parent link="fr3_link5" />
        <child link="fr3_link6" />
        <origin xyz="0 0 0" rpy="1.5708 -0 0" />
        <axis xyz="0 0 1" />
        <limit lower="0.544500" upper="4.516900" effort="12.000000" velocity="4.180000" />
        <dynamics damping="0.003000" friction="0.200000" />
    </joint>
    <link name="fr3_link7">
        <visual>
            <origin xyz="0 0 0" rpy="0 -0 0" />
            <geometry>
                <mesh filename="meshes/link7.dae" />
            </geometry>
        </visual>
        <collision>
            <origin xyz="0.0306997 0.0560882 0.0854259" rpy="0 -0 0" />
            <geometry>
                <sphere radius="0.028085" />
            </geometry>
        </collision>
        <collision>
            <origin xyz="0.00948346 -0.0155835 0.0709754" rpy="0 -0 0" />
            <geometry>
                <sphere radius="0.039167" />
            </geometry>
        </collision>
        <collision>
            <origin xyz="-0.0172347 0.00347287 0.071032" rpy="0 -0 0" />
            <geometry>
                <sphere radius="0.040778" />
            </geometry>
        </collision>
        <collision>
            <origin xyz="0.0510664 0.0267971 0.0844594" rpy="0 -0 0" />
            <geometry>
                <sphere radius="0.022339" />
            </geometry>
        </collision>
        <collision>
            <origin xyz="0.0591657 0.0445705 0.0870906" rpy="0 -0 0" />
            <geometry>
                <sphere radius="0.024453" />
            </geometry>
        </collision>
        <collision>
            <origin xyz="-0.010262 -0.0171335 0.0716151" rpy="0 -0 0" />
            <geometry>
                <sphere radius="0.038266" />
            </geometry>
        </collision>
        <collision>
            <origin xyz="0.000918158 0.0243541 0.0741909" rpy="0 -0 0" />
            <geometry>
                <sphere radius="0.037666" />
            </geometry>
        </collision>
        <collision>
            <origin xyz="0.0277022 0.00488179 0.0769662" rpy="0 -0 0" />
            <geometry>
                <sphere radius="0.035254" />
            </geometry>
        </collision>
        <inertial>
            <origin xyz="0.00452258 0.00862619 -0.0161633" rpy="0 -0 0" />
            <mass value="0.627143" />
            <inertia ixx="2.109239e-04" ixy="-2.433299e-05" ixz="4.564480e-05" iyy="1.771857e-04" iyz="8.744070e-05" izz="5.993191e-05" />
        </inertial>
    </link>
    <joint name="fr3_joint7" type="revolute">
        <parent link="fr3_link6" />
        <child link="fr3_link7" />
        <origin xyz="0.088 0 0" rpy="1.5708 -0 0" />
        <axis xyz="0 0 1" />
        <limit lower="-3.015900" upper="3.015900" effort="12.000000" velocity="5.260000" />
        <dynamics damping="0.003000" friction="0.200000" />
    </joint>
    <link name="fr3_link8" />
    <joint name="fr3_joint8" type="fixed">
        <parent link="fr3_link7" />
        <child link="fr3_link8" />
        <origin xyz="0 0 0.107" rpy="0 -0 0" />
    </joint>
    <link name="world" />
    <joint name="fr3_joint_world" type="fixed">
        <parent link="world" />
        <child link="fr3_link0" />
        <origin xyz="0 0 0" rpy="0 -0 0" />
    </joint>
    <link name="hand_hand">
        <visual>
            <origin xyz="0 0 0" rpy="0 -0 0" />
            <geometry>
                <mesh filename="meshes/hand.dae" />
            </geometry>
        </visual>
        <collision>
            <origin xyz="0.0154541 0.0649843 0.0151509" rpy="0 -0 0" />
            <geometry>
                <sphere radius="0.049303" />
            </geometry>
        </collision>
        <collision>
            <origin xyz="-0.00825424 0.0658155 0.0599849" rpy="0 -0 0" />
            <geometry>
                <sphere radius="0.046173" />
            </geometry>
        </collision>
        <collision>
            <origin xyz="-0.0155919 -0.0681579 0.0153692" rpy="0 -0 0" />
            <geometry>
                <sphere radius="0.049011" />
            </geometry>
        </collision>
        <collision>
            <origin xyz="-0.00616579 0.00620153 -0.00248646" rpy="0 -0 0" />
            <geometry>
                <sphere radius="0.049300" />
            </geometry>
        </collision>
        <collision>
            <origin xyz="0.00788416 -0.0917064 0.0656423" rpy="0 -0 0" />
            <geometry>
                <sphere radius="0.028885" />
            </geometry>
        </collision>
        <collision>
            <origin xyz="0.00272806 0.0113464 0.0583992" rpy="0 -0 0" />
            <geometry>
                <sphere radius="0.028756" />
            </geometry>
        </collision>
        <collision>
            <origin xyz="0.00290063 -0.0384371 0.0583957" rpy="0 -0 0" />
            <geometry>
                <sphere radius="0.041909" />
            </geometry>
        </collision>
        <inertial>
            <origin xyz="-3.76e-05 0.0119128 0.020726" rpy="0 -0 0" />
            <mass value="0.654400" />
            <inertia ixx="1.860000e-03" ixy="0.000000e+00" ixz="0.000000e+00" iyy="3.000000e-04" iyz="-2.000000e-05" izz="1.740000e-03" />
        </inertial>
    </link>
    <link name="hand_leftfinger">
        <visual>
            <origin xyz="-0.0165 0.0165 0.127733" rpy="-1.5708 0.202458 -1.5708" />
            <geometry>
                <mesh filename="meshes/flex_griper_connect.stl" />
            </geometry>
        </visual>
        <collision>
            <origin xyz="-5.71733e-05 0.0178721 0.0443357" rpy="0 -0 0" />
            <geometry>
                <sphere radius="0.026532" />
            </geometry>
        </collision>
        <collision>
            <origin xyz="3.62572e-05 0.0215544 0.00542782" rpy="0 -0 0" />
            <geometry>
                <sphere radius="0.016371" />
            </geometry>
        </collision>
        <collision>
            <origin xyz="3.22712e-07 0.0123855 0.0742801" rpy="0 -0 0" />
            <geometry>
                <sphere radius="0.016246" />
            </geometry>
        </collision>
        <collision>
            <origin xyz="-0.00057508 0.00823122 0.0934187" rpy="0 -0 0" />
            <geometry>
                <sphere radius="0.014401" />
            </geometry>
        </collision>
        <collision>
            <origin xyz="0.000520515 0.00419438 0.113085" rpy="0 -0 0" />
            <geometry>
                <sphere radius="0.013462" />
            </geometry>
        </collision>
        <collision>
            <origin xyz="0.00633608 0.0243293 0.0212351" rpy="0 -0 0" />
            <geometry>
                <sphere radius="0.018236" />
            </geometry>
        </collision>
        <collision>
            <origin xyz="-0.00760378 0.0231991 0.0216227" rpy="0 -0 0" />
            <geometry>
                <sphere radius="0.017873" />
            </geometry>
        </collision>
        <inertial>
            <origin xyz="0 0.0145644 0.0227941" rpy="0 -0 0" />
            <mass value="0.100000" />
            <inertia ixx="3.012209e-05" ixy="0.000000e+00" ixz="0.000000e+00" iyy="2.958738e-05" iyz="0.000000e+00" izz="6.951252e-06" />
        </inertial>
    </link>
    <joint name="hand_finger_joint1" type="prismatic">
        <parent link="hand_hand" />
        <child link="hand_leftfinger" />
        <origin xyz="0 0 0.0584" rpy="0 -0 0" />
        <axis xyz="0 1 0" />
        <limit lower="0.000000" upper="0.040000" effort="100.000000" velocity="0.200000" />
        <dynamics damping="0.300000" friction="0.000000" />
    </joint>
    <link name="hand_rightfinger">
        <visual>
            <origin xyz="-0.0165 0.0165 0.127733" rpy="-1.5708 0.202458 -1.5708" />
            <geometry>
                <mesh filename="meshes/flex_griper_connect.stl" />
            </geometry>
        </visual>
        <collision>
            <origin xyz="-0.00116899 0.0180242 0.0445661" rpy="0 -0 0" />
            <geometry>
                <sphere radius="0.026130" />
            </geometry>
        </collision>
        <collision>
            <origin xyz="0.00048715 0.00411549 0.11347" rpy="0 -0 0" />
            <geometry>
                <sphere radius="0.013164" />
            </geometry>
        </collision>
        <collision>
            <origin xyz="-0.00038401 0.0227149 0.0179154" rpy="0 -0 0" />
            <geometry>
                <sphere radius="0.017473" />
            </geometry>
        </collision>
        <collision>
            <origin xyz="7.55005e-07 0.0119583 0.0728283" rpy="0 -0 0" />
            <geometry>
                <sphere radius="0.016251" />
            </geometry>
        </collision>
        <collision>
            <origin xyz="-0.0109701 0.0226876 0.0231472" rpy="0 -0 0" />
            <geometry>
                <sphere radius="0.015983" />
            </geometry>
        </collision>
        <collision>
            <origin xyz="-0.000616674 0.00826939 0.0932296" rpy="0 -0 0" />
            <geometry>
                <sphere radius="0.015019" />
            </geometry>
        </collision>
        <collision>
            <origin xyz="-2.19596e-06 0.0214889 0.00507724" rpy="0 -0 0" />
            <geometry>
                <sphere radius="0.016206" />
            </geometry>
        </collision>
        <collision>
            <origin xyz="0.0126208 0.0227375 0.0249867" rpy="0 -0 0" />
            <geometry>
                <sphere radius="0.015928" />
            </geometry>
        </collision>
        <inertial>
            <origin xyz="0 0.0145644 0.0227941" rpy="0 -0 3.14159" />
            <mass value="0.100000" />
            <inertia ixx="3.012209e-05" ixy="0.000000e+00" ixz="0.000000e+00" iyy="2.958738e-05" iyz="0.000000e+00" izz="6.951252e-06" />
        </inertial>
    </link>
    <joint name="hand_finger_joint2" type="prismatic">
        <parent link="hand_hand" />
        <child link="hand_rightfinger" />
        <origin xyz="0 0 0.0584" rpy="0 -0 3.14159" />
        <axis xyz="0 1 0" />
        <limit lower="0.000000" upper="0.040000" effort="100.000000" velocity="0.200000" />
        <dynamics damping="0.300000" friction="0.000000" />
    </joint>
    <link name="hand_hand_tcp" />
    <joint name="hand_hand_tcp_joint" type="fixed">
        <parent link="hand_hand" />
        <child link="hand_hand_tcp" />
        <origin xyz="0 0 0.1034" rpy="0 -0 0" />
    </joint>
    <joint name="hand_joint_fr3_link8" type="fixed">
        <parent link="fr3_link8" />
        <child link="hand_hand" />
        <origin xyz="0 0 0" rpy="0 0 -0.785398" />
    </joint>
</robot>