<?xml version='1.0' encoding='utf-8'?>
<robot name="bot">
    <link name="fr3_link0">
        <visual>
            <origin xyz="0 0 0" rpy="0 -0 0" />
            <geometry>
                <mesh filename="meshes/link0.dae" />
            </geometry>
        </visual>
        <collision>
            <origin xyz="-0.109909 -0.00119874 0.00047311" rpy="-0.0278784 1.35129 -0.0223447" />
            <geometry>
                <cylinder radius="0.095477" length="0.025916" />
            </geometry>
        </collision>
        <collision>
            <origin xyz="-0.122556 -0.00127739 -0.0023473" rpy="0 -0 0" />
            <geometry>
                <sphere radius="0.095477" />
            </geometry>
        </collision>
        <collision>
            <origin xyz="-0.097262 -0.00112009 0.00329352" rpy="0 -0 0" />
            <geometry>
                <sphere radius="0.095477" />
            </geometry>
        </collision>
        <collision>
            <origin xyz="-0.00811674 0.000194159 0.0597853" rpy="-0.0220961 0.701762 -0.00808805" />
            <geometry>
                <cylinder radius="0.108636" length="0.061812" />
            </geometry>
        </collision>
        <collision>
            <origin xyz="-0.0280684 -0.00032733 0.0361881" rpy="0 -0 0" />
            <geometry>
                <sphere radius="0.108636" />
            </geometry>
        </collision>
        <collision>
            <origin xyz="0.0118349 0.000715649 0.0833824" rpy="0 -0 0" />
            <geometry>
                <sphere radius="0.108636" />
            </geometry>
        </collision>
        <inertial>
            <origin xyz="-0.0172 0.0004 0.0745" rpy="0 -0 0" />
            <mass value="2.396600" />
            <inertia ixx="9.000000e-03" ixy="0.000000e+00" ixz="2.000000e-03" iyy="1.150000e-02" iyz="0.000000e+00" izz="8.500000e-03" />
        </inertial>
    </link>
    <link name="fr3_link1">
        <visual>
            <origin xyz="0 0 0" rpy="0 -0 0" />
            <geometry>
                <mesh filename="meshes/link1.dae" />
            </geometry>
        </visual>
        <collision>
            <origin xyz="-7.12881e-05 -0.0509316 -0.0168984" rpy="-2.55223 0.00197803 -0.00651698" />
            <geometry>
                <cylinder radius="0.082595" length="0.050344" />
            </geometry>
        </collision>
        <collision>
            <origin xyz="-0.000121079 -0.064923 0.004027" rpy="0 -0 0" />
            <geometry>
                <sphere radius="0.082595" />
            </geometry>
        </collision>
        <collision>
            <origin xyz="-2.14969e-05 -0.0369402 -0.0378239" rpy="0 -0 0" />
            <geometry>
                <sphere radius="0.082595" />
            </geometry>
        </collision>
        <collision>
            <origin xyz="8.27697e-05 -0.00251874 -0.141086" rpy="-2.85244 0.000827436 -0.00568323" />
            <geometry>
                <cylinder radius="0.070388" length="0.042140" />
            </geometry>
        </collision>
        <collision>
            <origin xyz="6.53357e-05 -0.00852661 -0.120891" rpy="0 -0 0" />
            <geometry>
                <sphere radius="0.070388" />
            </geometry>
        </collision>
        <collision>
            <origin xyz="0.000100204 0.00348913 -0.161282" rpy="0 -0 0" />
            <geometry>
                <sphere radius="0.070388" />
            </geometry>
        </collision>
        <inertial>
            <origin xyz="4.128e-07 -0.0181251 -0.0386036" rpy="0 -0 0" />
            <mass value="2.927465" />
            <inertia ixx="2.392732e-02" ixy="1.331790e-05" ixz="-1.140477e-04" iyy="2.248216e-02" iyz="-1.995032e-03" izz="6.350098e-03" />
        </inertial>
    </link>
    <joint name="fr3_joint1" type="revolute">
        <parent link="fr3_link0" />
        <child link="fr3_link1" />
        <origin xyz="0 0 0.333" rpy="0 -0 0" />
        <axis xyz="0 0 1" />
        <limit lower="-2.743700" upper="2.743700" effort="87.000000" velocity="2.620000" />
        <dynamics damping="0.003000" friction="0.200000" />
    </joint>
    <link name="fr3_link2">
        <visual>
            <origin xyz="0 0 0" rpy="0 -0 0" />
            <geometry>
                <mesh filename="meshes/link2.dae" />
            </geometry>
        </visual>
        <collision>
            <origin xyz="-8.69454e-05 -0.0181504 0.0507686" rpy="2.15275 0.00233959 0.00433993" />
            <geometry>
                <cylinder radius="0.082486" length="0.050477" />
            </geometry>
        </collision>
        <collision>
            <origin xyz="-0.000145993 0.00293348 0.0646409" rpy="0 -0 0" />
            <geometry>
                <sphere radius="0.082486" />
            </geometry>
        </collision>
        <collision>
            <origin xyz="-2.78981e-05 -0.0392343 0.0368962" rpy="0 -0 0" />
            <geometry>
                <sphere radius="0.082486" />
            </geometry>
        </collision>
        <collision>
            <origin xyz="0.000103531 -0.142436 0.00273298" rpy="1.85942 0.00106807 0.00143128" />
            <geometry>
                <cylinder radius="0.070281" length="0.041949" />
            </geometry>
        </collision>
        <collision>
            <origin xyz="8.11287e-05 -0.122329 0.00870306" rpy="0 -0 0" />
            <geometry>
                <sphere radius="0.070281" />
            </geometry>
        </collision>
        <collision>
            <origin xyz="0.000125933 -0.162542 -0.0032371" rpy="0 -0 0" />
            <geometry>
                <sphere radius="0.070281" />
            </geometry>
        </collision>
        <inertial>
            <origin xyz="0.00318289 -0.0743222 0.00881461" rpy="0 -0 0" />
            <mass value="2.935537" />
            <inertia ixx="4.193895e-02" ixy="2.025733e-04" ixz="4.077784e-03" iyy="2.514515e-02" iyz="-4.225216e-03" izz="6.170214e-02" />
        </inertial>
    </link>
    <joint name="fr3_joint2" type="revolute">
        <parent link="fr3_link1" />
        <child link="fr3_link2" />
        <origin xyz="0 0 0" rpy="-1.5708 0 0" />
        <axis xyz="0 0 1" />
        <limit lower="-1.783700" upper="1.783700" effort="87.000000" velocity="2.620000" />
        <dynamics damping="0.003000" friction="0.200000" />
    </joint>
    <link name="fr3_link3">
        <visual>
            <origin xyz="0 0 0" rpy="0 -0 0" />
            <geometry>
                <mesh filename="meshes/link3.dae" />
            </geometry>
        </visual>
        <collision>
            <origin xyz="0.0483984 0.0355604 -0.0418982" rpy="-0.614478 0.65252 -0.213889" />
            <geometry>
                <cylinder radius="0.087410" length="0.107895" />
            </geometry>
        </collision>
        <collision>
            <origin xyz="0.015642 0.0108478 -0.0769216" rpy="0 -0 0" />
            <geometry>
                <sphere radius="0.087410" />
            </geometry>
        </collision>
        <collision>
            <origin xyz="0.0811548 0.0602731 -0.00687488" rpy="0 -0 0" />
            <geometry>
                <sphere radius="0.087410" />
            </geometry>
        </collision>
        <inertial>
            <origin xyz="0.0407016 -0.00482006 -0.0289731" rpy="0 -0 0" />
            <mass value="2.244901" />
            <inertia ixx="2.410143e-02" ixy="2.404695e-03" ixz="-2.856269e-03" iyy="1.974053e-02" iyz="-2.104213e-03" izz="1.904449e-02" />
        </inertial>
    </link>
    <joint name="fr3_joint3" type="revolute">
        <parent link="fr3_link2" />
        <child link="fr3_link3" />
        <origin xyz="0 -0.316 0" rpy="1.5708 -0 0" />
        <axis xyz="0 0 1" />
        <limit lower="-2.900700" upper="2.900700" effort="87.000000" velocity="2.620000" />
        <dynamics damping="0.003000" friction="0.200000" />
    </joint>
    <link name="fr3_link4">
        <visual>
            <origin xyz="0 0 0" rpy="0 -0 0" />
            <geometry>
                <mesh filename="meshes/link4.dae" />
            </geometry>
        </visual>
        <collision>
            <origin xyz="-0.0341201 0.0439822 0.0357699" rpy="0.951142 0.651889 0.344682" />
            <geometry>
                <cylinder radius="0.087865" length="0.107914" />
            </geometry>
        </collision>
        <collision>
            <origin xyz="-0.0668553 0.0789002 0.0108598" rpy="0 -0 0" />
            <geometry>
                <sphere radius="0.087865" />
            </geometry>
        </collision>
        <collision>
            <origin xyz="-0.00138496 0.00906416 0.06068" rpy="0 -0 0" />
            <geometry>
                <sphere radius="0.087865" />
            </geometry>
        </collision>
        <inertial>
            <origin xyz="-0.0459101 0.0630493 -0.00851879" rpy="0 -0 0" />
            <mass value="2.615596" />
            <inertia ixx="3.452998e-02" ixy="1.322552e-02" ixz="1.015143e-02" iyy="2.888162e-02" iyz="-9.762834e-04" izz="4.125471e-02" />
        </inertial>
    </link>
    <joint name="fr3_joint4" type="revolute">
        <parent link="fr3_link3" />
        <child link="fr3_link4" />
        <origin xyz="0.0825 0 0" rpy="1.5708 -0 0" />
        <axis xyz="0 0 1" />
        <limit lower="-3.042100" upper="-0.151800" effort="87.000000" velocity="2.620000" />
        <dynamics damping="0.003000" friction="0.200000" />
    </joint>
    <link name="fr3_link5">
        <visual>
            <origin xyz="0 0 0" rpy="0 -0 0" />
            <geometry>
                <mesh filename="meshes/link5.dae" />
            </geometry>
        </visual>
        <collision>
            <origin xyz="-0.000165246 0.0216044 -0.226833" rpy="-0.593901 0.00288307 -0.000882216" />
            <geometry>
                <cylinder radius="0.070483" length="0.031494" />
            </geometry>
        </collision>
        <collision>
            <origin xyz="-0.000210646 0.0127925 -0.239883" rpy="0 -0 0" />
            <geometry>
                <sphere radius="0.070483" />
            </geometry>
        </collision>
        <collision>
            <origin xyz="-0.000119847 0.0304163 -0.213782" rpy="0 -0 0" />
            <geometry>
                <sphere radius="0.070483" />
            </geometry>
        </collision>
        <collision>
            <origin xyz="0.000119069 0.0680221 -0.165046" rpy="-0.297431 -0.00187912 0.000281533" />
            <geometry>
                <cylinder radius="0.056454" length="0.001778" />
            </geometry>
        </collision>
        <collision>
            <origin xyz="0.000120739 0.0677616 -0.165896" rpy="0 -0 0" />
            <geometry>
                <sphere radius="0.056454" />
            </geometry>
        </collision>
        <collision>
            <origin xyz="0.000117398 0.0682827 -0.164196" rpy="0 -0 0" />
            <geometry>
                <sphere radius="0.056454" />
            </geometry>
        </collision>
        <collision>
            <origin xyz="0.000207028 0.0890384 -0.0331826" rpy="-0.00290964 0.00346631 -5.04288e-06" />
            <geometry>
                <cylinder radius="0.087781" length="0.068168" />
            </geometry>
        </collision>
        <collision>
            <origin xyz="8.88835e-05 0.0889392 -0.067266" rpy="0 -0 0" />
            <geometry>
                <sphere radius="0.087781" />
            </geometry>
        </collision>
        <collision>
            <origin xyz="0.000325173 0.0891376 0.000900804" rpy="0 -0 0" />
            <geometry>
                <sphere radius="0.087781" />
            </geometry>
        </collision>
        <collision>
            <origin xyz="6.58089e-05 0.0763284 -0.137948" rpy="-0.297431 -0.00187912 0.000281533" />
            <geometry>
                <cylinder radius="0.047721" length="0.007678" />
            </geometry>
        </collision>
        <collision>
            <origin xyz="7.30226e-05 0.0752034 -0.141618" rpy="0 -0 0" />
            <geometry>
                <sphere radius="0.047721" />
            </geometry>
        </collision>
        <collision>
            <origin xyz="5.85953e-05 0.0774534 -0.134278" rpy="0 -0 0" />
            <geometry>
                <sphere radius="0.047721" />
            </geometry>
        </collision>
        <inertial>
            <origin xyz="-0.00160396 0.0292536 -0.0972966" rpy="0 -0 0" />
            <mass value="2.327121" />
            <inertia ixx="5.161028e-02" ixy="-5.715173e-03" ixz="-3.567317e-03" iyy="4.787730e-02" iyz="1.067399e-02" izz="1.642363e-02" />
        </inertial>
    </link>
    <joint name="fr3_joint5" type="revolute">
        <parent link="fr3_link4" />
        <child link="fr3_link5" />
        <origin xyz="-0.0825 0.384 0" rpy="-1.5708 0 0" />
        <axis xyz="0 0 1" />
        <limit lower="-2.806500" upper="2.806500" effort="12.000000" velocity="5.260000" />
        <dynamics damping="0.003000" friction="0.200000" />
    </joint>
    <link name="fr3_link6">
        <visual>
            <origin xyz="0 0 0" rpy="0 -0 0" />
            <geometry>
                <mesh filename="meshes/link6.dae" />
            </geometry>
        </visual>
        <collision>
            <origin xyz="-0.030834 -0.0129882 0.0166908" rpy="-2.08872 1.32322 -1.85932" />
            <geometry>
                <cylinder radius="0.067779" length="0.006775" />
            </geometry>
        </collision>
        <collision>
            <origin xyz="-0.0341181 -0.0137095 0.0171018" rpy="0 -0 0" />
            <geometry>
                <sphere radius="0.067779" />
            </geometry>
        </collision>
        <collision>
            <origin xyz="-0.02755 -0.012267 0.0162798" rpy="0 -0 0" />
            <geometry>
                <sphere radius="0.067779" />
            </geometry>
        </collision>
        <collision>
            <origin xyz="0.0570257 0.0114608 0.00307482" rpy="-2.06698 1.13409 -1.63735" />
            <geometry>
                <cylinder radius="0.089170" length="0.049296" />
            </geometry>
        </collision>
        <collision>
            <origin xyz="0.034691 0.002293 0.00803792" rpy="0 -0 0" />
            <geometry>
                <sphere radius="0.089170" />
            </geometry>
        </collision>
        <collision>
            <origin xyz="0.0793605 0.0206287 -0.00188827" rpy="0 -0 0" />
            <geometry>
                <sphere radius="0.089170" />
            </geometry>
        </collision>
        <inertial>
            <origin xyz="0.0597131 -0.0410295 -0.0101693" rpy="0 -0 0" />
            <mass value="1.817038" />
            <inertia ixx="5.412334e-03" ixy="6.193456e-03" ixz="1.421929e-03" iyy="1.405833e-02" iyz="-1.314075e-03" izz="1.608082e-02" />
        </inertial>
    </link>
    <joint name="fr3_joint6" type="revolute">
        <parent link="fr3_link5" />
        <child link="fr3_link6" />
        <origin xyz="0 0 0" rpy="1.5708 -0 0" />
        <axis xyz="0 0 1" />
        <limit lower="0.544500" upper="4.516900" effort="12.000000" velocity="4.180000" />
        <dynamics damping="0.003000" friction="0.200000" />
    </joint>
    <link name="fr3_link7">
        <visual>
            <origin xyz="0 0 0" rpy="0 -0 0" />
            <geometry>
                <mesh filename="meshes/link7.dae" />
            </geometry>
        </visual>
        <collision>
            <origin xyz="0.0119469 0.01204 0.0811338" rpy="-1.43783 0.782414 -0.692827" />
            <geometry>
                <cylinder radius="0.051855" length="0.042725" />
            </geometry>
        </collision>
        <collision>
            <origin xyz="-0.00311333 -0.00297673 0.0791252" rpy="0 -0 0" />
            <geometry>
                <sphere radius="0.051855" />
            </geometry>
        </collision>
        <collision>
            <origin xyz="0.0270072 0.0270567 0.0831424" rpy="0 -0 0" />
            <geometry>
                <sphere radius="0.051855" />
            </geometry>
        </collision>
        <collision>
            <origin xyz="0.0577107 0.0577466 0.0870926" rpy="-1.44524 0.78106 -0.696383" />
            <geometry>
                <cylinder radius="0.040932" length="0.000873" />
            </geometry>
        </collision>
        <collision>
            <origin xyz="0.0574034 0.057439 0.0870538" rpy="0 -0 0" />
            <geometry>
                <sphere radius="0.040932" />
            </geometry>
        </collision>
        <collision>
            <origin xyz="0.0580181 0.0580542 0.0871314" rpy="0 -0 0" />
            <geometry>
                <sphere radius="0.040932" />
            </geometry>
        </collision>
        <inertial>
            <origin xyz="0.00452258 0.00862619 -0.0161633" rpy="0 -0 0" />
            <mass value="0.627143" />
            <inertia ixx="2.109239e-04" ixy="-2.433299e-05" ixz="4.564480e-05" iyy="1.771857e-04" iyz="8.744070e-05" izz="5.993191e-05" />
        </inertial>
    </link>
    <joint name="fr3_joint7" type="revolute">
        <parent link="fr3_link6" />
        <child link="fr3_link7" />
        <origin xyz="0.088 0 0" rpy="1.5708 -0 0" />
        <axis xyz="0 0 1" />
        <limit lower="-3.015900" upper="3.015900" effort="12.000000" velocity="5.260000" />
        <dynamics damping="0.003000" friction="0.200000" />
    </joint>
    <link name="fr3_link8" />
    <joint name="fr3_joint8" type="fixed">
        <parent link="fr3_link7" />
        <child link="fr3_link8" />
        <origin xyz="0 0 0.107" rpy="0 -0 0" />
    </joint>
    <link name="world" />
    <joint name="fr3_joint_world" type="fixed">
        <parent link="world" />
        <child link="fr3_link0" />
        <origin xyz="0 0 0" rpy="0 -0 0" />
    </joint>
    <link name="hand_hand">
        <visual>
            <origin xyz="0 0 0" rpy="0 -0 0" />
            <geometry>
                <mesh filename="meshes/hand.dae" />
            </geometry>
        </visual>
        <collision>
            <origin xyz="4.47607e-06 -0.00528891 0.0249983" rpy="1.61796 -0.000214573 -0.00022494" />
            <geometry>
                <cylinder radius="0.048999" length="0.142001" />
            </geometry>
        </collision>
        <collision>
            <origin xyz="1.97109e-05 0.0656326 0.0283457" rpy="0 -0 0" />
            <geometry>
                <sphere radius="0.048999" />
            </geometry>
        </collision>
        <collision>
            <origin xyz="-1.07587e-05 -0.0762104 0.0216509" rpy="0 -0 0" />
            <geometry>
                <sphere radius="0.048999" />
            </geometry>
        </collision>
        <inertial>
            <origin xyz="-3.76e-05 0.0119128 0.020726" rpy="0 -0 0" />
            <mass value="0.654400" />
            <inertia ixx="1.860000e-03" ixy="0.000000e+00" ixz="0.000000e+00" iyy="3.000000e-04" iyz="-2.000000e-05" izz="1.740000e-03" />
        </inertial>
    </link>
    <link name="hand_leftfinger">
        <visual>
            <origin xyz="-0.0165 0.0165 0.127733" rpy="-1.5708 0.202458 -1.5708" />
            <geometry>
                <mesh filename="meshes/flex_griper_connect.stl" />
            </geometry>
        </visual>
        <collision>
            <origin xyz="1.41071e-07 0.00776431 0.096105" rpy="-2.937 -5.63894e-06 5.49314e-05" />
            <geometry>
                <cylinder radius="0.016130" length="0.037550" />
            </geometry>
        </collision>
        <collision>
            <origin xyz="2.46943e-07 0.0039498 0.114489" rpy="0 -0 0" />
            <geometry>
                <sphere radius="0.016130" />
            </geometry>
        </collision>
        <collision>
            <origin xyz="3.51988e-08 0.0115788 0.0777214" rpy="0 -0 0" />
            <geometry>
                <sphere radius="0.016130" />
            </geometry>
        </collision>
        <collision>
            <origin xyz="-2.31687e-07 0.0138524 0.0569637" rpy="-3.06876 -1.54657e-05 0.000424485" />
            <geometry>
                <cylinder radius="0.026186" length="0.016366" />
            </geometry>
        </collision>
        <collision>
            <origin xyz="-1.05129e-07 0.0132569 0.0651252" rpy="0 -0 0" />
            <geometry>
                <sphere radius="0.026186" />
            </geometry>
        </collision>
        <collision>
            <origin xyz="-3.58245e-07 0.0144479 0.0488022" rpy="0 -0 0" />
            <geometry>
                <sphere radius="0.026186" />
            </geometry>
        </collision>
        <collision>
            <origin xyz="-6.94855e-07 0.0160318 0.027095" rpy="-3.06876 -1.54657e-05 0.000424485" />
            <geometry>
                <cylinder radius="0.027077" length="0.012071" />
            </geometry>
        </collision>
        <collision>
            <origin xyz="-6.01515e-07 0.0155926 0.0331143" rpy="0 -0 0" />
            <geometry>
                <sphere radius="0.027077" />
            </geometry>
        </collision>
        <collision>
            <origin xyz="-7.88195e-07 0.016471 0.0210757" rpy="0 -0 0" />
            <geometry>
                <sphere radius="0.027077" />
            </geometry>
        </collision>
        <inertial>
            <origin xyz="0 0.0145644 0.0227941" rpy="0 -0 0" />
            <mass value="0.100000" />
            <inertia ixx="3.012209e-05" ixy="0.000000e+00" ixz="0.000000e+00" iyy="2.958738e-05" iyz="0.000000e+00" izz="6.951252e-06" />
        </inertial>
    </link>
    <joint name="hand_finger_joint1" type="prismatic">
        <parent link="hand_hand" />
        <child link="hand_leftfinger" />
        <origin xyz="0 0 0.0584" rpy="0 -0 0" />
        <axis xyz="0 1 0" />
        <limit lower="0.000000" upper="0.040000" effort="100.000000" velocity="0.200000" />
        <dynamics damping="0.300000" friction="0.000000" />
    </joint>
    <link name="hand_rightfinger">
        <visual>
            <origin xyz="-0.0165 0.0165 0.127733" rpy="-1.5708 0.202458 -1.5708" />
            <geometry>
                <mesh filename="meshes/flex_griper_connect.stl" />
            </geometry>
        </visual>
        <collision>
            <origin xyz="1.41071e-07 0.00776431 0.096105" rpy="-2.937 -5.63894e-06 5.49314e-05" />
            <geometry>
                <cylinder radius="0.016130" length="0.037550" />
            </geometry>
        </collision>
        <collision>
            <origin xyz="2.46943e-07 0.0039498 0.114489" rpy="0 -0 0" />
            <geometry>
                <sphere radius="0.016130" />
            </geometry>
        </collision>
        <collision>
            <origin xyz="3.51988e-08 0.0115788 0.0777214" rpy="0 -0 0" />
            <geometry>
                <sphere radius="0.016130" />
            </geometry>
        </collision>
        <collision>
            <origin xyz="-2.31687e-07 0.0138524 0.0569637" rpy="-3.06876 -1.54657e-05 0.000424485" />
            <geometry>
                <cylinder radius="0.026186" length="0.016366" />
            </geometry>
        </collision>
        <collision>
            <origin xyz="-1.05129e-07 0.0132569 0.0651252" rpy="0 -0 0" />
            <geometry>
                <sphere radius="0.026186" />
            </geometry>
        </collision>
        <collision>
            <origin xyz="-3.58245e-07 0.0144479 0.0488022" rpy="0 -0 0" />
            <geometry>
                <sphere radius="0.026186" />
            </geometry>
        </collision>
        <collision>
            <origin xyz="-6.94855e-07 0.0160318 0.027095" rpy="-3.06876 -1.54657e-05 0.000424485" />
            <geometry>
                <cylinder radius="0.027077" length="0.012071" />
            </geometry>
        </collision>
        <collision>
            <origin xyz="-6.01515e-07 0.0155926 0.0331143" rpy="0 -0 0" />
            <geometry>
                <sphere radius="0.027077" />
            </geometry>
        </collision>
        <collision>
            <origin xyz="-7.88195e-07 0.016471 0.0210757" rpy="0 -0 0" />
            <geometry>
                <sphere radius="0.027077" />
            </geometry>
        </collision>
        <inertial>
            <origin xyz="0 0.0145644 0.0227941" rpy="0 -0 3.14159" />
            <mass value="0.100000" />
            <inertia ixx="3.012209e-05" ixy="0.000000e+00" ixz="0.000000e+00" iyy="2.958738e-05" iyz="0.000000e+00" izz="6.951252e-06" />
        </inertial>
    </link>
    <joint name="hand_finger_joint2" type="prismatic">
        <parent link="hand_hand" />
        <child link="hand_rightfinger" />
        <origin xyz="0 0 0.0584" rpy="0 -0 3.14159" />
        <axis xyz="0 1 0" />
        <limit lower="0.000000" upper="0.040000" effort="100.000000" velocity="0.200000" />
        <dynamics damping="0.300000" friction="0.000000" />
    </joint>
    <link name="hand_hand_tcp" />
    <joint name="hand_hand_tcp_joint" type="fixed">
        <parent link="hand_hand" />
        <child link="hand_hand_tcp" />
        <origin xyz="0 0 0.1034" rpy="0 -0 0" />
    </joint>
    <joint name="hand_joint_fr3_link8" type="fixed">
        <parent link="fr3_link8" />
        <child link="hand_hand" />
        <origin xyz="0 0 0" rpy="0 0 -0.785398" />
    </joint>
</robot>