<?xml version="1.0" encoding="utf-8"?>
<robot name="bot">
    <link name="fr3_link0">
        <visual>
            <origin xyz="0 0 0" rpy="0 -0 0"/>
            <geometry>
                <mesh filename="/workspace/resources/fr3/meshes/fr3/visual/link0.dae"/>
            </geometry>
        </visual>
        <collision>
            <origin xyz="-0.040768 6.03063e-05 0.0370764" rpy="-0.00337435 1.18796 -0.00227881"/>
            <geometry>
                <cylinder radius="0.107104" length="0.239863"/>
            </geometry>
        </collision>
        <collision>
            <origin xyz="-0.152017 -9.08678e-05 -0.00772437" rpy="0 -0 0"/>
            <geometry>
                <sphere radius="0.107104"/>
            </geometry>
        </collision>
        <collision>
            <origin xyz="0.0704813 0.00021148 0.0818772" rpy="0 -0 0"/>
            <geometry>
                <sphere radius="0.107104"/>
            </geometry>
        </collision>
        <inertial>
            <origin xyz="-0.0172 0.0004 0.0745" rpy="0 -0 0"/>
            <mass value="2.396600"/>
            <inertia ixx="9.000000e-03" ixy="0.000000e+00" ixz="2.000000e-03" iyy="1.150000e-02" iyz="0.000000e+00" izz="8.500000e-03"/>
        </inertial>
    </link>
    <link name="fr3_link1">
        <visual>
            <origin xyz="0 0 0" rpy="0 -0 0"/>
            <geometry>
                <mesh filename="/workspace/resources/fr3/meshes/fr3/visual/link1.dae"/>
            </geometry>
        </visual>
        <collision>
            <origin xyz="-0.000926319 -0.0315371 -0.0752475" rpy="-2.79978 0.00568555 -0.0329393"/>
            <geometry>
                <cylinder radius="0.080738" length="0.284383"/>
            </geometry>
        </collision>
        <collision>
            <origin xyz="-0.00173475 -0.0791988 0.0587158" rpy="0 -0 0"/>
            <geometry>
                <sphere radius="0.080738"/>
            </geometry>
        </collision>
        <collision>
            <origin xyz="-0.000117885 0.0161246 -0.209211" rpy="0 -0 0"/>
            <geometry>
                <sphere radius="0.080738"/>
            </geometry>
        </collision>
        <inertial>
            <origin xyz="4.128e-07 -0.0181251 -0.0386036" rpy="0 -0 0"/>
            <mass value="2.927465"/>
            <inertia ixx="2.392732e-02" ixy="1.331790e-05" ixz="-1.140477e-04" iyy="2.248216e-02" iyz="-1.995032e-03" izz="6.350098e-03"/>
        </inertial>
    </link>
    <joint name="fr3_joint1" type="revolute">
        <parent link="fr3_link0"/>
        <child link="fr3_link1"/>
        <origin xyz="0 0 0.333" rpy="0 -0 0"/>
        <axis xyz="0 0 1"/>
        <limit lower="-2.743700" upper="2.743700" effort="87.000000" velocity="2.620000"/>
        <dynamics damping="0.003000" friction="0.200000"/>
    </joint>
    <link name="fr3_link2">
        <visual>
            <origin xyz="0 0 0" rpy="0 -0 0"/>
            <geometry>
                <mesh filename="/workspace/resources/fr3/meshes/fr3/visual/link2.dae"/>
            </geometry>
        </visual>
        <collision>
            <origin xyz="0.000603042 -0.0761141 0.0314147" rpy="1.90705 -0.00585858 -0.00825384"/>
            <geometry>
                <cylinder radius="0.080391" length="0.285592"/>
            </geometry>
        </collision>
        <collision>
            <origin xyz="0.00143962 0.0586829 0.0785297" rpy="0 -0 0"/>
            <geometry>
                <sphere radius="0.080391"/>
            </geometry>
        </collision>
        <collision>
            <origin xyz="-0.000233536 -0.210911 -0.0157004" rpy="0 -0 0"/>
            <geometry>
                <sphere radius="0.080391"/>
            </geometry>
        </collision>
        <inertial>
            <origin xyz="0.00318289 -0.0743222 0.00881461" rpy="0 -0 0"/>
            <mass value="2.935537"/>
            <inertia ixx="4.193895e-02" ixy="2.025733e-04" ixz="4.077784e-03" iyy="2.514515e-02" iyz="-4.225216e-03" izz="6.170214e-02"/>
        </inertial>
    </link>
    <joint name="fr3_joint2" type="revolute">
        <parent link="fr3_link1"/>
        <child link="fr3_link2"/>
        <origin xyz="0 0 0" rpy="-1.5708 0 0"/>
        <axis xyz="0 0 1"/>
        <limit lower="-1.783700" upper="1.783700" effort="87.000000" velocity="2.620000"/>
        <dynamics damping="0.003000" friction="0.200000"/>
    </joint>
    <link name="fr3_link3">
        <visual>
            <origin xyz="0 0 0" rpy="0 -0 0"/>
            <geometry>
                <mesh filename="/workspace/resources/fr3/meshes/fr3/visual/link3.dae"/>
            </geometry>
        </visual>
        <collision>
            <origin xyz="0.0434003 0.0222297 -0.048544" rpy="-0.489318 0.70326 -0.18268"/>
            <geometry>
                <cylinder radius="0.075502" length="0.254614"/>
            </geometry>
        </collision>
        <collision>
            <origin xyz="-0.0389301 -0.0234106 -0.134251" rpy="0 -0 0"/>
            <geometry>
                <sphere radius="0.075502"/>
            </geometry>
        </collision>
        <collision>
            <origin xyz="0.125731 0.06787 0.0371634" rpy="0 -0 0"/>
            <geometry>
                <sphere radius="0.075502"/>
            </geometry>
        </collision>
        <inertial>
            <origin xyz="0.0407016 -0.00482006 -0.0289731" rpy="0 -0 0"/>
            <mass value="2.244901"/>
            <inertia ixx="2.410143e-02" ixy="2.404695e-03" ixz="-2.856269e-03" iyy="1.974053e-02" iyz="-2.104213e-03" izz="1.904449e-02"/>
        </inertial>
    </link>
    <joint name="fr3_joint3" type="revolute">
        <parent link="fr3_link2"/>
        <child link="fr3_link3"/>
        <origin xyz="0 -0.316 0" rpy="1.5708 -0 0"/>
        <axis xyz="0 0 1"/>
        <limit lower="-2.900700" upper="2.900700" effort="87.000000" velocity="2.620000"/>
        <dynamics damping="0.003000" friction="0.200000"/>
    </joint>
    <link name="fr3_link4">
        <visual>
            <origin xyz="0 0 0" rpy="0 -0 0"/>
            <geometry>
                <mesh filename="/workspace/resources/fr3/meshes/fr3/visual/link4.dae"/>
            </geometry>
        </visual>
        <collision>
            <origin xyz="-0.0392193 0.0494013 0.0224751" rpy="1.09443 0.688986 0.430446"/>
            <geometry>
                <cylinder radius="0.076085" length="0.256383"/>
            </geometry>
        </collision>
        <collision>
            <origin xyz="-0.120718 0.137335 -0.022899" rpy="0 -0 0"/>
            <geometry>
                <sphere radius="0.076085"/>
            </geometry>
        </collision>
        <collision>
            <origin xyz="0.042279 -0.038532 0.0678492" rpy="0 -0 0"/>
            <geometry>
                <sphere radius="0.076085"/>
            </geometry>
        </collision>
        <inertial>
            <origin xyz="-0.0459101 0.0630493 -0.00851879" rpy="0 -0 0"/>
            <mass value="2.615596"/>
            <inertia ixx="3.452998e-02" ixy="1.322552e-02" ixz="1.015143e-02" iyy="2.888162e-02" iyz="-9.762834e-04" izz="4.125471e-02"/>
        </inertial>
    </link>
    <joint name="fr3_joint4" type="revolute">
        <parent link="fr3_link3"/>
        <child link="fr3_link4"/>
        <origin xyz="0.0825 0 0" rpy="1.5708 -0 0"/>
        <axis xyz="0 0 1"/>
        <limit lower="-3.042100" upper="-0.151800" effort="87.000000" velocity="2.620000"/>
        <dynamics damping="0.003000" friction="0.200000"/>
    </joint>
    <link name="fr3_link5">
        <visual>
            <origin xyz="0 0 0" rpy="0 -0 0"/>
            <geometry>
                <mesh filename="/workspace/resources/fr3/meshes/fr3/visual/link5.dae"/>
            </geometry>
        </visual>
        <collision>
            <origin xyz="-3.83052e-05 0.036354 -0.108225" rpy="-0.268516 0.00451785 -0.000610231"/>
            <geometry>
                <cylinder radius="0.073151" length="0.343367"/>
            </geometry>
        </collision>
        <collision>
            <origin xyz="-0.000813943 -0.00919332 -0.273755" rpy="0 -0 0"/>
            <geometry>
                <sphere radius="0.073151"/>
            </geometry>
        </collision>
        <collision>
            <origin xyz="0.000737333 0.0819014 0.0573041" rpy="0 -0 0"/>
            <geometry>
                <sphere radius="0.073151"/>
            </geometry>
        </collision>
        <inertial>
            <origin xyz="-0.00160396 0.0292536 -0.0972966" rpy="0 -0 0"/>
            <mass value="2.327121"/>
            <inertia ixx="5.161028e-02" ixy="-5.715173e-03" ixz="-3.567317e-03" iyy="4.787730e-02" iyz="1.067399e-02" izz="1.642363e-02"/>
        </inertial>
    </link>
    <joint name="fr3_joint5" type="revolute">
        <parent link="fr3_link4"/>
        <child link="fr3_link5"/>
        <origin xyz="-0.0825 0.384 0" rpy="-1.5708 0 0"/>
        <axis xyz="0 0 1"/>
        <limit lower="-2.806500" upper="2.806500" effort="12.000000" velocity="5.260000"/>
        <dynamics damping="0.003000" friction="0.200000"/>
    </joint>
    <link name="fr3_link6">
        <visual>
            <origin xyz="0 0 0" rpy="0 -0 0"/>
            <geometry>
                <mesh filename="/workspace/resources/fr3/meshes/fr3/visual/link6.dae"/>
            </geometry>
        </visual>
        <collision>
            <origin xyz="0.0430981 0.00348575 0.00323242" rpy="-2.24571 1.39748 -2.10251"/>
            <geometry>
                <cylinder radius="0.075958" length="0.185416"/>
            </geometry>
        </collision>
        <collision>
            <origin xyz="-0.0482209 -0.00899653 0.0132218" rpy="0 -0 0"/>
            <geometry>
                <sphere radius="0.075958"/>
            </geometry>
        </collision>
        <collision>
            <origin xyz="0.134417 0.015968 -0.00675696" rpy="0 -0 0"/>
            <geometry>
                <sphere radius="0.075958"/>
            </geometry>
        </collision>
        <inertial>
            <origin xyz="0.0597131 -0.0410295 -0.0101693" rpy="0 -0 0"/>
            <mass value="1.817038"/>
            <inertia ixx="5.412334e-03" ixy="6.193456e-03" ixz="1.421929e-03" iyy="1.405833e-02" iyz="-1.314075e-03" izz="1.608082e-02"/>
        </inertial>
    </link>
    <joint name="fr3_joint6" type="revolute">
        <parent link="fr3_link5"/>
        <child link="fr3_link6"/>
        <origin xyz="0 0 0" rpy="1.5708 -0 0"/>
        <axis xyz="0 0 1"/>
        <limit lower="0.544500" upper="4.516900" effort="12.000000" velocity="4.180000"/>
        <dynamics damping="0.003000" friction="0.200000"/>
    </joint>
    <link name="fr3_link7">
        <visual>
            <origin xyz="0 0 0" rpy="0 -0 0"/>
            <geometry>
                <mesh filename="/workspace/resources/fr3/meshes/fr3/visual/link7.dae"/>
            </geometry>
        </visual>
        <collision>
            <origin xyz="0.0123092 0.0122728 0.0787283" rpy="-1.43867 0.778569 -0.689884"/>
            <geometry>
                <cylinder radius="0.050662" length="0.142033"/>
            </geometry>
        </collision>
        <collision>
            <origin xyz="-0.0375631 -0.0378446 0.0720676" rpy="0 -0 0"/>
            <geometry>
                <sphere radius="0.050662"/>
            </geometry>
        </collision>
        <collision>
            <origin xyz="0.0621814 0.0623902 0.085389" rpy="0 -0 0"/>
            <geometry>
                <sphere radius="0.050662"/>
            </geometry>
        </collision>
        <inertial>
            <origin xyz="0.00452258 0.00862619 -0.0161633" rpy="0 -0 0"/>
            <mass value="0.627143"/>
            <inertia ixx="2.109239e-04" ixy="-2.433299e-05" ixz="4.564480e-05" iyy="1.771857e-04" iyz="8.744070e-05" izz="5.993191e-05"/>
        </inertial>
    </link>
    <joint name="fr3_joint7" type="revolute">
        <parent link="fr3_link6"/>
        <child link="fr3_link7"/>
        <origin xyz="0.088 0 0" rpy="1.5708 -0 0"/>
        <axis xyz="0 0 1"/>
        <limit lower="-3.015900" upper="3.015900" effort="12.000000" velocity="5.260000"/>
        <dynamics damping="0.003000" friction="0.200000"/>
    </joint>
    <link name="fr3_link8"/>
    <joint name="fr3_joint8" type="fixed">
        <parent link="fr3_link7"/>
        <child link="fr3_link8"/>
        <origin xyz="0 0 0.107" rpy="0 -0 0"/>
    </joint>
    <link name="world"/>
    <joint name="fr3_joint_world" type="fixed">
        <parent link="world"/>
        <child link="fr3_link0"/>
        <origin xyz="0 0 0" rpy="0 -0 0"/>
    </joint>
    <link name="hand_hand">
        <visual>
            <origin xyz="0 0 0" rpy="0 -0 0"/>
            <geometry>
                <mesh filename="/workspace/resources/fr3/meshes/franka_hand/visual/hand.dae"/>
            </geometry>
        </visual>
        <collision>
            <origin xyz="-0.000192559 -0.00164113 0.023825" rpy="1.60774 -0.00115343 -0.00119685"/>
            <geometry>
                <cylinder radius="0.048119" length="0.206419"/>
            </geometry>
        </collision>
        <collision>
            <origin xyz="-7.35146e-05 0.101498 0.0276375" rpy="0 -0 0"/>
            <geometry>
                <sphere radius="0.048119"/>
            </geometry>
        </collision>
        <collision>
            <origin xyz="-0.000311604 -0.10478 0.0200125" rpy="0 -0 0"/>
            <geometry>
                <sphere radius="0.048119"/>
            </geometry>
        </collision>
        <inertial>
            <origin xyz="-3.76e-05 0.0119128 0.020726" rpy="0 -0 0"/>
            <mass value="0.654400"/>
            <inertia ixx="1.860000e-03" ixy="0.000000e+00" ixz="0.000000e+00" iyy="3.000000e-04" iyz="-2.000000e-05" izz="1.740000e-03"/>
        </inertial>
    </link>
    <link name="hand_leftfinger">
        <visual>
            <origin xyz="-0.0165 0.0165 0.127733" rpy="-1.5708 0.202458 -1.5708"/>
            <geometry>
                <mesh filename="/workspace/resources/fr3/meshes/plate/collision/flex_griper_connect.stl"/>
            </geometry>
        </visual>
        <collision>
            <origin xyz="1.37044e-06 0.00730541 0.101116" rpy="-2.96055 -4.96385e-05 0.000546851"/>
            <geometry>
                <cylinder radius="0.013789" length="0.048333"/>
            </geometry>
        </collision>
        <collision>
            <origin xyz="2.57004e-06 0.00295398 0.124888" rpy="0 -0 0"/>
            <geometry>
                <sphere radius="0.013789"/>
            </geometry>
        </collision>
        <collision>
            <origin xyz="1.70846e-07 0.0116568 0.0773448" rpy="0 -0 0"/>
            <geometry>
                <sphere radius="0.013789"/>
            </geometry>
        </collision>
        <collision>
            <origin xyz="-1.42005e-06 0.0159681 0.0373294" rpy="-3.03427 -3.95284e-05 0.000735892"/>
            <geometry>
                <cylinder radius="0.026123" length="0.080494"/>
            </geometry>
        </collision>
        <collision>
            <origin xyz="1.70846e-07 0.0116568 0.0773448" rpy="0 -0 0"/>
            <geometry>
                <sphere radius="0.026123"/>
            </geometry>
        </collision>
        <collision>
            <origin xyz="-3.01095e-06 0.0202794 -0.00268608" rpy="0 -0 0"/>
            <geometry>
                <sphere radius="0.026123"/>
            </geometry>
        </collision>
        <inertial>
            <origin xyz="0 0.0145644 0.0227941" rpy="0 -0 0"/>
            <mass value="0.100000"/>
            <inertia ixx="3.012209e-05" ixy="0.000000e+00" ixz="0.000000e+00" iyy="2.958738e-05" iyz="0.000000e+00" izz="6.951252e-06"/>
        </inertial>
    </link>
    <joint name="hand_finger_joint1" type="prismatic">
        <parent link="hand_hand"/>
        <child link="hand_leftfinger"/>
        <origin xyz="0 0 0.0584" rpy="0 -0 0"/>
        <axis xyz="0 1 0"/>
        <limit lower="0.000000" upper="0.040000" effort="100.000000" velocity="0.200000"/>
        <dynamics damping="0.300000" friction="0.000000"/>
    </joint>
    <link name="hand_rightfinger">
        <visual>
            <origin xyz="-0.0165 0.0165 0.127733" rpy="-1.5708 0.202458 -1.5708"/>
            <geometry>
                <mesh filename="/workspace/resources/fr3/meshes/plate/collision/flex_griper_connect.stl"/>
            </geometry>
        </visual>
        <collision>
            <origin xyz="1.37044e-06 0.00730541 0.101116" rpy="-2.96055 -4.96385e-05 0.000546851"/>
            <geometry>
                <cylinder radius="0.013789" length="0.048333"/>
            </geometry>
        </collision>
        <collision>
            <origin xyz="2.57004e-06 0.00295398 0.124888" rpy="0 -0 0"/>
            <geometry>
                <sphere radius="0.013789"/>
            </geometry>
        </collision>
        <collision>
            <origin xyz="1.70846e-07 0.0116568 0.0773448" rpy="0 -0 0"/>
            <geometry>
                <sphere radius="0.013789"/>
            </geometry>
        </collision>
        <collision>
            <origin xyz="-1.42005e-06 0.0159681 0.0373294" rpy="-3.03427 -3.95284e-05 0.000735892"/>
            <geometry>
                <cylinder radius="0.026123" length="0.080494"/>
            </geometry>
        </collision>
        <collision>
            <origin xyz="1.70846e-07 0.0116568 0.0773448" rpy="0 -0 0"/>
            <geometry>
                <sphere radius="0.026123"/>
            </geometry>
        </collision>
        <collision>
            <origin xyz="-3.01095e-06 0.0202794 -0.00268608" rpy="0 -0 0"/>
            <geometry>
                <sphere radius="0.026123"/>
            </geometry>
        </collision>
        <inertial>
            <origin xyz="0 0.0145644 0.0227941" rpy="0 -0 3.14159"/>
            <mass value="0.100000"/>
            <inertia ixx="3.012209e-05" ixy="0.000000e+00" ixz="0.000000e+00" iyy="2.958738e-05" iyz="0.000000e+00" izz="6.951252e-06"/>
        </inertial>
    </link>
    <joint name="hand_finger_joint2" type="prismatic">
        <parent link="hand_hand"/>
        <child link="hand_rightfinger"/>
        <origin xyz="0 0 0.0584" rpy="0 -0 3.14159"/>
        <axis xyz="0 1 0"/>
        <limit lower="0.000000" upper="0.040000" effort="100.000000" velocity="0.200000"/>
        <dynamics damping="0.300000" friction="0.000000"/>
    </joint>
    <link name="hand_hand_tcp"/>
    <joint name="hand_hand_tcp_joint" type="fixed">
        <parent link="hand_hand"/>
        <child link="hand_hand_tcp"/>
        <origin xyz="0 0 0.1034" rpy="0 -0 0"/>
    </joint>
    <joint name="hand_joint_fr3_link8" type="fixed">
        <parent link="fr3_link8"/>
        <child link="hand_hand"/>
        <origin xyz="0 0 0" rpy="0 0 -0.785398"/>
    </joint>
</robot>
