<?xml version="1.0" encoding="utf-8"?>
<robot name="bot">
    <link name="fr3_link0">
        <visual>
            <origin xyz="0 0 0" rpy="0 -0 0"/>
            <geometry>
                <mesh filename="/workspace/resources/fr3/meshes/fr3/visual/link0.dae"/>
            </geometry>
        </visual>
        <collision>
            <origin xyz="-0.0377909 0.000107998 0.0397339" rpy="-0.00519164 1.19845 -0.00354589"/>
            <geometry>
                <cylinder radius="0.107683" length="0.073671"/>
            </geometry>
        </collision>
        <collision>
            <origin xyz="-0.0721023 3.84266e-05 0.0263333" rpy="0 -0 0"/>
            <geometry>
                <sphere radius="0.107683"/>
            </geometry>
        </collision>
        <collision>
            <origin xyz="-0.00347947 0.00017757 0.0531346" rpy="0 -0 0"/>
            <geometry>
                <sphere radius="0.107683"/>
            </geometry>
        </collision>
        <inertial>
            <origin xyz="-0.0172 0.0004 0.0745" rpy="0 -0 0"/>
            <mass value="2.396600"/>
            <inertia ixx="9.000000e-03" ixy="0.000000e+00" ixz="2.000000e-03" iyy="1.150000e-02" iyz="0.000000e+00" izz="8.500000e-03"/>
        </inertial>
    </link>
    <link name="fr3_link1">
        <visual>
            <origin xyz="0 0 0" rpy="0 -0 0"/>
            <geometry>
                <mesh filename="/workspace/resources/fr3/meshes/fr3/visual/link1.dae"/>
            </geometry>
        </visual>
        <collision>
            <origin xyz="-0.000148781 -0.0402153 -0.0607906" rpy="-2.74777 -0.00498923 0.0250077"/>
            <geometry>
                <cylinder radius="0.085299" length="0.133841"/>
            </geometry>
        </collision>
        <collision>
            <origin xyz="0.000185101 -0.0658941 0.00100641" rpy="0 -0 0"/>
            <geometry>
                <sphere radius="0.085299"/>
            </geometry>
        </collision>
        <collision>
            <origin xyz="-0.000482662 -0.0145365 -0.122588" rpy="0 -0 0"/>
            <geometry>
                <sphere radius="0.085299"/>
            </geometry>
        </collision>
        <collision>
            <origin xyz="-2.3186e-05 0.00867802 -0.192639" rpy="-2.85036 0.0105919 -0.0721939"/>
            <geometry>
                <cylinder radius="0.071244" length="0.004647"/>
            </geometry>
        </collision>
        <collision>
            <origin xyz="-4.77943e-05 0.00801095 -0.190413" rpy="0 -0 0"/>
            <geometry>
                <sphere radius="0.071244"/>
            </geometry>
        </collision>
        <collision>
            <origin xyz="1.42232e-06 0.00934509 -0.194864" rpy="0 -0 0"/>
            <geometry>
                <sphere radius="0.071244"/>
            </geometry>
        </collision>
        <inertial>
            <origin xyz="4.128e-07 -0.0181251 -0.0386036" rpy="0 -0 0"/>
            <mass value="2.927465"/>
            <inertia ixx="2.392732e-02" ixy="1.331790e-05" ixz="-1.140477e-04" iyy="2.248216e-02" iyz="-1.995032e-03" izz="6.350098e-03"/>
        </inertial>
    </link>
    <joint name="fr3_joint1" type="revolute">
        <parent link="fr3_link0"/>
        <child link="fr3_link1"/>
        <origin xyz="0 0 0.333" rpy="0 -0 0"/>
        <axis xyz="0 0 1"/>
        <limit lower="-2.743700" upper="2.743700" effort="87.000000" velocity="2.620000"/>
        <dynamics damping="0.003000" friction="0.200000"/>
    </joint>
    <link name="fr3_link2">
        <visual>
            <origin xyz="0 0 0" rpy="0 -0 0"/>
            <geometry>
                <mesh filename="/workspace/resources/fr3/meshes/fr3/visual/link2.dae"/>
            </geometry>
        </visual>
        <collision>
            <origin xyz="4.85941e-05 -0.0709501 0.0394974" rpy="1.92995 -0.00492845 -0.00711468"/>
            <geometry>
                <cylinder radius="0.086811" length="0.148798"/>
            </geometry>
        </collision>
        <collision>
            <origin xyz="0.000415265 -0.00129899 0.0656473" rpy="0 -0 0"/>
            <geometry>
                <sphere radius="0.086811"/>
            </geometry>
        </collision>
        <collision>
            <origin xyz="-0.000318077 -0.140601 0.0133475" rpy="0 -0 0"/>
            <geometry>
                <sphere radius="0.086811"/>
            </geometry>
        </collision>
        <inertial>
            <origin xyz="0.00318289 -0.0743222 0.00881461" rpy="0 -0 0"/>
            <mass value="2.935537"/>
            <inertia ixx="4.193895e-02" ixy="2.025733e-04" ixz="4.077784e-03" iyy="2.514515e-02" iyz="-4.225216e-03" izz="6.170214e-02"/>
        </inertial>
    </link>
    <joint name="fr3_joint2" type="revolute">
        <parent link="fr3_link1"/>
        <child link="fr3_link2"/>
        <origin xyz="0 0 0" rpy="-1.5708 0 0"/>
        <axis xyz="0 0 1"/>
        <limit lower="-1.783700" upper="1.783700" effort="87.000000" velocity="2.620000"/>
        <dynamics damping="0.003000" friction="0.200000"/>
    </joint>
    <link name="fr3_link3">
        <visual>
            <origin xyz="0 0 0" rpy="0 -0 0"/>
            <geometry>
                <mesh filename="/workspace/resources/fr3/meshes/fr3/visual/link3.dae"/>
            </geometry>
        </visual>
        <collision>
            <origin xyz="0.0462664 0.0289364 -0.0444485" rpy="-0.530784 0.692968 -0.195642"/>
            <geometry>
                <cylinder radius="0.079753" length="0.115592"/>
            </geometry>
        </collision>
        <collision>
            <origin xyz="0.00934492 0.00642748 -0.0827962" rpy="0 -0 0"/>
            <geometry>
                <sphere radius="0.079753"/>
            </geometry>
        </collision>
        <collision>
            <origin xyz="0.0831879 0.0514453 -0.00610091" rpy="0 -0 0"/>
            <geometry>
                <sphere radius="0.079753"/>
            </geometry>
        </collision>
        <inertial>
            <origin xyz="0.0407016 -0.00482006 -0.0289731" rpy="0 -0 0"/>
            <mass value="2.244901"/>
            <inertia ixx="2.410143e-02" ixy="2.404695e-03" ixz="-2.856269e-03" iyy="1.974053e-02" iyz="-2.104213e-03" izz="1.904449e-02"/>
        </inertial>
    </link>
    <joint name="fr3_joint3" type="revolute">
        <parent link="fr3_link2"/>
        <child link="fr3_link3"/>
        <origin xyz="0 -0.316 0" rpy="1.5708 -0 0"/>
        <axis xyz="0 0 1"/>
        <limit lower="-2.900700" upper="2.900700" effort="87.000000" velocity="2.620000"/>
        <dynamics damping="0.003000" friction="0.200000"/>
    </joint>
    <link name="fr3_link4">
        <visual>
            <origin xyz="0 0 0" rpy="0 -0 0"/>
            <geometry>
                <mesh filename="/workspace/resources/fr3/meshes/fr3/visual/link4.dae"/>
            </geometry>
        </visual>
        <collision>
            <origin xyz="-0.0360496 0.0457227 0.028843" rpy="1.05149 0.678404 0.403863"/>
            <geometry>
                <cylinder radius="0.079916" length="0.116163"/>
            </geometry>
        </collision>
        <collision>
            <origin xyz="-0.0724988 0.0849818 0.00640074" rpy="0 -0 0"/>
            <geometry>
                <sphere radius="0.079916"/>
            </geometry>
        </collision>
        <collision>
            <origin xyz="0.000399486 0.00646371 0.0512853" rpy="0 -0 0"/>
            <geometry>
                <sphere radius="0.079916"/>
            </geometry>
        </collision>
        <inertial>
            <origin xyz="-0.0459101 0.0630493 -0.00851879" rpy="0 -0 0"/>
            <mass value="2.615596"/>
            <inertia ixx="3.452998e-02" ixy="1.322552e-02" ixz="1.015143e-02" iyy="2.888162e-02" iyz="-9.762834e-04" izz="4.125471e-02"/>
        </inertial>
    </link>
    <joint name="fr3_joint4" type="revolute">
        <parent link="fr3_link3"/>
        <child link="fr3_link4"/>
        <origin xyz="0.0825 0 0" rpy="1.5708 -0 0"/>
        <axis xyz="0 0 1"/>
        <limit lower="-3.042100" upper="-0.151800" effort="87.000000" velocity="2.620000"/>
        <dynamics damping="0.003000" friction="0.200000"/>
    </joint>
    <link name="fr3_link5">
        <visual>
            <origin xyz="0 0 0" rpy="0 -0 0"/>
            <geometry>
                <mesh filename="/workspace/resources/fr3/meshes/fr3/visual/link5.dae"/>
            </geometry>
        </visual>
        <collision>
            <origin xyz="3.20336e-05 0.0363531 -0.110622" rpy="-0.270337 0.00257315 -0.000349943"/>
            <geometry>
                <cylinder radius="0.072580" length="0.227397"/>
            </geometry>
        </collision>
        <collision>
            <origin xyz="-0.00026053 0.00598926 -0.220191" rpy="0 -0 0"/>
            <geometry>
                <sphere radius="0.072580"/>
            </geometry>
        </collision>
        <collision>
            <origin xyz="0.000324597 0.0667169 -0.00105323" rpy="0 -0 0"/>
            <geometry>
                <sphere radius="0.072580"/>
            </geometry>
        </collision>
        <inertial>
            <origin xyz="-0.00160396 0.0292536 -0.0972966" rpy="0 -0 0"/>
            <mass value="2.327121"/>
            <inertia ixx="5.161028e-02" ixy="-5.715173e-03" ixz="-3.567317e-03" iyy="4.787730e-02" iyz="1.067399e-02" izz="1.642363e-02"/>
        </inertial>
    </link>
    <joint name="fr3_joint5" type="revolute">
        <parent link="fr3_link4"/>
        <child link="fr3_link5"/>
        <origin xyz="-0.0825 0.384 0" rpy="-1.5708 0 0"/>
        <axis xyz="0 0 1"/>
        <limit lower="-2.806500" upper="2.806500" effort="12.000000" velocity="5.260000"/>
        <dynamics damping="0.003000" friction="0.200000"/>
    </joint>
    <link name="fr3_link6">
        <visual>
            <origin xyz="0 0 0" rpy="0 -0 0"/>
            <geometry>
                <mesh filename="/workspace/resources/fr3/meshes/fr3/visual/link6.dae"/>
            </geometry>
        </visual>
        <collision>
            <origin xyz="0.0503694 0.00377663 0.00145815" rpy="-2.29626 1.40296 -2.16315"/>
            <geometry>
                <cylinder radius="0.076478" length="0.071069"/>
            </geometry>
        </collision>
        <collision>
            <origin xyz="0.015334 -0.000664717 0.00539664" rpy="0 -0 0"/>
            <geometry>
                <sphere radius="0.076478"/>
            </geometry>
        </collision>
        <collision>
            <origin xyz="0.0854048 0.00821797 -0.00248034" rpy="0 -0 0"/>
            <geometry>
                <sphere radius="0.076478"/>
            </geometry>
        </collision>
        <inertial>
            <origin xyz="0.0597131 -0.0410295 -0.0101693" rpy="0 -0 0"/>
            <mass value="1.817038"/>
            <inertia ixx="5.412334e-03" ixy="6.193456e-03" ixz="1.421929e-03" iyy="1.405833e-02" iyz="-1.314075e-03" izz="1.608082e-02"/>
        </inertial>
    </link>
    <joint name="fr3_joint6" type="revolute">
        <parent link="fr3_link5"/>
        <child link="fr3_link6"/>
        <origin xyz="0 0 0" rpy="1.5708 -0 0"/>
        <axis xyz="0 0 1"/>
        <limit lower="0.544500" upper="4.516900" effort="12.000000" velocity="4.180000"/>
        <dynamics damping="0.003000" friction="0.200000"/>
    </joint>
    <link name="fr3_link7">
        <visual>
            <origin xyz="0 0 0" rpy="0 -0 0"/>
            <geometry>
                <mesh filename="/workspace/resources/fr3/meshes/fr3/visual/link7.dae"/>
            </geometry>
        </visual>
        <collision>
            <origin xyz="0.0111747 0.0109921 0.0785859" rpy="-1.45415 0.77725 -0.698662"/>
            <geometry>
                <cylinder radius="0.050873" length="0.042026"/>
            </geometry>
        </collision>
        <collision>
            <origin xyz="-0.00356204 -0.00388504 0.0768425" rpy="0 -0 0"/>
            <geometry>
                <sphere radius="0.050873"/>
            </geometry>
        </collision>
        <collision>
            <origin xyz="0.0259115 0.0258692 0.0803292" rpy="0 -0 0"/>
            <geometry>
                <sphere radius="0.050873"/>
            </geometry>
        </collision>
        <collision>
            <origin xyz="0.0568217 0.0569763 0.085132" rpy="-1.39647 0.7755 -0.660462"/>
            <geometry>
                <cylinder radius="0.042971" length="0.002390"/>
            </geometry>
        </collision>
        <collision>
            <origin xyz="0.0559851 0.0561358 0.0849839" rpy="0 -0 0"/>
            <geometry>
                <sphere radius="0.042971"/>
            </geometry>
        </collision>
        <collision>
            <origin xyz="0.0576584 0.0578168 0.08528" rpy="0 -0 0"/>
            <geometry>
                <sphere radius="0.042971"/>
            </geometry>
        </collision>
        <inertial>
            <origin xyz="0.00452258 0.00862619 -0.0161633" rpy="0 -0 0"/>
            <mass value="0.627143"/>
            <inertia ixx="2.109239e-04" ixy="-2.433299e-05" ixz="4.564480e-05" iyy="1.771857e-04" iyz="8.744070e-05" izz="5.993191e-05"/>
        </inertial>
    </link>
    <joint name="fr3_joint7" type="revolute">
        <parent link="fr3_link6"/>
        <child link="fr3_link7"/>
        <origin xyz="0.088 0 0" rpy="1.5708 -0 0"/>
        <axis xyz="0 0 1"/>
        <limit lower="-3.015900" upper="3.015900" effort="12.000000" velocity="5.260000"/>
        <dynamics damping="0.003000" friction="0.200000"/>
    </joint>
    <link name="fr3_link8"/>
    <joint name="fr3_joint8" type="fixed">
        <parent link="fr3_link7"/>
        <child link="fr3_link8"/>
        <origin xyz="0 0 0.107" rpy="0 -0 0"/>
    </joint>
    <link name="world"/>
    <joint name="fr3_joint_world" type="fixed">
        <parent link="world"/>
        <child link="fr3_link0"/>
        <origin xyz="0 0 0" rpy="0 -0 0"/>
    </joint>
    <link name="hand_hand">
        <visual>
            <origin xyz="0 0 0" rpy="0 -0 0"/>
            <geometry>
                <mesh filename="/workspace/resources/fr3/meshes/franka_hand/visual/hand.dae"/>
            </geometry>
        </visual>
        <collision>
            <origin xyz="-0.000169047 -0.00529219 0.0247821" rpy="1.61264 -0.000985837 -0.00102798"/>
            <geometry>
                <cylinder radius="0.049001" length="0.141655"/>
            </geometry>
        </collision>
        <collision>
            <origin xyz="-9.92228e-05 0.0654733 0.027745" rpy="0 -0 0"/>
            <geometry>
                <sphere radius="0.049001"/>
            </geometry>
        </collision>
        <collision>
            <origin xyz="-0.000238872 -0.0760577 0.0218192" rpy="0 -0 0"/>
            <geometry>
                <sphere radius="0.049001"/>
            </geometry>
        </collision>
        <inertial>
            <origin xyz="-3.76e-05 0.0119128 0.020726" rpy="0 -0 0"/>
            <mass value="0.654400"/>
            <inertia ixx="1.860000e-03" ixy="0.000000e+00" ixz="0.000000e+00" iyy="3.000000e-04" iyz="-2.000000e-05" izz="1.740000e-03"/>
        </inertial>
    </link>
    <link name="hand_leftfinger">
        <visual>
            <origin xyz="-0.0165 0.0165 0.127733" rpy="-1.5708 0.202458 -1.5708"/>
            <geometry>
                <mesh filename="/workspace/resources/fr3/meshes/plate/collision/flex_griper_connect.stl"/>
            </geometry>
        </visual>
        <collision>
            <origin xyz="1.41071e-07 0.00776431 0.096105" rpy="-2.937 -5.63894e-06 5.49314e-05"/>
            <geometry>
                <cylinder radius="0.016130" length="0.037550"/>
            </geometry>
        </collision>
        <collision>
            <origin xyz="2.46943e-07 0.0039498 0.114489" rpy="0 -0 0"/>
            <geometry>
                <sphere radius="0.016130"/>
            </geometry>
        </collision>
        <collision>
            <origin xyz="3.51988e-08 0.0115788 0.0777214" rpy="0 -0 0"/>
            <geometry>
                <sphere radius="0.016130"/>
            </geometry>
        </collision>
        <collision>
            <origin xyz="-2.31687e-07 0.0138524 0.0569637" rpy="-3.06876 -1.54657e-05 0.000424485"/>
            <geometry>
                <cylinder radius="0.026186" length="0.016366"/>
            </geometry>
        </collision>
        <collision>
            <origin xyz="-1.05129e-07 0.0132569 0.0651252" rpy="0 -0 0"/>
            <geometry>
                <sphere radius="0.026186"/>
            </geometry>
        </collision>
        <collision>
            <origin xyz="-3.58245e-07 0.0144479 0.0488022" rpy="0 -0 0"/>
            <geometry>
                <sphere radius="0.026186"/>
            </geometry>
        </collision>
        <collision>
            <origin xyz="-6.94855e-07 0.0160318 0.027095" rpy="-3.06876 -1.54657e-05 0.000424485"/>
            <geometry>
                <cylinder radius="0.027077" length="0.012071"/>
            </geometry>
        </collision>
        <collision>
            <origin xyz="-6.01515e-07 0.0155926 0.0331143" rpy="0 -0 0"/>
            <geometry>
                <sphere radius="0.027077"/>
            </geometry>
        </collision>
        <collision>
            <origin xyz="-7.88195e-07 0.016471 0.0210757" rpy="0 -0 0"/>
            <geometry>
                <sphere radius="0.027077"/>
            </geometry>
        </collision>
        <inertial>
            <origin xyz="0 0.0145644 0.0227941" rpy="0 -0 0"/>
            <mass value="0.100000"/>
            <inertia ixx="3.012209e-05" ixy="0.000000e+00" ixz="0.000000e+00" iyy="2.958738e-05" iyz="0.000000e+00" izz="6.951252e-06"/>
        </inertial>
    </link>
    <joint name="hand_finger_joint1" type="prismatic">
        <parent link="hand_hand"/>
        <child link="hand_leftfinger"/>
        <origin xyz="0 0 0.0584" rpy="0 -0 0"/>
        <axis xyz="0 1 0"/>
        <limit lower="0.000000" upper="0.040000" effort="100.000000" velocity="0.200000"/>
        <dynamics damping="0.300000" friction="0.000000"/>
    </joint>
    <link name="hand_rightfinger">
        <visual>
            <origin xyz="-0.0165 0.0165 0.127733" rpy="-1.5708 0.202458 -1.5708"/>
            <geometry>
                <mesh filename="/workspace/resources/fr3/meshes/plate/collision/flex_griper_connect.stl"/>
            </geometry>
        </visual>
        <collision>
            <origin xyz="1.41071e-07 0.00776431 0.096105" rpy="-2.937 -5.63894e-06 5.49314e-05"/>
            <geometry>
                <cylinder radius="0.016130" length="0.037550"/>
            </geometry>
        </collision>
        <collision>
            <origin xyz="2.46943e-07 0.0039498 0.114489" rpy="0 -0 0"/>
            <geometry>
                <sphere radius="0.016130"/>
            </geometry>
        </collision>
        <collision>
            <origin xyz="3.51988e-08 0.0115788 0.0777214" rpy="0 -0 0"/>
            <geometry>
                <sphere radius="0.016130"/>
            </geometry>
        </collision>
        <collision>
            <origin xyz="-2.31687e-07 0.0138524 0.0569637" rpy="-3.06876 -1.54657e-05 0.000424485"/>
            <geometry>
                <cylinder radius="0.026186" length="0.016366"/>
            </geometry>
        </collision>
        <collision>
            <origin xyz="-1.05129e-07 0.0132569 0.0651252" rpy="0 -0 0"/>
            <geometry>
                <sphere radius="0.026186"/>
            </geometry>
        </collision>
        <collision>
            <origin xyz="-3.58245e-07 0.0144479 0.0488022" rpy="0 -0 0"/>
            <geometry>
                <sphere radius="0.026186"/>
            </geometry>
        </collision>
        <collision>
            <origin xyz="-6.94855e-07 0.0160318 0.027095" rpy="-3.06876 -1.54657e-05 0.000424485"/>
            <geometry>
                <cylinder radius="0.027077" length="0.012071"/>
            </geometry>
        </collision>
        <collision>
            <origin xyz="-6.01515e-07 0.0155926 0.0331143" rpy="0 -0 0"/>
            <geometry>
                <sphere radius="0.027077"/>
            </geometry>
        </collision>
        <collision>
            <origin xyz="-7.88195e-07 0.016471 0.0210757" rpy="0 -0 0"/>
            <geometry>
                <sphere radius="0.027077"/>
            </geometry>
        </collision>
        <inertial>
            <origin xyz="0 0.0145644 0.0227941" rpy="0 -0 3.14159"/>
            <mass value="0.100000"/>
            <inertia ixx="3.012209e-05" ixy="0.000000e+00" ixz="0.000000e+00" iyy="2.958738e-05" iyz="0.000000e+00" izz="6.951252e-06"/>
        </inertial>
    </link>
    <joint name="hand_finger_joint2" type="prismatic">
        <parent link="hand_hand"/>
        <child link="hand_rightfinger"/>
        <origin xyz="0 0 0.0584" rpy="0 -0 3.14159"/>
        <axis xyz="0 1 0"/>
        <limit lower="0.000000" upper="0.040000" effort="100.000000" velocity="0.200000"/>
        <dynamics damping="0.300000" friction="0.000000"/>
    </joint>
    <link name="hand_hand_tcp"/>
    <joint name="hand_hand_tcp_joint" type="fixed">
        <parent link="hand_hand"/>
        <child link="hand_hand_tcp"/>
        <origin xyz="0 0 0.1034" rpy="0 -0 0"/>
    </joint>
    <joint name="hand_joint_fr3_link8" type="fixed">
        <parent link="fr3_link8"/>
        <child link="hand_hand"/>
        <origin xyz="0 0 0" rpy="0 0 -0.785398"/>
    </joint>
</robot>
