<?xml version="1.0" encoding="utf-8"?>
<robot name="bot">
    <link name="fr3_link0">
        <visual>
            <origin xyz="0 0 0" rpy="0 -0 0"/>
            <geometry>
                <mesh filename="/workspace/resources/fr3/meshes/fr3/visual/link0.dae"/>
            </geometry>
        </visual>
        <collision>
            <origin xyz="-0.143265 0.0176363 0.0168881" rpy="-0.00954932 1.30832 -0.00732231"/>
            <geometry>
                <cylinder radius="0.115454" length="0.029766"/>
            </geometry>
        </collision>
        <collision>
            <origin xyz="-0.157638 0.0175994 0.0130265" rpy="0 -0 0"/>
            <geometry>
                <sphere radius="0.115454"/>
            </geometry>
        </collision>
        <collision>
            <origin xyz="-0.128891 0.0176732 0.0207497" rpy="0 -0 0"/>
            <geometry>
                <sphere radius="0.115454"/>
            </geometry>
        </collision>
        <collision>
            <origin xyz="-0.141083 0.0512862 0.00844595" rpy="-0.00954932 1.30832 -0.00732231"/>
            <geometry>
                <cylinder radius="0.049697" length="0.029766"/>
            </geometry>
        </collision>
        <collision>
            <origin xyz="-0.155456 0.0512494 0.00458434" rpy="0 -0 0"/>
            <geometry>
                <sphere radius="0.049697"/>
            </geometry>
        </collision>
        <collision>
            <origin xyz="-0.12671 0.0513231 0.0123076" rpy="0 -0 0"/>
            <geometry>
                <sphere radius="0.049697"/>
            </geometry>
        </collision>
        <collision>
            <origin xyz="0.0640938 -0.0433899 0.0487081" rpy="-0.00954932 1.30832 -0.00732231"/>
            <geometry>
                <cylinder radius="0.080217" length="0.029766"/>
            </geometry>
        </collision>
        <collision>
            <origin xyz="0.0497206 -0.0434267 0.0448465" rpy="0 -0 0"/>
            <geometry>
                <sphere radius="0.080217"/>
            </geometry>
        </collision>
        <collision>
            <origin xyz="0.078467 -0.043353 0.0525697" rpy="0 -0 0"/>
            <geometry>
                <sphere radius="0.080217"/>
            </geometry>
        </collision>
        <collision>
            <origin xyz="0.0517482 -0.0484503 0.094708" rpy="-0.00954932 1.30832 -0.00732231"/>
            <geometry>
                <cylinder radius="0.111662" length="0.029766"/>
            </geometry>
        </collision>
        <collision>
            <origin xyz="0.037375 -0.0484872 0.0908464" rpy="0 -0 0"/>
            <geometry>
                <sphere radius="0.111662"/>
            </geometry>
        </collision>
        <collision>
            <origin xyz="0.0661214 -0.0484134 0.0985696" rpy="0 -0 0"/>
            <geometry>
                <sphere radius="0.111662"/>
            </geometry>
        </collision>
        <collision>
            <origin xyz="0.0738648 -0.0376176 0.0122846" rpy="-0.00954932 1.30832 -0.00732231"/>
            <geometry>
                <cylinder radius="0.083681" length="0.029766"/>
            </geometry>
        </collision>
        <collision>
            <origin xyz="0.0594916 -0.0376545 0.00842303" rpy="0 -0 0"/>
            <geometry>
                <sphere radius="0.083681"/>
            </geometry>
        </collision>
        <collision>
            <origin xyz="0.088238 -0.0375807 0.0161462" rpy="0 -0 0"/>
            <geometry>
                <sphere radius="0.083681"/>
            </geometry>
        </collision>
        <collision>
            <origin xyz="0.0426177 -0.0503629 0.12871" rpy="-0.00954932 1.30832 -0.00732231"/>
            <geometry>
                <cylinder radius="0.043401" length="0.029766"/>
            </geometry>
        </collision>
        <collision>
            <origin xyz="0.0282445 -0.0503997 0.124849" rpy="0 -0 0"/>
            <geometry>
                <sphere radius="0.043401"/>
            </geometry>
        </collision>
        <collision>
            <origin xyz="0.0569909 -0.050326 0.132572" rpy="0 -0 0"/>
            <geometry>
                <sphere radius="0.043401"/>
            </geometry>
        </collision>
        <collision>
            <origin xyz="0.0401631 -0.0200161 0.137557" rpy="-0.00954932 1.30832 -0.00732231"/>
            <geometry>
                <cylinder radius="0.084345" length="0.029766"/>
            </geometry>
        </collision>
        <collision>
            <origin xyz="0.0257899 -0.0200529 0.133695" rpy="0 -0 0"/>
            <geometry>
                <sphere radius="0.084345"/>
            </geometry>
        </collision>
        <collision>
            <origin xyz="0.0545363 -0.0199792 0.141418" rpy="0 -0 0"/>
            <geometry>
                <sphere radius="0.084345"/>
            </geometry>
        </collision>
        <collision>
            <origin xyz="0.0436386 0.0296281 0.124147" rpy="-0.00954932 1.30832 -0.00732231"/>
            <geometry>
                <cylinder radius="0.085592" length="0.029766"/>
            </geometry>
        </collision>
        <collision>
            <origin xyz="0.0292654 0.0295912 0.120285" rpy="0 -0 0"/>
            <geometry>
                <sphere radius="0.085592"/>
            </geometry>
        </collision>
        <collision>
            <origin xyz="0.0580118 0.029665 0.128009" rpy="0 -0 0"/>
            <geometry>
                <sphere radius="0.085592"/>
            </geometry>
        </collision>
        <collision>
            <origin xyz="0.0690499 0.040915 0.0294563" rpy="-0.00954932 1.30832 -0.00732231"/>
            <geometry>
                <cylinder radius="0.081212" length="0.029766"/>
            </geometry>
        </collision>
        <collision>
            <origin xyz="0.0546767 0.0408781 0.0255947" rpy="0 -0 0"/>
            <geometry>
                <sphere radius="0.081212"/>
            </geometry>
        </collision>
        <collision>
            <origin xyz="0.0834231 0.0409519 0.0333179" rpy="0 -0 0"/>
            <geometry>
                <sphere radius="0.081212"/>
            </geometry>
        </collision>
        <collision>
            <origin xyz="0.0556876 0.047361 0.0791302" rpy="-0.00954932 1.30832 -0.00732231"/>
            <geometry>
                <cylinder radius="0.053362" length="0.029766"/>
            </geometry>
        </collision>
        <collision>
            <origin xyz="0.0413144 0.0473241 0.0752686" rpy="0 -0 0"/>
            <geometry>
                <sphere radius="0.053362"/>
            </geometry>
        </collision>
        <collision>
            <origin xyz="0.0700608 0.0473979 0.0829918" rpy="0 -0 0"/>
            <geometry>
                <sphere radius="0.053362"/>
            </geometry>
        </collision>
        <collision>
            <origin xyz="0.0401971 -0.0502312 0.137719" rpy="-0.00954932 1.30832 -0.00732231"/>
            <geometry>
                <cylinder radius="0.064615" length="0.029766"/>
            </geometry>
        </collision>
        <collision>
            <origin xyz="0.0258239 -0.0502681 0.133858" rpy="0 -0 0"/>
            <geometry>
                <sphere radius="0.064615"/>
            </geometry>
        </collision>
        <collision>
            <origin xyz="0.0545703 -0.0501944 0.141581" rpy="0 -0 0"/>
            <geometry>
                <sphere radius="0.064615"/>
            </geometry>
        </collision>
        <collision>
            <origin xyz="0.0430137 0.0511324 0.126267" rpy="-0.00954932 1.30832 -0.00732231"/>
            <geometry>
                <cylinder radius="0.072171" length="0.029766"/>
            </geometry>
        </collision>
        <collision>
            <origin xyz="0.0286405 0.0510955 0.122406" rpy="0 -0 0"/>
            <geometry>
                <sphere radius="0.072171"/>
            </geometry>
        </collision>
        <collision>
            <origin xyz="0.0573869 0.0511693 0.130129" rpy="0 -0 0"/>
            <geometry>
                <sphere radius="0.072171"/>
            </geometry>
        </collision>
        <inertial>
            <origin xyz="-0.0172 0.0004 0.0745" rpy="0 -0 0"/>
            <mass value="2.396600"/>
            <inertia ixx="9.000000e-03" ixy="0.000000e+00" ixz="2.000000e-03" iyy="1.150000e-02" iyz="0.000000e+00" izz="8.500000e-03"/>
        </inertial>
    </link>
    <link name="fr3_link1">
        <visual>
            <origin xyz="0 0 0" rpy="0 -0 0"/>
            <geometry>
                <mesh filename="/workspace/resources/fr3/meshes/fr3/visual/link1.dae"/>
            </geometry>
        </visual>
        <collision>
            <origin xyz="-0.00182145 -0.0720469 0.042498" rpy="-2.72626 -0.00489156 0.0232143"/>
            <geometry>
                <cylinder radius="0.085320" length="0.035450"/>
            </geometry>
        </collision>
        <collision>
            <origin xyz="-0.00173475 -0.0791988 0.0587158" rpy="0 -0 0"/>
            <geometry>
                <sphere radius="0.085320"/>
            </geometry>
        </collision>
        <collision>
            <origin xyz="-0.00190816 -0.0648951 0.0262802" rpy="0 -0 0"/>
            <geometry>
                <sphere radius="0.085320"/>
            </geometry>
        </collision>
        <collision>
            <origin xyz="-0.0180008 -0.133157 0.0156356" rpy="-2.72626 -0.00489156 0.0232143"/>
            <geometry>
                <cylinder radius="0.075402" length="0.035450"/>
            </geometry>
        </collision>
        <collision>
            <origin xyz="-0.0179141 -0.140309 0.0318534" rpy="0 -0 0"/>
            <geometry>
                <sphere radius="0.075402"/>
            </geometry>
        </collision>
        <collision>
            <origin xyz="-0.0180875 -0.126006 -0.00058221" rpy="0 -0 0"/>
            <geometry>
                <sphere radius="0.075402"/>
            </geometry>
        </collision>
        <collision>
            <origin xyz="-0.000111972 -0.0393756 -0.0399643" rpy="0 -0 0"/>
            <geometry>
                <sphere radius="0.085223"/>
            </geometry>
        </collision>
        <collision>
            <origin xyz="-2.65447e-05 -0.0180007 -0.108027" rpy="0 -0 0"/>
            <geometry>
                <sphere radius="0.078295"/>
            </geometry>
        </collision>
        <collision>
            <origin xyz="-3.11824e-05 0.00897276 -0.192993" rpy="-2.72626 -0.00489156 0.0232143"/>
            <geometry>
                <cylinder radius="0.074385" length="0.035450"/>
            </geometry>
        </collision>
        <collision>
            <origin xyz="5.55199e-05 0.00182092 -0.176775" rpy="0 -0 0"/>
            <geometry>
                <sphere radius="0.074385"/>
            </geometry>
        </collision>
        <collision>
            <origin xyz="-0.000117885 0.0161246 -0.209211" rpy="0 -0 0"/>
            <geometry>
                <sphere radius="0.074385"/>
            </geometry>
        </collision>
        <inertial>
            <origin xyz="4.128e-07 -0.0181251 -0.0386036" rpy="0 -0 0"/>
            <mass value="2.927465"/>
            <inertia ixx="2.392732e-02" ixy="1.331790e-05" ixz="-1.140477e-04" iyy="2.248216e-02" iyz="-1.995032e-03" izz="6.350098e-03"/>
        </inertial>
    </link>
    <joint name="fr3_joint1" type="revolute">
        <parent link="fr3_link0"/>
        <child link="fr3_link1"/>
        <origin xyz="0 0 0.333" rpy="0 -0 0"/>
        <axis xyz="0 0 1"/>
        <limit lower="-2.743700" upper="2.743700" effort="87.000000" velocity="2.620000"/>
        <dynamics damping="0.003000" friction="0.200000"/>
    </joint>
    <link name="fr3_link2">
        <visual>
            <origin xyz="0 0 0" rpy="0 -0 0"/>
            <geometry>
                <mesh filename="/workspace/resources/fr3/meshes/fr3/visual/link2.dae"/>
            </geometry>
        </visual>
        <collision>
            <origin xyz="0.00132637 0.0423205 0.0715055" rpy="1.97629 -0.00635987 -0.00965132"/>
            <geometry>
                <cylinder radius="0.084856" length="0.035613"/>
            </geometry>
        </collision>
        <collision>
            <origin xyz="0.00143962 0.0586829 0.0785297" rpy="0 -0 0"/>
            <geometry>
                <sphere radius="0.084856"/>
            </geometry>
        </collision>
        <collision>
            <origin xyz="0.00121312 0.0259581 0.0644813" rpy="0 -0 0"/>
            <geometry>
                <sphere radius="0.084856"/>
            </geometry>
        </collision>
        <collision>
            <origin xyz="5.82993e-05 -0.0407091 0.0392321" rpy="0 -0 0"/>
            <geometry>
                <sphere radius="0.084693"/>
            </geometry>
        </collision>
        <collision>
            <origin xyz="-0.0416283 -0.0993824 -0.00398487" rpy="0 -0 0"/>
            <geometry>
                <sphere radius="0.071082"/>
            </geometry>
        </collision>
        <collision>
            <origin xyz="0.00444347 -0.0870102 -0.0335478" rpy="0 -0 0"/>
            <geometry>
                <sphere radius="0.071256"/>
            </geometry>
        </collision>
        <collision>
            <origin xyz="-0.0543332 -0.114882 0.0323247" rpy="0 -0 0"/>
            <geometry>
                <sphere radius="0.070174"/>
            </geometry>
        </collision>
        <collision>
            <origin xyz="-0.00705708 -0.122739 0.0498646" rpy="0 -0 0"/>
            <geometry>
                <sphere radius="0.072870"/>
            </geometry>
        </collision>
        <collision>
            <origin xyz="0.0318066 -0.116454 0.0345994" rpy="0 -0 0"/>
            <geometry>
                <sphere radius="0.072246"/>
            </geometry>
        </collision>
        <collision>
            <origin xyz="0.0253701 -0.100447 -0.00258475" rpy="0 -0 0"/>
            <geometry>
                <sphere radius="0.071326"/>
            </geometry>
        </collision>
        <collision>
            <origin xyz="-0.000119702 -0.194549 -0.00867651" rpy="1.97629 -0.00635987 -0.00965132"/>
            <geometry>
                <cylinder radius="0.063972" length="0.035613"/>
            </geometry>
        </collision>
        <collision>
            <origin xyz="-6.45422e-06 -0.178186 -0.00165231" rpy="0 -0 0"/>
            <geometry>
                <sphere radius="0.063972"/>
            </geometry>
        </collision>
        <collision>
            <origin xyz="-0.00023295 -0.210911 -0.0157007" rpy="0 -0 0"/>
            <geometry>
                <sphere radius="0.063972"/>
            </geometry>
        </collision>
        <inertial>
            <origin xyz="0.00318289 -0.0743222 0.00881461" rpy="0 -0 0"/>
            <mass value="2.935537"/>
            <inertia ixx="4.193895e-02" ixy="2.025733e-04" ixz="4.077784e-03" iyy="2.514515e-02" iyz="-4.225216e-03" izz="6.170214e-02"/>
        </inertial>
    </link>
    <joint name="fr3_joint2" type="revolute">
        <parent link="fr3_link1"/>
        <child link="fr3_link2"/>
        <origin xyz="0 0 0" rpy="-1.5708 0 0"/>
        <axis xyz="0 0 1"/>
        <limit lower="-1.783700" upper="1.783700" effort="87.000000" velocity="2.620000"/>
        <dynamics damping="0.003000" friction="0.200000"/>
    </joint>
    <link name="fr3_link3">
        <visual>
            <origin xyz="0 0 0" rpy="0 -0 0"/>
            <geometry>
                <mesh filename="/workspace/resources/fr3/meshes/fr3/visual/link3.dae"/>
            </geometry>
        </visual>
        <collision>
            <origin xyz="-0.048511 -0.0298195 -0.09217" rpy="0.529372 0.666073 0.186974"/>
            <geometry>
                <cylinder radius="0.075378" length="0.047508"/>
            </geometry>
        </collision>
        <collision>
            <origin xyz="-0.0631887 -0.020388 -0.10829" rpy="0 -0 0"/>
            <geometry>
                <sphere radius="0.075378"/>
            </geometry>
        </collision>
        <collision>
            <origin xyz="-0.0338333 -0.0392511 -0.0760497" rpy="0 -0 0"/>
            <geometry>
                <sphere radius="0.075378"/>
            </geometry>
        </collision>
        <collision>
            <origin xyz="-0.0447399 -0.0457806 -0.0854808" rpy="-0.605558 0.760189 -0.248324"/>
            <geometry>
                <cylinder radius="0.048197" length="0.031656"/>
            </geometry>
        </collision>
        <collision>
            <origin xyz="-0.0556465 -0.05231 -0.094912" rpy="0 -0 0"/>
            <geometry>
                <sphere radius="0.048197"/>
            </geometry>
        </collision>
        <collision>
            <origin xyz="-0.0338333 -0.0392511 -0.0760497" rpy="0 -0 0"/>
            <geometry>
                <sphere radius="0.048197"/>
            </geometry>
        </collision>
        <collision>
            <origin xyz="-0.0273027 -0.0164498 -0.125952" rpy="-0.605558 0.760189 -0.248324"/>
            <geometry>
                <cylinder radius="0.074491" length="0.031656"/>
            </geometry>
        </collision>
        <collision>
            <origin xyz="-0.0382093 -0.0229793 -0.135384" rpy="0 -0 0"/>
            <geometry>
                <sphere radius="0.074491"/>
            </geometry>
        </collision>
        <collision>
            <origin xyz="-0.0163962 -0.00992039 -0.116521" rpy="0 -0 0"/>
            <geometry>
                <sphere radius="0.074491"/>
            </geometry>
        </collision>
        <collision>
            <origin xyz="0.0332838 0.00967526 0.0249761" rpy="1.19329 0.23344 0.158946"/>
            <geometry>
                <cylinder radius="0.058311" length="0.034267"/>
            </geometry>
        </collision>
        <collision>
            <origin xyz="0.0293203 0.0251703 0.0188319" rpy="0 -0 0"/>
            <geometry>
                <sphere radius="0.058311"/>
            </geometry>
        </collision>
        <collision>
            <origin xyz="0.0372472 -0.00581975 0.0311202" rpy="0 -0 0"/>
            <geometry>
                <sphere radius="0.058311"/>
            </geometry>
        </collision>
        <collision>
            <origin xyz="0.0696432 0.0687817 -0.0579927" rpy="0 -0 0"/>
            <geometry>
                <sphere radius="0.067575"/>
            </geometry>
        </collision>
        <collision>
            <origin xyz="0.0887595 0.0596611 0.0590374" rpy="-0.605558 0.760189 -0.248324"/>
            <geometry>
                <cylinder radius="0.040862" length="0.031656"/>
            </geometry>
        </collision>
        <collision>
            <origin xyz="0.0778529 0.0531316 0.0496062" rpy="0 -0 0"/>
            <geometry>
                <sphere radius="0.040862"/>
            </geometry>
        </collision>
        <collision>
            <origin xyz="0.0996661 0.0661905 0.0684685" rpy="0 -0 0"/>
            <geometry>
                <sphere radius="0.040862"/>
            </geometry>
        </collision>
        <collision>
            <origin xyz="0.109546 0.0221941 0.0609378" rpy="-0.605558 0.760189 -0.248324"/>
            <geometry>
                <cylinder radius="0.037438" length="0.031656"/>
            </geometry>
        </collision>
        <collision>
            <origin xyz="0.0986399 0.0156647 0.0515067" rpy="0 -0 0"/>
            <geometry>
                <sphere radius="0.037438"/>
            </geometry>
        </collision>
        <collision>
            <origin xyz="0.120453 0.0287235 0.070369" rpy="0 -0 0"/>
            <geometry>
                <sphere radius="0.037438"/>
            </geometry>
        </collision>
        <collision>
            <origin xyz="0.117938 0.0117854 0.0584398" rpy="-0.605558 0.760189 -0.248324"/>
            <geometry>
                <cylinder radius="0.034368" length="0.031656"/>
            </geometry>
        </collision>
        <collision>
            <origin xyz="0.107031 0.005256 0.0490086" rpy="0 -0 0"/>
            <geometry>
                <sphere radius="0.034368"/>
            </geometry>
        </collision>
        <collision>
            <origin xyz="0.128845 0.0183149 0.0678709" rpy="0 -0 0"/>
            <geometry>
                <sphere radius="0.034368"/>
            </geometry>
        </collision>
        <collision>
            <origin xyz="0.145337 0.0200669 0.0210212" rpy="-0.605558 0.760189 -0.248324"/>
            <geometry>
                <cylinder radius="0.052067" length="0.031656"/>
            </geometry>
        </collision>
        <collision>
            <origin xyz="0.13443 0.0135374 0.01159" rpy="0 -0 0"/>
            <geometry>
                <sphere radius="0.052067"/>
            </geometry>
        </collision>
        <collision>
            <origin xyz="0.156243 0.0265963 0.0304523" rpy="0 -0 0"/>
            <geometry>
                <sphere radius="0.052067"/>
            </geometry>
        </collision>
        <collision>
            <origin xyz="0.131202 0.0088289 0.0451475" rpy="-0.605558 0.760189 -0.248324"/>
            <geometry>
                <cylinder radius="0.035667" length="0.031656"/>
            </geometry>
        </collision>
        <collision>
            <origin xyz="0.120295 0.00229947 0.0357164" rpy="0 -0 0"/>
            <geometry>
                <sphere radius="0.035667"/>
            </geometry>
        </collision>
        <collision>
            <origin xyz="0.142109 0.0153583 0.0545786" rpy="0 -0 0"/>
            <geometry>
                <sphere radius="0.035667"/>
            </geometry>
        </collision>
        <collision>
            <origin xyz="0.11148 0.0708151 0.0250396" rpy="-0.605558 0.760189 -0.248324"/>
            <geometry>
                <cylinder radius="0.057856" length="0.031656"/>
            </geometry>
        </collision>
        <collision>
            <origin xyz="0.100574 0.0642856 0.0156085" rpy="0 -0 0"/>
            <geometry>
                <sphere radius="0.057856"/>
            </geometry>
        </collision>
        <collision>
            <origin xyz="0.122387 0.0773445 0.0344708" rpy="0 -0 0"/>
            <geometry>
                <sphere radius="0.057856"/>
            </geometry>
        </collision>
        <collision>
            <origin xyz="0.0746297 0.103645 0.0449267" rpy="-0.605558 0.760189 -0.248324"/>
            <geometry>
                <cylinder radius="0.057418" length="0.031656"/>
            </geometry>
        </collision>
        <collision>
            <origin xyz="0.0637231 0.0971151 0.0354956" rpy="0 -0 0"/>
            <geometry>
                <sphere radius="0.057418"/>
            </geometry>
        </collision>
        <collision>
            <origin xyz="0.0855363 0.110174 0.0543579" rpy="0 -0 0"/>
            <geometry>
                <sphere radius="0.057418"/>
            </geometry>
        </collision>
        <inertial>
            <origin xyz="0.0407016 -0.00482006 -0.0289731" rpy="0 -0 0"/>
            <mass value="2.244901"/>
            <inertia ixx="2.410143e-02" ixy="2.404695e-03" ixz="-2.856269e-03" iyy="1.974053e-02" iyz="-2.104213e-03" izz="1.904449e-02"/>
        </inertial>
    </link>
    <joint name="fr3_joint3" type="revolute">
        <parent link="fr3_link2"/>
        <child link="fr3_link3"/>
        <origin xyz="0 -0.316 0" rpy="1.5708 -0 0"/>
        <axis xyz="0 0 1"/>
        <limit lower="-2.900700" upper="2.900700" effort="87.000000" velocity="2.620000"/>
        <dynamics damping="0.003000" friction="0.200000"/>
    </joint>
    <link name="fr3_link4">
        <visual>
            <origin xyz="0 0 0" rpy="0 -0 0"/>
            <geometry>
                <mesh filename="/workspace/resources/fr3/meshes/fr3/visual/link4.dae"/>
            </geometry>
        </visual>
        <collision>
            <origin xyz="-0.105099 0.0361673 0.0335155" rpy="2.22269 -0.337373 -0.663018"/>
            <geometry>
                <cylinder radius="0.123103" length="0.034324"/>
            </geometry>
        </collision>
        <collision>
            <origin xyz="-0.0994187 0.049041 0.0433406" rpy="0 -0 0"/>
            <geometry>
                <sphere radius="0.123103"/>
            </geometry>
        </collision>
        <collision>
            <origin xyz="-0.11078 0.0232937 0.0236904" rpy="0 -0 0"/>
            <geometry>
                <sphere radius="0.123103"/>
            </geometry>
        </collision>
        <collision>
            <origin xyz="-0.10584 0.0188842 0.00900452" rpy="2.8499 0.311693 1.63809"/>
            <geometry>
                <cylinder radius="0.126120" length="0.032220"/>
            </geometry>
        </collision>
        <collision>
            <origin xyz="-0.11078 0.0232937 0.0236904" rpy="0 -0 0"/>
            <geometry>
                <sphere radius="0.126120"/>
            </geometry>
        </collision>
        <collision>
            <origin xyz="-0.100899 0.0144747 -0.00568139" rpy="0 -0 0"/>
            <geometry>
                <sphere radius="0.126120"/>
            </geometry>
        </collision>
        <collision>
            <origin xyz="0.0170202 -0.0636118 0.0332576" rpy="0.979275 0.741971 0.40882"/>
            <geometry>
                <cylinder radius="0.046693" length="0.031882"/>
            </geometry>
        </collision>
        <collision>
            <origin xyz="0.00624818 -0.0538575 0.0267051" rpy="0 -0 0"/>
            <geometry>
                <sphere radius="0.046693"/>
            </geometry>
        </collision>
        <collision>
            <origin xyz="0.0277923 -0.073366 0.0398101" rpy="0 -0 0"/>
            <geometry>
                <sphere radius="0.046693"/>
            </geometry>
        </collision>
        <collision>
            <origin xyz="0.0189723 -0.0633772 0.0303977" rpy="0.979275 0.741971 0.40882"/>
            <geometry>
                <cylinder radius="0.039487" length="0.031882"/>
            </geometry>
        </collision>
        <collision>
            <origin xyz="0.00820028 -0.0536229 0.0238451" rpy="0 -0 0"/>
            <geometry>
                <sphere radius="0.039487"/>
            </geometry>
        </collision>
        <collision>
            <origin xyz="0.0297444 -0.0731314 0.0369502" rpy="0 -0 0"/>
            <geometry>
                <sphere radius="0.039487"/>
            </geometry>
        </collision>
        <collision>
            <origin xyz="0.033064 -0.0599781 0.0122916" rpy="0.979275 0.741971 0.40882"/>
            <geometry>
                <cylinder radius="0.039967" length="0.031882"/>
            </geometry>
        </collision>
        <collision>
            <origin xyz="0.0222919 -0.0502238 0.00573912" rpy="0 -0 0"/>
            <geometry>
                <sphere radius="0.039967"/>
            </geometry>
        </collision>
        <collision>
            <origin xyz="0.043836 -0.0697323 0.0188442" rpy="0 -0 0"/>
            <geometry>
                <sphere radius="0.039967"/>
            </geometry>
        </collision>
        <collision>
            <origin xyz="0.037243 -0.0571462 0.0096371" rpy="0.955949 0.968888 0.532323"/>
            <geometry>
                <cylinder radius="0.039500" length="0.032725"/>
            </geometry>
        </collision>
        <collision>
            <origin xyz="0.0237562 -0.0495782 0.00429294" rpy="0 -0 0"/>
            <geometry>
                <sphere radius="0.039500"/>
            </geometry>
        </collision>
        <collision>
            <origin xyz="0.0507298 -0.0647141 0.0149813" rpy="0 -0 0"/>
            <geometry>
                <sphere radius="0.039500"/>
            </geometry>
        </collision>
        <collision>
            <origin xyz="0.0304649 -0.0590306 0.0179748" rpy="0.709561 0.0602084 0.0223103"/>
            <geometry>
                <cylinder radius="0.044252" length="0.042517"/>
            </geometry>
        </collision>
        <collision>
            <origin xyz="0.0291857 -0.0452056 0.00187623" rpy="0 -0 0"/>
            <geometry>
                <sphere radius="0.044252"/>
            </geometry>
        </collision>
        <collision>
            <origin xyz="0.031744 -0.0728555 0.0340735" rpy="0 -0 0"/>
            <geometry>
                <sphere radius="0.044252"/>
            </geometry>
        </collision>
        <collision>
            <origin xyz="0.020972 -0.0631013 0.027521" rpy="0.979275 0.741971 0.40882"/>
            <geometry>
                <cylinder radius="0.035784" length="0.031882"/>
            </geometry>
        </collision>
        <collision>
            <origin xyz="0.0102 -0.0533471 0.0209684" rpy="0 -0 0"/>
            <geometry>
                <sphere radius="0.035784"/>
            </geometry>
        </collision>
        <collision>
            <origin xyz="0.031744 -0.0728555 0.0340735" rpy="0 -0 0"/>
            <geometry>
                <sphere radius="0.035784"/>
            </geometry>
        </collision>
        <collision>
            <origin xyz="0.047808 -0.0255736 0.0392683" rpy="0.979275 0.741971 0.40882"/>
            <geometry>
                <cylinder radius="0.057619" length="0.031882"/>
            </geometry>
        </collision>
        <collision>
            <origin xyz="0.0370359 -0.0158194 0.0327158" rpy="0 -0 0"/>
            <geometry>
                <sphere radius="0.057619"/>
            </geometry>
        </collision>
        <collision>
            <origin xyz="0.05858 -0.0353279 0.0458209" rpy="0 -0 0"/>
            <geometry>
                <sphere radius="0.057619"/>
            </geometry>
        </collision>
        <collision>
            <origin xyz="0.028247 -0.015317 0.086694" rpy="0.979275 0.741971 0.40882"/>
            <geometry>
                <cylinder radius="0.053021" length="0.031882"/>
            </geometry>
        </collision>
        <collision>
            <origin xyz="0.017475 -0.00556279 0.0801414" rpy="0 -0 0"/>
            <geometry>
                <sphere radius="0.053021"/>
            </geometry>
        </collision>
        <collision>
            <origin xyz="0.0390191 -0.0250713 0.0932465" rpy="0 -0 0"/>
            <geometry>
                <sphere radius="0.053021"/>
            </geometry>
        </collision>
        <collision>
            <origin xyz="-0.00891794 -0.0458526 0.102335" rpy="0.979275 0.741971 0.40882"/>
            <geometry>
                <cylinder radius="0.042213" length="0.031882"/>
            </geometry>
        </collision>
        <collision>
            <origin xyz="-0.01969 -0.0360984 0.095783" rpy="0 -0 0"/>
            <geometry>
                <sphere radius="0.042213"/>
            </geometry>
        </collision>
        <collision>
            <origin xyz="0.00185411 -0.0556068 0.108888" rpy="0 -0 0"/>
            <geometry>
                <sphere radius="0.042213"/>
            </geometry>
        </collision>
        <collision>
            <origin xyz="-0.00592377 -0.0381513 0.108878" rpy="0.979275 0.741971 0.40882"/>
            <geometry>
                <cylinder radius="0.048513" length="0.031882"/>
            </geometry>
        </collision>
        <collision>
            <origin xyz="-0.0166958 -0.0283971 0.102325" rpy="0 -0 0"/>
            <geometry>
                <sphere radius="0.048513"/>
            </geometry>
        </collision>
        <collision>
            <origin xyz="0.00484827 -0.0479056 0.11543" rpy="0 -0 0"/>
            <geometry>
                <sphere radius="0.048513"/>
            </geometry>
        </collision>
        <inertial>
            <origin xyz="-0.0459101 0.0630493 -0.00851879" rpy="0 -0 0"/>
            <mass value="2.615596"/>
            <inertia ixx="3.452998e-02" ixy="1.322552e-02" ixz="1.015143e-02" iyy="2.888162e-02" iyz="-9.762834e-04" izz="4.125471e-02"/>
        </inertial>
    </link>
    <joint name="fr3_joint4" type="revolute">
        <parent link="fr3_link3"/>
        <child link="fr3_link4"/>
        <origin xyz="0.0825 0 0" rpy="1.5708 -0 0"/>
        <axis xyz="0 0 1"/>
        <limit lower="-3.042100" upper="-0.151800" effort="87.000000" velocity="2.620000"/>
        <dynamics damping="0.003000" friction="0.200000"/>
    </joint>
    <link name="fr3_link5">
        <visual>
            <origin xyz="0 0 0" rpy="0 -0 0"/>
            <geometry>
                <mesh filename="/workspace/resources/fr3/meshes/fr3/visual/link5.dae"/>
            </geometry>
        </visual>
        <collision>
            <origin xyz="-0.0488335 -0.0151658 -0.248726" rpy="-0.312938 0.0111371 -0.00175699"/>
            <geometry>
                <cylinder radius="0.048972" length="0.042878"/>
            </geometry>
        </collision>
        <collision>
            <origin xyz="-0.0490723 -0.0217654 -0.269122" rpy="0 -0 0"/>
            <geometry>
                <sphere radius="0.048972"/>
            </geometry>
        </collision>
        <collision>
            <origin xyz="-0.0485948 -0.00856614 -0.228329" rpy="0 -0 0"/>
            <geometry>
                <sphere radius="0.048972"/>
            </geometry>
        </collision>
        <collision>
            <origin xyz="-0.0406474 0.0274035 -0.262596" rpy="-0.312938 0.0111371 -0.00175699"/>
            <geometry>
                <cylinder radius="0.077454" length="0.042878"/>
            </geometry>
        </collision>
        <collision>
            <origin xyz="-0.0408862 0.0208038 -0.282992" rpy="0 -0 0"/>
            <geometry>
                <sphere radius="0.077454"/>
            </geometry>
        </collision>
        <collision>
            <origin xyz="-0.0404086 0.0340031 -0.242199" rpy="0 -0 0"/>
            <geometry>
                <sphere radius="0.077454"/>
            </geometry>
        </collision>
        <collision>
            <origin xyz="-0.000575183 -0.00259368 -0.253359" rpy="-0.312938 0.0111371 -0.00175699"/>
            <geometry>
                <cylinder radius="0.077165" length="0.042878"/>
            </geometry>
        </collision>
        <collision>
            <origin xyz="-0.000813943 -0.00919332 -0.273755" rpy="0 -0 0"/>
            <geometry>
                <sphere radius="0.077165"/>
            </geometry>
        </collision>
        <collision>
            <origin xyz="-0.000336422 0.00400596 -0.232962" rpy="0 -0 0"/>
            <geometry>
                <sphere radius="0.077165"/>
            </geometry>
        </collision>
        <collision>
            <origin xyz="-0.0427825 -0.0391623 -0.241032" rpy="-0.312938 0.0111371 -0.00175699"/>
            <geometry>
                <cylinder radius="0.074811" length="0.042878"/>
            </geometry>
        </collision>
        <collision>
            <origin xyz="-0.0430213 -0.0457619 -0.261428" rpy="0 -0 0"/>
            <geometry>
                <sphere radius="0.074811"/>
            </geometry>
        </collision>
        <collision>
            <origin xyz="-0.0425438 -0.0325627 -0.220636" rpy="0 -0 0"/>
            <geometry>
                <sphere radius="0.074811"/>
            </geometry>
        </collision>
        <collision>
            <origin xyz="-0.0467124 0.00729864 -0.143347" rpy="0 -0 0"/>
            <geometry>
                <sphere radius="0.075738"/>
            </geometry>
        </collision>
        <collision>
            <origin xyz="-0.0406383 0.0605751 -0.160656" rpy="0 -0 0"/>
            <geometry>
                <sphere radius="0.077781"/>
            </geometry>
        </collision>
        <collision>
            <origin xyz="-3.54608e-05 0.0313691 -0.151682" rpy="0 -0 0"/>
            <geometry>
                <sphere radius="0.079139"/>
            </geometry>
        </collision>
        <collision>
            <origin xyz="-5.77357e-05 0.0489971 -0.067247" rpy="0 -0 0"/>
            <geometry>
                <sphere radius="0.080250"/>
            </geometry>
        </collision>
        <collision>
            <origin xyz="0.000498572 0.0753018 0.0369078" rpy="-0.312938 0.0111371 -0.00175699"/>
            <geometry>
                <cylinder radius="0.080231" length="0.042878"/>
            </geometry>
        </collision>
        <collision>
            <origin xyz="0.000259812 0.0687021 0.0165115" rpy="0 -0 0"/>
            <geometry>
                <sphere radius="0.080231"/>
            </geometry>
        </collision>
        <collision>
            <origin xyz="0.000737333 0.0819014 0.0573041" rpy="0 -0 0"/>
            <geometry>
                <sphere radius="0.080231"/>
            </geometry>
        </collision>
        <inertial>
            <origin xyz="-0.00160396 0.0292536 -0.0972966" rpy="0 -0 0"/>
            <mass value="2.327121"/>
            <inertia ixx="5.161028e-02" ixy="-5.715173e-03" ixz="-3.567317e-03" iyy="4.787730e-02" iyz="1.067399e-02" izz="1.642363e-02"/>
        </inertial>
    </link>
    <joint name="fr3_joint5" type="revolute">
        <parent link="fr3_link4"/>
        <child link="fr3_link5"/>
        <origin xyz="-0.0825 0.384 0" rpy="-1.5708 0 0"/>
        <axis xyz="0 0 1"/>
        <limit lower="-2.806500" upper="2.806500" effort="12.000000" velocity="5.260000"/>
        <dynamics damping="0.003000" friction="0.200000"/>
    </joint>
    <link name="fr3_link6">
        <visual>
            <origin xyz="0 0 0" rpy="0 -0 0"/>
            <geometry>
                <mesh filename="/workspace/resources/fr3/meshes/fr3/visual/link6.dae"/>
            </geometry>
        </visual>
        <collision>
            <origin xyz="-0.0338786 -0.0305716 0.00315088" rpy="2.55908 0.492705 1.39592"/>
            <geometry>
                <cylinder radius="0.058054" length="0.048193"/>
            </geometry>
        </collision>
        <collision>
            <origin xyz="-0.0452765 -0.0188923 0.0208799" rpy="0 -0 0"/>
            <geometry>
                <sphere radius="0.058054"/>
            </geometry>
        </collision>
        <collision>
            <origin xyz="-0.0224808 -0.0422509 -0.0145781" rpy="0 -0 0"/>
            <geometry>
                <sphere radius="0.058054"/>
            </geometry>
        </collision>
        <collision>
            <origin xyz="-0.0337422 -0.0443115 -0.012911" rpy="-2.251 1.33964 -2.05688"/>
            <geometry>
                <cylinder radius="0.052145" length="0.023138"/>
            </geometry>
        </collision>
        <collision>
            <origin xyz="-0.0450035 -0.0463722 -0.011244" rpy="0 -0 0"/>
            <geometry>
                <sphere radius="0.052145"/>
            </geometry>
        </collision>
        <collision>
            <origin xyz="-0.0224808 -0.0422509 -0.0145781" rpy="0 -0 0"/>
            <geometry>
                <sphere radius="0.052145"/>
            </geometry>
        </collision>
        <collision>
            <origin xyz="-0.0350457 -0.0389489 -0.0150883" rpy="-2.251 1.33964 -2.05688"/>
            <geometry>
                <cylinder radius="0.050656" length="0.023138"/>
            </geometry>
        </collision>
        <collision>
            <origin xyz="-0.0463071 -0.0410095 -0.0134213" rpy="0 -0 0"/>
            <geometry>
                <sphere radius="0.050656"/>
            </geometry>
        </collision>
        <collision>
            <origin xyz="-0.0237843 -0.0368883 -0.0167554" rpy="0 -0 0"/>
            <geometry>
                <sphere radius="0.050656"/>
            </geometry>
        </collision>
        <collision>
            <origin xyz="-0.0365989 -0.0315846 -0.0164777" rpy="-2.251 1.33964 -2.05688"/>
            <geometry>
                <cylinder radius="0.044632" length="0.023138"/>
            </geometry>
        </collision>
        <collision>
            <origin xyz="-0.0478603 -0.0336453 -0.0148107" rpy="0 -0 0"/>
            <geometry>
                <sphere radius="0.044632"/>
            </geometry>
        </collision>
        <collision>
            <origin xyz="-0.0253376 -0.029524 -0.0181448" rpy="0 -0 0"/>
            <geometry>
                <sphere radius="0.044632"/>
            </geometry>
        </collision>
        <collision>
            <origin xyz="-0.0380645 0.000151843 0.0128508" rpy="-2.251 1.33964 -2.05688"/>
            <geometry>
                <cylinder radius="0.085244" length="0.023138"/>
            </geometry>
        </collision>
        <collision>
            <origin xyz="-0.0493259 -0.00190879 0.0145179" rpy="0 -0 0"/>
            <geometry>
                <sphere radius="0.085244"/>
            </geometry>
        </collision>
        <collision>
            <origin xyz="-0.0268032 0.00221248 0.0111838" rpy="0 -0 0"/>
            <geometry>
                <sphere radius="0.085244"/>
            </geometry>
        </collision>
        <collision>
            <origin xyz="0.0568653 0.0753674 0.0245096" rpy="0 -0 0"/>
            <geometry>
                <sphere radius="0.066543"/>
            </geometry>
        </collision>
        <collision>
            <origin xyz="0.128723 -0.0124011 -4.67429e-06" rpy="-2.251 1.33964 -2.05688"/>
            <geometry>
                <cylinder radius="0.080199" length="0.023138"/>
            </geometry>
        </collision>
        <collision>
            <origin xyz="0.117461 -0.0144618 0.00166239" rpy="0 -0 0"/>
            <geometry>
                <sphere radius="0.080199"/>
            </geometry>
        </collision>
        <collision>
            <origin xyz="0.139984 -0.0103405 -0.00167173" rpy="0 -0 0"/>
            <geometry>
                <sphere radius="0.080199"/>
            </geometry>
        </collision>
        <collision>
            <origin xyz="0.118129 0.0407345 -0.00588469" rpy="-2.251 1.33964 -2.05688"/>
            <geometry>
                <cylinder radius="0.057319" length="0.023138"/>
            </geometry>
        </collision>
        <collision>
            <origin xyz="0.106868 0.0386739 -0.00421763" rpy="0 -0 0"/>
            <geometry>
                <sphere radius="0.057319"/>
            </geometry>
        </collision>
        <collision>
            <origin xyz="0.129391 0.0427952 -0.00755175" rpy="0 -0 0"/>
            <geometry>
                <sphere radius="0.057319"/>
            </geometry>
        </collision>
        <collision>
            <origin xyz="0.129593 -0.0437909 -0.032926" rpy="-2.251 1.33964 -2.05688"/>
            <geometry>
                <cylinder radius="0.045305" length="0.023138"/>
            </geometry>
        </collision>
        <collision>
            <origin xyz="0.118331 -0.0458515 -0.0312589" rpy="0 -0 0"/>
            <geometry>
                <sphere radius="0.045305"/>
            </geometry>
        </collision>
        <collision>
            <origin xyz="0.140854 -0.0417302 -0.034593" rpy="0 -0 0"/>
            <geometry>
                <sphere radius="0.045305"/>
            </geometry>
        </collision>
        <collision>
            <origin xyz="0.127954 -0.0359955 -0.0343628" rpy="-2.251 1.33964 -2.05688"/>
            <geometry>
                <cylinder radius="0.064468" length="0.023138"/>
            </geometry>
        </collision>
        <collision>
            <origin xyz="0.116692 -0.0380562 -0.0326957" rpy="0 -0 0"/>
            <geometry>
                <sphere radius="0.064468"/>
            </geometry>
        </collision>
        <collision>
            <origin xyz="0.139215 -0.0339349 -0.0360298" rpy="0 -0 0"/>
            <geometry>
                <sphere radius="0.064468"/>
            </geometry>
        </collision>
        <collision>
            <origin xyz="0.125072 -0.0222541 -0.0368445" rpy="-2.251 1.33964 -2.05688"/>
            <geometry>
                <cylinder radius="0.048947" length="0.023138"/>
            </geometry>
        </collision>
        <collision>
            <origin xyz="0.113811 -0.0243147 -0.0351774" rpy="0 -0 0"/>
            <geometry>
                <sphere radius="0.048947"/>
            </geometry>
        </collision>
        <collision>
            <origin xyz="0.136333 -0.0201935 -0.0385115" rpy="0 -0 0"/>
            <geometry>
                <sphere radius="0.048947"/>
            </geometry>
        </collision>
        <collision>
            <origin xyz="0.118967 0.00860007 -0.0399447" rpy="-2.251 1.33964 -2.05688"/>
            <geometry>
                <cylinder radius="0.050966" length="0.023138"/>
            </geometry>
        </collision>
        <collision>
            <origin xyz="0.107706 0.00653944 -0.0382776" rpy="0 -0 0"/>
            <geometry>
                <sphere radius="0.050966"/>
            </geometry>
        </collision>
        <collision>
            <origin xyz="0.130229 0.0106607 -0.0416117" rpy="0 -0 0"/>
            <geometry>
                <sphere radius="0.050966"/>
            </geometry>
        </collision>
        <inertial>
            <origin xyz="0.0597131 -0.0410295 -0.0101693" rpy="0 -0 0"/>
            <mass value="1.817038"/>
            <inertia ixx="5.412334e-03" ixy="6.193456e-03" ixz="1.421929e-03" iyy="1.405833e-02" iyz="-1.314075e-03" izz="1.608082e-02"/>
        </inertial>
    </link>
    <joint name="fr3_joint6" type="revolute">
        <parent link="fr3_link5"/>
        <child link="fr3_link6"/>
        <origin xyz="0 0 0" rpy="1.5708 -0 0"/>
        <axis xyz="0 0 1"/>
        <limit lower="0.544500" upper="4.516900" effort="12.000000" velocity="4.180000"/>
        <dynamics damping="0.003000" friction="0.200000"/>
    </joint>
    <link name="fr3_link7">
        <visual>
            <origin xyz="0 0 0" rpy="0 -0 0"/>
            <geometry>
                <mesh filename="/workspace/resources/fr3/meshes/fr3/visual/link7.dae"/>
            </geometry>
        </visual>
        <collision>
            <origin xyz="-0.0310613 -0.031819 0.0724812" rpy="-1.50913 0.779252 -0.736842"/>
            <geometry>
                <cylinder radius="0.063004" length="0.017732"/>
            </geometry>
        </collision>
        <collision>
            <origin xyz="-0.0372918 -0.0381145 0.0720925" rpy="0 -0 0"/>
            <geometry>
                <sphere radius="0.063004"/>
            </geometry>
        </collision>
        <collision>
            <origin xyz="-0.0248308 -0.0255234 0.0728699" rpy="0 -0 0"/>
            <geometry>
                <sphere radius="0.063004"/>
            </geometry>
        </collision>
        <collision>
            <origin xyz="-0.0446558 -0.0180421 0.067251" rpy="-0.0377226 0.759457 -0.0150565"/>
            <geometry>
                <cylinder radius="0.055593" length="0.033140"/>
            </geometry>
        </collision>
        <collision>
            <origin xyz="-0.0560648 -0.0184953 0.0552427" rpy="0 -0 0"/>
            <geometry>
                <sphere radius="0.055593"/>
            </geometry>
        </collision>
        <collision>
            <origin xyz="-0.0332468 -0.0175889 0.0792593" rpy="0 -0 0"/>
            <geometry>
                <sphere radius="0.055593"/>
            </geometry>
        </collision>
        <collision>
            <origin xyz="-0.049841 -0.012225 0.0561484" rpy="-1.50913 0.779252 -0.736842"/>
            <geometry>
                <cylinder radius="0.048162" length="0.017732"/>
            </geometry>
        </collision>
        <collision>
            <origin xyz="-0.0560715 -0.0185206 0.0557598" rpy="0 -0 0"/>
            <geometry>
                <sphere radius="0.048162"/>
            </geometry>
        </collision>
        <collision>
            <origin xyz="-0.0436105 -0.00592945 0.0565371" rpy="0 -0 0"/>
            <geometry>
                <sphere radius="0.048162"/>
            </geometry>
        </collision>
        <collision>
            <origin xyz="0.0477945 0.0651525 0.0690354" rpy="-1.50913 0.779252 -0.736842"/>
            <geometry>
                <cylinder radius="0.029802" length="0.017732"/>
            </geometry>
        </collision>
        <collision>
            <origin xyz="0.041564 0.0588569 0.0686467" rpy="0 -0 0"/>
            <geometry>
                <sphere radius="0.029802"/>
            </geometry>
        </collision>
        <collision>
            <origin xyz="0.054025 0.071448 0.0694241" rpy="0 -0 0"/>
            <geometry>
                <sphere radius="0.029802"/>
            </geometry>
        </collision>
        <collision>
            <origin xyz="0.0695348 0.0425929 0.0859446" rpy="-1.50913 0.779252 -0.736842"/>
            <geometry>
                <cylinder radius="0.054015" length="0.017732"/>
            </geometry>
        </collision>
        <collision>
            <origin xyz="0.0633043 0.0362973 0.0855559" rpy="0 -0 0"/>
            <geometry>
                <sphere radius="0.054015"/>
            </geometry>
        </collision>
        <collision>
            <origin xyz="0.0757653 0.0488885 0.0863333" rpy="0 -0 0"/>
            <geometry>
                <sphere radius="0.054015"/>
            </geometry>
        </collision>
        <collision>
            <origin xyz="0.0615818 0.0515073 0.0690401" rpy="-1.50913 0.779252 -0.736842"/>
            <geometry>
                <cylinder radius="0.066285" length="0.017732"/>
            </geometry>
        </collision>
        <collision>
            <origin xyz="0.0553513 0.0452118 0.0686514" rpy="0 -0 0"/>
            <geometry>
                <sphere radius="0.066285"/>
            </geometry>
        </collision>
        <collision>
            <origin xyz="0.0678123 0.0578029 0.0694288" rpy="0 -0 0"/>
            <geometry>
                <sphere radius="0.066285"/>
            </geometry>
        </collision>
        <collision>
            <origin xyz="0.0496233 0.0633549 0.068836" rpy="-1.50913 0.779252 -0.736842"/>
            <geometry>
                <cylinder radius="0.028542" length="0.017732"/>
            </geometry>
        </collision>
        <collision>
            <origin xyz="0.0433928 0.0570593 0.0684473" rpy="0 -0 0"/>
            <geometry>
                <sphere radius="0.028542"/>
            </geometry>
        </collision>
        <collision>
            <origin xyz="0.0558538 0.0696505 0.0692246" rpy="0 -0 0"/>
            <geometry>
                <sphere radius="0.028542"/>
            </geometry>
        </collision>
        <collision>
            <origin xyz="0.0392078 0.0735635 0.0704423" rpy="-1.50913 0.779252 -0.736842"/>
            <geometry>
                <cylinder radius="0.046542" length="0.017732"/>
            </geometry>
        </collision>
        <collision>
            <origin xyz="0.0329773 0.0672679 0.0700536" rpy="0 -0 0"/>
            <geometry>
                <sphere radius="0.046542"/>
            </geometry>
        </collision>
        <collision>
            <origin xyz="0.0454383 0.0798591 0.070831" rpy="0 -0 0"/>
            <geometry>
                <sphere radius="0.046542"/>
            </geometry>
        </collision>
        <collision>
            <origin xyz="0.0396029 0.0725023 0.0812982" rpy="0.124417 1.10988 0.0771903"/>
            <geometry>
                <cylinder radius="0.055668" length="0.029089"/>
            </geometry>
        </collision>
        <collision>
            <origin xyz="0.0265761 0.0733051 0.0748792" rpy="0 -0 0"/>
            <geometry>
                <sphere radius="0.055668"/>
            </geometry>
        </collision>
        <collision>
            <origin xyz="0.0526297 0.0716995 0.0877172" rpy="0 -0 0"/>
            <geometry>
                <sphere radius="0.055668"/>
            </geometry>
        </collision>
        <collision>
            <origin xyz="0.0463992 0.0654039 0.0873285" rpy="-1.50913 0.779252 -0.736842"/>
            <geometry>
                <cylinder radius="0.053361" length="0.017732"/>
            </geometry>
        </collision>
        <collision>
            <origin xyz="0.0401687 0.0591083 0.0869398" rpy="0 -0 0"/>
            <geometry>
                <sphere radius="0.053361"/>
            </geometry>
        </collision>
        <collision>
            <origin xyz="0.0526297 0.0716995 0.0877172" rpy="0 -0 0"/>
            <geometry>
                <sphere radius="0.053361"/>
            </geometry>
        </collision>
        <collision>
            <origin xyz="0.0442765 0.0686102 0.0694222" rpy="-1.50913 0.779252 -0.736842"/>
            <geometry>
                <cylinder radius="0.035978" length="0.017732"/>
            </geometry>
        </collision>
        <collision>
            <origin xyz="0.038046 0.0623147 0.0690335" rpy="0 -0 0"/>
            <geometry>
                <sphere radius="0.035978"/>
            </geometry>
        </collision>
        <collision>
            <origin xyz="0.050507 0.0749058 0.0698109" rpy="0 -0 0"/>
            <geometry>
                <sphere radius="0.035978"/>
            </geometry>
        </collision>
        <collision>
            <origin xyz="0.0327221 0.0796695 0.0755051" rpy="-1.50913 0.779252 -0.736842"/>
            <geometry>
                <cylinder radius="0.042188" length="0.017732"/>
            </geometry>
        </collision>
        <collision>
            <origin xyz="0.0264916 0.073374 0.0751164" rpy="0 -0 0"/>
            <geometry>
                <sphere radius="0.042188"/>
            </geometry>
        </collision>
        <collision>
            <origin xyz="0.0389526 0.0859651 0.0758938" rpy="0 -0 0"/>
            <geometry>
                <sphere radius="0.042188"/>
            </geometry>
        </collision>
        <inertial>
            <origin xyz="0.00452258 0.00862619 -0.0161633" rpy="0 -0 0"/>
            <mass value="0.627143"/>
            <inertia ixx="2.109239e-04" ixy="-2.433299e-05" ixz="4.564480e-05" iyy="1.771857e-04" iyz="8.744070e-05" izz="5.993191e-05"/>
        </inertial>
    </link>
    <joint name="fr3_joint7" type="revolute">
        <parent link="fr3_link6"/>
        <child link="fr3_link7"/>
        <origin xyz="0.088 0 0" rpy="1.5708 -0 0"/>
        <axis xyz="0 0 1"/>
        <limit lower="-3.015900" upper="3.015900" effort="12.000000" velocity="5.260000"/>
        <dynamics damping="0.003000" friction="0.200000"/>
    </joint>
    <link name="fr3_link8"/>
    <joint name="fr3_joint8" type="fixed">
        <parent link="fr3_link7"/>
        <child link="fr3_link8"/>
        <origin xyz="0 0 0.107" rpy="0 -0 0"/>
    </joint>
    <link name="world"/>
    <joint name="fr3_joint_world" type="fixed">
        <parent link="world"/>
        <child link="fr3_link0"/>
        <origin xyz="0 0 0" rpy="0 -0 0"/>
    </joint>
    <link name="hand_hand">
        <visual>
            <origin xyz="0 0 0" rpy="0 -0 0"/>
            <geometry>
                <mesh filename="/workspace/resources/fr3/meshes/franka_hand/visual/hand.dae"/>
            </geometry>
        </visual>
        <collision>
            <origin xyz="-0.000132353 0.0886051 0.0271761" rpy="1.60657 -0.00456078 -0.00472692"/>
            <geometry>
                <cylinder radius="0.049585" length="0.025802"/>
            </geometry>
        </collision>
        <collision>
            <origin xyz="-7.35146e-05 0.101498 0.0276375" rpy="0 -0 0"/>
            <geometry>
                <sphere radius="0.049585"/>
            </geometry>
        </collision>
        <collision>
            <origin xyz="-0.000191192 0.0757124 0.0267147" rpy="0 -0 0"/>
            <geometry>
                <sphere radius="0.049585"/>
            </geometry>
        </collision>
        <collision>
            <origin xyz="4.95844e-05 0.0241244 0.0252877" rpy="0 -0 0"/>
            <geometry>
                <sphere radius="0.051180"/>
            </geometry>
        </collision>
        <collision>
            <origin xyz="-0.000278964 -0.0274072 0.0223586" rpy="0 -0 0"/>
            <geometry>
                <sphere radius="0.053966"/>
            </geometry>
        </collision>
        <collision>
            <origin xyz="-0.000252765 -0.0918874 0.0204739" rpy="1.60657 -0.00456078 -0.00472692"/>
            <geometry>
                <cylinder radius="0.054138" length="0.025802"/>
            </geometry>
        </collision>
        <collision>
            <origin xyz="-0.000193926 -0.0789947 0.0209353" rpy="0 -0 0"/>
            <geometry>
                <sphere radius="0.054138"/>
            </geometry>
        </collision>
        <collision>
            <origin xyz="-0.000311604 -0.10478 0.0200125" rpy="0 -0 0"/>
            <geometry>
                <sphere radius="0.054138"/>
            </geometry>
        </collision>
        <inertial>
            <origin xyz="-3.76e-05 0.0119128 0.020726" rpy="0 -0 0"/>
            <mass value="0.654400"/>
            <inertia ixx="1.860000e-03" ixy="0.000000e+00" ixz="0.000000e+00" iyy="3.000000e-04" iyz="-2.000000e-05" izz="1.740000e-03"/>
        </inertial>
    </link>
    <link name="hand_leftfinger">
        <visual>
            <origin xyz="-0.0165 0.0165 0.127733" rpy="-1.5708 0.202458 -1.5708"/>
            <geometry>
                <mesh filename="/workspace/resources/fr3/meshes/plate/collision/flex_griper_connect.stl"/>
            </geometry>
        </visual>
        <collision>
            <origin xyz="1.3236e-06 0.00402772 0.116914" rpy="-3.00775 -0.000154903 0.00231129"/>
            <geometry>
                <cylinder radius="0.019820" length="0.016093"/>
            </geometry>
        </collision>
        <collision>
            <origin xyz="2.57004e-06 0.00295398 0.124888" rpy="0 -0 0"/>
            <geometry>
                <sphere radius="0.019820"/>
            </geometry>
        </collision>
        <collision>
            <origin xyz="7.71663e-08 0.00510146 0.108939" rpy="0 -0 0"/>
            <geometry>
                <sphere radius="0.019820"/>
            </geometry>
        </collision>
        <collision>
            <origin xyz="1.70846e-07 0.0116568 0.0773448" rpy="0 -0 0"/>
            <geometry>
                <sphere radius="0.022545"/>
            </geometry>
        </collision>
        <collision>
            <origin xyz="-8.90195e-11 0.0180211 0.045725" rpy="0 -0 0"/>
            <geometry>
                <sphere radius="0.028132"/>
            </geometry>
        </collision>
        <collision>
            <origin xyz="-6.76516e-07 0.0232472 0.00583271" rpy="-3.00775 -0.000154903 0.00231129"/>
            <geometry>
                <cylinder radius="0.027863" length="0.016093"/>
            </geometry>
        </collision>
        <collision>
            <origin xyz="5.6992e-07 0.0221735 0.0138073" rpy="0 -0 0"/>
            <geometry>
                <sphere radius="0.027863"/>
            </geometry>
        </collision>
        <collision>
            <origin xyz="-1.92295e-06 0.024321 -0.00214191" rpy="0 -0 0"/>
            <geometry>
                <sphere radius="0.027863"/>
            </geometry>
        </collision>
        <collision>
            <origin xyz="-2.4512e-07 0.0109671 0.00417924" rpy="-3.00775 -0.000154903 0.00231129"/>
            <geometry>
                <cylinder radius="0.025168" length="0.016093"/>
            </geometry>
        </collision>
        <collision>
            <origin xyz="1.00132e-06 0.00989331 0.0121539" rpy="0 -0 0"/>
            <geometry>
                <sphere radius="0.025168"/>
            </geometry>
        </collision>
        <collision>
            <origin xyz="-1.49156e-06 0.0120408 -0.00379537" rpy="0 -0 0"/>
            <geometry>
                <sphere radius="0.025168"/>
            </geometry>
        </collision>
        <inertial>
            <origin xyz="0 0.0145644 0.0227941" rpy="0 -0 0"/>
            <mass value="0.100000"/>
            <inertia ixx="3.012209e-05" ixy="0.000000e+00" ixz="0.000000e+00" iyy="2.958738e-05" iyz="0.000000e+00" izz="6.951252e-06"/>
        </inertial>
    </link>
    <joint name="hand_finger_joint1" type="prismatic">
        <parent link="hand_hand"/>
        <child link="hand_leftfinger"/>
        <origin xyz="0 0 0.0584" rpy="0 -0 0"/>
        <axis xyz="0 1 0"/>
        <limit lower="0.000000" upper="0.040000" effort="100.000000" velocity="0.200000"/>
        <dynamics damping="0.300000" friction="0.000000"/>
    </joint>
    <link name="hand_rightfinger">
        <visual>
            <origin xyz="-0.0165 0.0165 0.127733" rpy="-1.5708 0.202458 -1.5708"/>
            <geometry>
                <mesh filename="/workspace/resources/fr3/meshes/plate/collision/flex_griper_connect.stl"/>
            </geometry>
        </visual>
        <collision>
            <origin xyz="1.3236e-06 0.00402772 0.116914" rpy="-3.00775 -0.000154903 0.00231129"/>
            <geometry>
                <cylinder radius="0.019820" length="0.016093"/>
            </geometry>
        </collision>
        <collision>
            <origin xyz="2.57004e-06 0.00295398 0.124888" rpy="0 -0 0"/>
            <geometry>
                <sphere radius="0.019820"/>
            </geometry>
        </collision>
        <collision>
            <origin xyz="7.71663e-08 0.00510146 0.108939" rpy="0 -0 0"/>
            <geometry>
                <sphere radius="0.019820"/>
            </geometry>
        </collision>
        <collision>
            <origin xyz="1.70846e-07 0.0116568 0.0773448" rpy="0 -0 0"/>
            <geometry>
                <sphere radius="0.022545"/>
            </geometry>
        </collision>
        <collision>
            <origin xyz="-8.90195e-11 0.0180211 0.045725" rpy="0 -0 0"/>
            <geometry>
                <sphere radius="0.028132"/>
            </geometry>
        </collision>
        <collision>
            <origin xyz="-6.76516e-07 0.0232472 0.00583271" rpy="-3.00775 -0.000154903 0.00231129"/>
            <geometry>
                <cylinder radius="0.027863" length="0.016093"/>
            </geometry>
        </collision>
        <collision>
            <origin xyz="5.6992e-07 0.0221735 0.0138073" rpy="0 -0 0"/>
            <geometry>
                <sphere radius="0.027863"/>
            </geometry>
        </collision>
        <collision>
            <origin xyz="-1.92295e-06 0.024321 -0.00214191" rpy="0 -0 0"/>
            <geometry>
                <sphere radius="0.027863"/>
            </geometry>
        </collision>
        <collision>
            <origin xyz="-2.4512e-07 0.0109671 0.00417924" rpy="-3.00775 -0.000154903 0.00231129"/>
            <geometry>
                <cylinder radius="0.025168" length="0.016093"/>
            </geometry>
        </collision>
        <collision>
            <origin xyz="1.00132e-06 0.00989331 0.0121539" rpy="0 -0 0"/>
            <geometry>
                <sphere radius="0.025168"/>
            </geometry>
        </collision>
        <collision>
            <origin xyz="-1.49156e-06 0.0120408 -0.00379537" rpy="0 -0 0"/>
            <geometry>
                <sphere radius="0.025168"/>
            </geometry>
        </collision>
        <inertial>
            <origin xyz="0 0.0145644 0.0227941" rpy="0 -0 3.14159"/>
            <mass value="0.100000"/>
            <inertia ixx="3.012209e-05" ixy="0.000000e+00" ixz="0.000000e+00" iyy="2.958738e-05" iyz="0.000000e+00" izz="6.951252e-06"/>
        </inertial>
    </link>
    <joint name="hand_finger_joint2" type="prismatic">
        <parent link="hand_hand"/>
        <child link="hand_rightfinger"/>
        <origin xyz="0 0 0.0584" rpy="0 -0 3.14159"/>
        <axis xyz="0 1 0"/>
        <limit lower="0.000000" upper="0.040000" effort="100.000000" velocity="0.200000"/>
        <dynamics damping="0.300000" friction="0.000000"/>
    </joint>
    <link name="hand_hand_tcp"/>
    <joint name="hand_hand_tcp_joint" type="fixed">
        <parent link="hand_hand"/>
        <child link="hand_hand_tcp"/>
        <origin xyz="0 0 0.1034" rpy="0 -0 0"/>
    </joint>
    <joint name="hand_joint_fr3_link8" type="fixed">
        <parent link="fr3_link8"/>
        <child link="hand_hand"/>
        <origin xyz="0 0 0" rpy="0 0 -0.785398"/>
    </joint>
</robot>
