<?xml version="1.0" encoding="utf-8"?>
<robot name="bot">
    <link name="fr3_link0">
        <visual>
            <origin xyz="0 0 0" rpy="0 -0 0"/>
            <geometry>
                <mesh filename="/workspace/resources/fr3/meshes/fr3/visual/link0.dae"/>
            </geometry>
        </visual>
        <collision>
            <origin xyz="-0.135973 -9.10807e-05 0.00138814" rpy="-0.00519164 1.19845 -0.00354589"/>
            <geometry>
                <cylinder radius="0.072194" length="0.035936"/>
            </geometry>
        </collision>
        <collision>
            <origin xyz="-0.152709 -0.000125017 -0.00514852" rpy="0 -0 0"/>
            <geometry>
                <sphere radius="0.072194"/>
            </geometry>
        </collision>
        <collision>
            <origin xyz="-0.119236 -5.71444e-05 0.0079248" rpy="0 -0 0"/>
            <geometry>
                <sphere radius="0.072194"/>
            </geometry>
        </collision>
        <collision>
            <origin xyz="-0.0243949 0.000135161 0.0449659" rpy="-0.00519164 1.19845 -0.00354589"/>
            <geometry>
                <cylinder radius="0.107683" length="0.203636"/>
            </geometry>
        </collision>
        <collision>
            <origin xyz="-0.119236 -5.71444e-05 0.0079248" rpy="0 -0 0"/>
            <geometry>
                <sphere radius="0.107683"/>
            </geometry>
        </collision>
        <collision>
            <origin xyz="0.0704462 0.000327466 0.0820069" rpy="0 -0 0"/>
            <geometry>
                <sphere radius="0.107683"/>
            </geometry>
        </collision>
        <inertial>
            <origin xyz="-0.0172 0.0004 0.0745" rpy="0 -0 0"/>
            <mass value="2.396600"/>
            <inertia ixx="9.000000e-03" ixy="0.000000e+00" ixz="2.000000e-03" iyy="1.150000e-02" iyz="0.000000e+00" izz="8.500000e-03"/>
        </inertial>
    </link>
    <link name="fr3_link1">
        <visual>
            <origin xyz="0 0 0" rpy="0 -0 0"/>
            <geometry>
                <mesh filename="/workspace/resources/fr3/meshes/fr3/visual/link1.dae"/>
            </geometry>
        </visual>
        <collision>
            <origin xyz="-5.53767e-05 -0.047399 -0.0435028" rpy="-2.74777 -0.00498923 0.0250077"/>
            <geometry>
                <cylinder radius="0.085190" length="0.212749"/>
            </geometry>
        </collision>
        <collision>
            <origin xyz="0.000475347 -0.0882169 0.0547271" rpy="0 -0 0"/>
            <geometry>
                <sphere radius="0.085190"/>
            </geometry>
        </collision>
        <collision>
            <origin xyz="-0.0005861 -0.00658111 -0.141733" rpy="0 -0 0"/>
            <geometry>
                <sphere radius="0.085190"/>
            </geometry>
        </collision>
        <collision>
            <origin xyz="-0.00020767 0.00367713 -0.175955" rpy="-2.85036 0.0105919 -0.0721939"/>
            <geometry>
                <cylinder radius="0.064088" length="0.071458"/>
            </geometry>
        </collision>
        <collision>
            <origin xyz="-0.0005861 -0.00658111 -0.141733" rpy="0 -0 0"/>
            <geometry>
                <sphere radius="0.064088"/>
            </geometry>
        </collision>
        <collision>
            <origin xyz="0.00017076 0.0139354 -0.210178" rpy="0 -0 0"/>
            <geometry>
                <sphere radius="0.064088"/>
            </geometry>
        </collision>
        <inertial>
            <origin xyz="4.128e-07 -0.0181251 -0.0386036" rpy="0 -0 0"/>
            <mass value="2.927465"/>
            <inertia ixx="2.392732e-02" ixy="1.331790e-05" ixz="-1.140477e-04" iyy="2.248216e-02" iyz="-1.995032e-03" izz="6.350098e-03"/>
        </inertial>
    </link>
    <joint name="fr3_joint1" type="revolute">
        <parent link="fr3_link0"/>
        <child link="fr3_link1"/>
        <origin xyz="0 0 0.333" rpy="0 -0 0"/>
        <axis xyz="0 0 1"/>
        <limit lower="-2.743700" upper="2.743700" effort="87.000000" velocity="2.620000"/>
        <dynamics damping="0.003000" friction="0.200000"/>
    </joint>
    <link name="fr3_link2">
        <visual>
            <origin xyz="0 0 0" rpy="0 -0 0"/>
            <geometry>
                <mesh filename="/workspace/resources/fr3/meshes/fr3/visual/link2.dae"/>
            </geometry>
        </visual>
        <collision>
            <origin xyz="9.4695e-06 -0.078382 0.0367072" rpy="1.92995 -0.00492845 -0.00711468"/>
            <geometry>
                <cylinder radius="0.085889" length="0.285214"/>
            </geometry>
        </collision>
        <collision>
            <origin xyz="0.000712299 0.0551243 0.0868309" rpy="0 -0 0"/>
            <geometry>
                <sphere radius="0.085889"/>
            </geometry>
        </collision>
        <collision>
            <origin xyz="-0.00069336 -0.211888 -0.0134166" rpy="0 -0 0"/>
            <geometry>
                <sphere radius="0.085889"/>
            </geometry>
        </collision>
        <inertial>
            <origin xyz="0.00318289 -0.0743222 0.00881461" rpy="0 -0 0"/>
            <mass value="2.935537"/>
            <inertia ixx="4.193895e-02" ixy="2.025733e-04" ixz="4.077784e-03" iyy="2.514515e-02" iyz="-4.225216e-03" izz="6.170214e-02"/>
        </inertial>
    </link>
    <joint name="fr3_joint2" type="revolute">
        <parent link="fr3_link1"/>
        <child link="fr3_link2"/>
        <origin xyz="0 0 0" rpy="-1.5708 0 0"/>
        <axis xyz="0 0 1"/>
        <limit lower="-1.783700" upper="1.783700" effort="87.000000" velocity="2.620000"/>
        <dynamics damping="0.003000" friction="0.200000"/>
    </joint>
    <link name="fr3_link3">
        <visual>
            <origin xyz="0 0 0" rpy="0 -0 0"/>
            <geometry>
                <mesh filename="/workspace/resources/fr3/meshes/fr3/visual/link3.dae"/>
            </geometry>
        </visual>
        <collision>
            <origin xyz="0.0416609 0.0261287 -0.0492319" rpy="-0.530784 0.692968 -0.195642"/>
            <geometry>
                <cylinder radius="0.079442" length="0.254222"/>
            </geometry>
        </collision>
        <collision>
            <origin xyz="-0.0395406 -0.0233752 -0.13357" rpy="0 -0 0"/>
            <geometry>
                <sphere radius="0.079442"/>
            </geometry>
        </collision>
        <collision>
            <origin xyz="0.122862 0.0756326 0.0351062" rpy="0 -0 0"/>
            <geometry>
                <sphere radius="0.079442"/>
            </geometry>
        </collision>
        <inertial>
            <origin xyz="0.0407016 -0.00482006 -0.0289731" rpy="0 -0 0"/>
            <mass value="2.244901"/>
            <inertia ixx="2.410143e-02" ixy="2.404695e-03" ixz="-2.856269e-03" iyy="1.974053e-02" iyz="-2.104213e-03" izz="1.904449e-02"/>
        </inertial>
    </link>
    <joint name="fr3_joint3" type="revolute">
        <parent link="fr3_link2"/>
        <child link="fr3_link3"/>
        <origin xyz="0 -0.316 0" rpy="1.5708 -0 0"/>
        <axis xyz="0 0 1"/>
        <limit lower="-2.900700" upper="2.900700" effort="87.000000" velocity="2.620000"/>
        <dynamics damping="0.003000" friction="0.200000"/>
    </joint>
    <link name="fr3_link4">
        <visual>
            <origin xyz="0 0 0" rpy="0 -0 0"/>
            <geometry>
                <mesh filename="/workspace/resources/fr3/meshes/fr3/visual/link4.dae"/>
            </geometry>
        </visual>
        <collision>
            <origin xyz="-0.0404645 0.0504779 0.0261248" rpy="1.05149 0.678404 0.403863"/>
            <geometry>
                <cylinder radius="0.079450" length="0.255957"/>
            </geometry>
        </collision>
        <collision>
            <origin xyz="-0.120777 0.136982 -0.0233252" rpy="0 -0 0"/>
            <geometry>
                <sphere radius="0.079450"/>
            </geometry>
        </collision>
        <collision>
            <origin xyz="0.0398485 -0.0360265 0.0755747" rpy="0 -0 0"/>
            <geometry>
                <sphere radius="0.079450"/>
            </geometry>
        </collision>
        <inertial>
            <origin xyz="-0.0459101 0.0630493 -0.00851879" rpy="0 -0 0"/>
            <mass value="2.615596"/>
            <inertia ixx="3.452998e-02" ixy="1.322552e-02" ixz="1.015143e-02" iyy="2.888162e-02" iyz="-9.762834e-04" izz="4.125471e-02"/>
        </inertial>
    </link>
    <joint name="fr3_joint4" type="revolute">
        <parent link="fr3_link3"/>
        <child link="fr3_link4"/>
        <origin xyz="0.0825 0 0" rpy="1.5708 -0 0"/>
        <axis xyz="0 0 1"/>
        <limit lower="-3.042100" upper="-0.151800" effort="87.000000" velocity="2.620000"/>
        <dynamics damping="0.003000" friction="0.200000"/>
    </joint>
    <link name="fr3_link5">
        <visual>
            <origin xyz="0 0 0" rpy="0 -0 0"/>
            <geometry>
                <mesh filename="/workspace/resources/fr3/meshes/fr3/visual/link5.dae"/>
            </geometry>
        </visual>
        <collision>
            <origin xyz="3.7905e-05 0.0369624 -0.108423" rpy="-0.270337 0.00257315 -0.000349943"/>
            <geometry>
                <cylinder radius="0.072580" length="0.343345"/>
            </geometry>
        </collision>
        <collision>
            <origin xyz="-0.000403833 -0.00888354 -0.27386" rpy="0 -0 0"/>
            <geometry>
                <sphere radius="0.072580"/>
            </geometry>
        </collision>
        <collision>
            <origin xyz="0.000479643 0.0828084 0.0570136" rpy="0 -0 0"/>
            <geometry>
                <sphere radius="0.072580"/>
            </geometry>
        </collision>
        <inertial>
            <origin xyz="-0.00160396 0.0292536 -0.0972966" rpy="0 -0 0"/>
            <mass value="2.327121"/>
            <inertia ixx="5.161028e-02" ixy="-5.715173e-03" ixz="-3.567317e-03" iyy="4.787730e-02" iyz="1.067399e-02" izz="1.642363e-02"/>
        </inertial>
    </link>
    <joint name="fr3_joint5" type="revolute">
        <parent link="fr3_link4"/>
        <child link="fr3_link5"/>
        <origin xyz="-0.0825 0.384 0" rpy="-1.5708 0 0"/>
        <axis xyz="0 0 1"/>
        <limit lower="-2.806500" upper="2.806500" effort="12.000000" velocity="5.260000"/>
        <dynamics damping="0.003000" friction="0.200000"/>
    </joint>
    <link name="fr3_link6">
        <visual>
            <origin xyz="0 0 0" rpy="0 -0 0"/>
            <geometry>
                <mesh filename="/workspace/resources/fr3/meshes/fr3/visual/link6.dae"/>
            </geometry>
        </visual>
        <collision>
            <origin xyz="0.0430729 0.00285167 0.00227838" rpy="-2.29626 1.40296 -2.16315"/>
            <geometry>
                <cylinder radius="0.076478" length="0.185485"/>
            </geometry>
        </collision>
        <collision>
            <origin xyz="-0.0483662 -0.00873982 0.0125575" rpy="0 -0 0"/>
            <geometry>
                <sphere radius="0.076478"/>
            </geometry>
        </collision>
        <collision>
            <origin xyz="0.134512 0.0144432 -0.0080007" rpy="0 -0 0"/>
            <geometry>
                <sphere radius="0.076478"/>
            </geometry>
        </collision>
        <inertial>
            <origin xyz="0.0597131 -0.0410295 -0.0101693" rpy="0 -0 0"/>
            <mass value="1.817038"/>
            <inertia ixx="5.412334e-03" ixy="6.193456e-03" ixz="1.421929e-03" iyy="1.405833e-02" iyz="-1.314075e-03" izz="1.608082e-02"/>
        </inertial>
    </link>
    <joint name="fr3_joint6" type="revolute">
        <parent link="fr3_link5"/>
        <child link="fr3_link6"/>
        <origin xyz="0 0 0" rpy="1.5708 -0 0"/>
        <axis xyz="0 0 1"/>
        <limit lower="0.544500" upper="4.516900" effort="12.000000" velocity="4.180000"/>
        <dynamics damping="0.003000" friction="0.200000"/>
    </joint>
    <link name="fr3_link7">
        <visual>
            <origin xyz="0 0 0" rpy="0 -0 0"/>
            <geometry>
                <mesh filename="/workspace/resources/fr3/meshes/fr3/visual/link7.dae"/>
            </geometry>
        </visual>
        <collision>
            <origin xyz="-6.83221e-05 -0.000358051 0.0772558" rpy="-1.45415 0.77725 -0.698662"/>
            <geometry>
                <cylinder radius="0.050865" length="0.106473"/>
            </geometry>
        </collision>
        <collision>
            <origin xyz="-0.0374042 -0.0380495 0.0728391" rpy="0 -0 0"/>
            <geometry>
                <sphere radius="0.050865"/>
            </geometry>
        </collision>
        <collision>
            <origin xyz="0.0372675 0.0373334 0.0816726" rpy="0 -0 0"/>
            <geometry>
                <sphere radius="0.050865"/>
            </geometry>
        </collision>
        <collision>
            <origin xyz="0.0497213 0.0498436 0.0838758" rpy="-1.39647 0.7755 -0.660462"/>
            <geometry>
                <cylinder radius="0.038466" length="0.035579"/>
            </geometry>
        </collision>
        <collision>
            <origin xyz="0.0372675 0.0373334 0.0816726" rpy="0 -0 0"/>
            <geometry>
                <sphere radius="0.038466"/>
            </geometry>
        </collision>
        <collision>
            <origin xyz="0.0621751 0.0623539 0.086079" rpy="0 -0 0"/>
            <geometry>
                <sphere radius="0.038466"/>
            </geometry>
        </collision>
        <inertial>
            <origin xyz="0.00452258 0.00862619 -0.0161633" rpy="0 -0 0"/>
            <mass value="0.627143"/>
            <inertia ixx="2.109239e-04" ixy="-2.433299e-05" ixz="4.564480e-05" iyy="1.771857e-04" iyz="8.744070e-05" izz="5.993191e-05"/>
        </inertial>
    </link>
    <joint name="fr3_joint7" type="revolute">
        <parent link="fr3_link6"/>
        <child link="fr3_link7"/>
        <origin xyz="0.088 0 0" rpy="1.5708 -0 0"/>
        <axis xyz="0 0 1"/>
        <limit lower="-3.015900" upper="3.015900" effort="12.000000" velocity="5.260000"/>
        <dynamics damping="0.003000" friction="0.200000"/>
    </joint>
    <link name="fr3_link8"/>
    <joint name="fr3_joint8" type="fixed">
        <parent link="fr3_link7"/>
        <child link="fr3_link8"/>
        <origin xyz="0 0 0.107" rpy="0 -0 0"/>
    </joint>
    <link name="world"/>
    <joint name="fr3_joint_world" type="fixed">
        <parent link="world"/>
        <child link="fr3_link0"/>
        <origin xyz="0 0 0" rpy="0 -0 0"/>
    </joint>
    <link name="hand_hand">
        <visual>
            <origin xyz="0 0 0" rpy="0 -0 0"/>
            <geometry>
                <mesh filename="/workspace/resources/fr3/meshes/franka_hand/visual/hand.dae"/>
            </geometry>
        </visual>
        <collision>
            <origin xyz="-0.000165484 -0.00168091 0.0249333" rpy="1.61264 -0.000985837 -0.00102798"/>
            <geometry>
                <cylinder radius="0.049001" length="0.206423"/>
            </geometry>
        </collision>
        <collision>
            <origin xyz="-6.37343e-05 0.10144 0.0292509" rpy="0 -0 0"/>
            <geometry>
                <sphere radius="0.049001"/>
            </geometry>
        </collision>
        <collision>
            <origin xyz="-0.000267234 -0.104802 0.0206157" rpy="0 -0 0"/>
            <geometry>
                <sphere radius="0.049001"/>
            </geometry>
        </collision>
        <inertial>
            <origin xyz="-3.76e-05 0.0119128 0.020726" rpy="0 -0 0"/>
            <mass value="0.654400"/>
            <inertia ixx="1.860000e-03" ixy="0.000000e+00" ixz="0.000000e+00" iyy="3.000000e-04" iyz="-2.000000e-05" izz="1.740000e-03"/>
        </inertial>
    </link>
    <link name="hand_leftfinger">
        <visual>
            <origin xyz="-0.0165 0.0165 0.127733" rpy="-1.5708 0.202458 -1.5708"/>
            <geometry>
                <mesh filename="/workspace/resources/fr3/meshes/plate/collision/flex_griper_connect.stl"/>
            </geometry>
        </visual>
        <collision>
            <origin xyz="9.23737e-07 0.00547819 0.10899" rpy="-2.96055 -4.96385e-05 0.000546851"/>
            <geometry>
                <cylinder radius="0.011853" length="0.032222"/>
            </geometry>
        </collision>
        <collision>
            <origin xyz="1.72347e-06 0.00257724 0.124837" rpy="0 -0 0"/>
            <geometry>
                <sphere radius="0.011853"/>
            </geometry>
        </collision>
        <collision>
            <origin xyz="1.24006e-07 0.00837915 0.0931419" rpy="0 -0 0"/>
            <geometry>
                <sphere radius="0.011853"/>
            </geometry>
        </collision>
        <collision>
            <origin xyz="6.33555e-08 0.0105644 0.0826105" rpy="-2.937 -5.63894e-06 5.49314e-05"/>
            <geometry>
                <cylinder radius="0.014643" length="0.021511"/>
            </geometry>
        </collision>
        <collision>
            <origin xyz="1.24006e-07 0.00837915 0.0931419" rpy="0 -0 0"/>
            <geometry>
                <sphere radius="0.014643"/>
            </geometry>
        </collision>
        <collision>
            <origin xyz="2.70484e-09 0.0127496 0.0720792" rpy="0 -0 0"/>
            <geometry>
                <sphere radius="0.014643"/>
            </geometry>
        </collision>
        <collision>
            <origin xyz="-5.79124e-07 0.0154873 0.0345582" rpy="-3.06876 -1.54657e-05 0.000424485"/>
            <geometry>
                <cylinder radius="0.027062" length="0.075241"/>
            </geometry>
        </collision>
        <collision>
            <origin xyz="2.70484e-09 0.0127496 0.0720792" rpy="0 -0 0"/>
            <geometry>
                <sphere radius="0.027062"/>
            </geometry>
        </collision>
        <collision>
            <origin xyz="-1.16095e-06 0.018225 -0.0029627" rpy="0 -0 0"/>
            <geometry>
                <sphere radius="0.027062"/>
            </geometry>
        </collision>
        <inertial>
            <origin xyz="0 0.0145644 0.0227941" rpy="0 -0 0"/>
            <mass value="0.100000"/>
            <inertia ixx="3.012209e-05" ixy="0.000000e+00" ixz="0.000000e+00" iyy="2.958738e-05" iyz="0.000000e+00" izz="6.951252e-06"/>
        </inertial>
    </link>
    <joint name="hand_finger_joint1" type="prismatic">
        <parent link="hand_hand"/>
        <child link="hand_leftfinger"/>
        <origin xyz="0 0 0.0584" rpy="0 -0 0"/>
        <axis xyz="0 1 0"/>
        <limit lower="0.000000" upper="0.040000" effort="100.000000" velocity="0.200000"/>
        <dynamics damping="0.300000" friction="0.000000"/>
    </joint>
    <link name="hand_rightfinger">
        <visual>
            <origin xyz="-0.0165 0.0165 0.127733" rpy="-1.5708 0.202458 -1.5708"/>
            <geometry>
                <mesh filename="/workspace/resources/fr3/meshes/plate/collision/flex_griper_connect.stl"/>
            </geometry>
        </visual>
        <collision>
            <origin xyz="9.23737e-07 0.00547819 0.10899" rpy="-2.96055 -4.96385e-05 0.000546851"/>
            <geometry>
                <cylinder radius="0.011853" length="0.032222"/>
            </geometry>
        </collision>
        <collision>
            <origin xyz="1.72347e-06 0.00257724 0.124837" rpy="0 -0 0"/>
            <geometry>
                <sphere radius="0.011853"/>
            </geometry>
        </collision>
        <collision>
            <origin xyz="1.24006e-07 0.00837915 0.0931419" rpy="0 -0 0"/>
            <geometry>
                <sphere radius="0.011853"/>
            </geometry>
        </collision>
        <collision>
            <origin xyz="6.33555e-08 0.0105644 0.0826105" rpy="-2.937 -5.63894e-06 5.49314e-05"/>
            <geometry>
                <cylinder radius="0.014643" length="0.021511"/>
            </geometry>
        </collision>
        <collision>
            <origin xyz="1.24006e-07 0.00837915 0.0931419" rpy="0 -0 0"/>
            <geometry>
                <sphere radius="0.014643"/>
            </geometry>
        </collision>
        <collision>
            <origin xyz="2.70484e-09 0.0127496 0.0720792" rpy="0 -0 0"/>
            <geometry>
                <sphere radius="0.014643"/>
            </geometry>
        </collision>
        <collision>
            <origin xyz="-5.79124e-07 0.0154873 0.0345582" rpy="-3.06876 -1.54657e-05 0.000424485"/>
            <geometry>
                <cylinder radius="0.027062" length="0.075241"/>
            </geometry>
        </collision>
        <collision>
            <origin xyz="2.70484e-09 0.0127496 0.0720792" rpy="0 -0 0"/>
            <geometry>
                <sphere radius="0.027062"/>
            </geometry>
        </collision>
        <collision>
            <origin xyz="-1.16095e-06 0.018225 -0.0029627" rpy="0 -0 0"/>
            <geometry>
                <sphere radius="0.027062"/>
            </geometry>
        </collision>
        <inertial>
            <origin xyz="0 0.0145644 0.0227941" rpy="0 -0 3.14159"/>
            <mass value="0.100000"/>
            <inertia ixx="3.012209e-05" ixy="0.000000e+00" ixz="0.000000e+00" iyy="2.958738e-05" iyz="0.000000e+00" izz="6.951252e-06"/>
        </inertial>
    </link>
    <joint name="hand_finger_joint2" type="prismatic">
        <parent link="hand_hand"/>
        <child link="hand_rightfinger"/>
        <origin xyz="0 0 0.0584" rpy="0 -0 3.14159"/>
        <axis xyz="0 1 0"/>
        <limit lower="0.000000" upper="0.040000" effort="100.000000" velocity="0.200000"/>
        <dynamics damping="0.300000" friction="0.000000"/>
    </joint>
    <link name="hand_hand_tcp"/>
    <joint name="hand_hand_tcp_joint" type="fixed">
        <parent link="hand_hand"/>
        <child link="hand_hand_tcp"/>
        <origin xyz="0 0 0.1034" rpy="0 -0 0"/>
    </joint>
    <joint name="hand_joint_fr3_link8" type="fixed">
        <parent link="fr3_link8"/>
        <child link="hand_hand"/>
        <origin xyz="0 0 0" rpy="0 0 -0.785398"/>
    </joint>
</robot>
